
daily.sh at 2022-07-06T16:00:01-04:00
-------------------------------------

github pull in /home/lachaume/git/autolog

github pull in /data/www/twoptwo.com

executing periodlog.py in /home/lachaume/git/autolog/scripts
Traceback (most recent call last):
  File "/usr/lib/python3/dist-packages/urllib3/connection.py", line 169, in _new_conn
    conn = connection.create_connection(
  File "/usr/lib/python3/dist-packages/urllib3/util/connection.py", line 73, in create_connection
    for res in socket.getaddrinfo(host, port, family, socket.SOCK_STREAM):
  File "/usr/lib/python3.10/socket.py", line 955, in getaddrinfo
    for res in _socket.getaddrinfo(host, port, family, type, proto, flags):
socket.gaierror: [Errno -3] Temporary failure in name resolution

During handling of the above exception, another exception occurred:

Traceback (most recent call last):
  File "/usr/lib/python3/dist-packages/urllib3/connectionpool.py", line 699, in urlopen
    httplib_response = self._make_request(
  File "/usr/lib/python3/dist-packages/urllib3/connectionpool.py", line 394, in _make_request
    conn.request(method, url, **httplib_request_kw)
  File "/usr/lib/python3/dist-packages/urllib3/connection.py", line 234, in request
    super(HTTPConnection, self).request(method, url, body=body, headers=headers)
  File "/usr/lib/python3.10/http/client.py", line 1282, in request
    self._send_request(method, url, body, headers, encode_chunked)
  File "/usr/lib/python3.10/http/client.py", line 1328, in _send_request
    self.endheaders(body, encode_chunked=encode_chunked)
  File "/usr/lib/python3.10/http/client.py", line 1277, in endheaders
    self._send_output(message_body, encode_chunked=encode_chunked)
  File "/usr/lib/python3.10/http/client.py", line 1037, in _send_output
    self.send(msg)
  File "/usr/lib/python3.10/http/client.py", line 975, in send
    self.connect()
  File "/usr/lib/python3/dist-packages/urllib3/connection.py", line 200, in connect
    conn = self._new_conn()
  File "/usr/lib/python3/dist-packages/urllib3/connection.py", line 181, in _new_conn
    raise NewConnectionError(
urllib3.exceptions.NewConnectionError: <urllib3.connection.HTTPConnection object at 0x7f978ae684c0>: Failed to establish a new connection: [Errno -3] Temporary failure in name resolution

During handling of the above exception, another exception occurred:

Traceback (most recent call last):
  File "/usr/lib/python3/dist-packages/requests/adapters.py", line 439, in send
    resp = conn.urlopen(
  File "/usr/lib/python3/dist-packages/urllib3/connectionpool.py", line 755, in urlopen
    retries = retries.increment(
  File "/usr/lib/python3/dist-packages/urllib3/util/retry.py", line 574, in increment
    raise MaxRetryError(_pool, url, error or ResponseError(cause))
urllib3.exceptions.MaxRetryError: HTTPConnectionPool(host='archive.eso.org', port=80): Max retries exceeded with url: /tap_obs/sync (Caused by NewConnectionError('<urllib3.connection.HTTPConnection object at 0x7f978ae684c0>: Failed to establish a new connection: [Errno -3] Temporary failure in name resolution'))

During handling of the above exception, another exception occurred:

Traceback (most recent call last):
  File "/usr/local/lib/python3.10/dist-packages/pyvo/dal/query.py", line 242, in execute_votable
    return votableparse(self.execute_stream(post=post).read)
  File "/usr/local/lib/python3.10/dist-packages/pyvo/dal/tap.py", line 926, in execute_stream
    return super().execute_stream(post=post)
  File "/usr/local/lib/python3.10/dist-packages/pyvo/utils/decorators.py", line 9, in wrapper
    raw = func(*args, **kwargs)
  File "/usr/local/lib/python3.10/dist-packages/pyvo/dal/query.py", line 191, in execute_stream
    response = self.submit(post=post)
  File "/usr/local/lib/python3.10/dist-packages/pyvo/dal/tap.py", line 959, in submit
    response = self._session.post(
  File "/usr/lib/python3/dist-packages/requests/sessions.py", line 590, in post
    return self.request('POST', url, data=data, json=json, **kwargs)
  File "/usr/lib/python3/dist-packages/requests/sessions.py", line 542, in request
    resp = self.send(prep, **send_kwargs)
  File "/usr/lib/python3/dist-packages/requests/sessions.py", line 655, in send
    r = adapter.send(request, **kwargs)
  File "/usr/lib/python3/dist-packages/requests/adapters.py", line 516, in send
    raise ConnectionError(e, request=request)
requests.exceptions.ConnectionError: HTTPConnectionPool(host='archive.eso.org', port=80): Max retries exceeded with url: /tap_obs/sync (Caused by NewConnectionError('<urllib3.connection.HTTPConnection object at 0x7f978ae684c0>: Failed to establish a new connection: [Errno -3] Temporary failure in name resolution'))

During handling of the above exception, another exception occurred:

Traceback (most recent call last):
  File "/home/lachaume/git/autolog/scripts/./periodlog.py", line 22, in <module>
    log = PeriodLog.fetch(telescope, period, **opts) 
  File "/home/lachaume/git/autolog/scripts/../autolog/eso/periodlog.py", line 56, in fetch
    logs = [NightLog.fetch(telescope, night, **opts)
  File "/home/lachaume/git/autolog/scripts/../autolog/eso/periodlog.py", line 56, in <listcomp>
    logs = [NightLog.fetch(telescope, night, **opts)
  File "/home/lachaume/git/autolog/scripts/../autolog/eso/nightlog.py", line 67, in fetch
    log = query.fetch(night=night, use_tap_cache=use_tap_cache)
  File "/home/lachaume/git/autolog/scripts/../autolog/eso/tapquery.py", line 115, in fetch
    tab = tap.execute().to_table()
  File "/usr/local/lib/python3.10/dist-packages/pyvo/dal/tap.py", line 942, in execute
    return TAPResults(self.execute_votable(), url=self.queryurl, session=self._session)
  File "/usr/local/lib/python3.10/dist-packages/pyvo/dal/query.py", line 245, in execute_votable
    raise DALFormatError(e, self.queryurl)
pyvo.dal.exceptions.DALFormatError: ConnectionError: HTTPConnectionPool(host='archive.eso.org', port=80): Max retries exceeded with url: /tap_obs/sync (Caused by NewConnectionError('<urllib3.connection.HTTPConnection object at 0x7f978ae684c0>: Failed to establish a new connection: [Errno -3] Temporary failure in name resolution'))

git add * in /home/lachaume/git/autolog
git commit
git push
ssh: Could not resolve hostname github.com: Temporary failure in name resolution
fatal: Could not read from remote repository.

Please make sure you have the correct access rights
and the repository exists.


daily.sh at 2022-07-06T16:01:01-04:00
-------------------------------------

github pull in /home/lachaume/git/autolog

git add * in /data/www/twoptwo.com
git commit
ssh: Could not resolve hostname github.com: Temporary failure in name resolution
fatal: Could not read from remote repository.

Please make sure you have the correct access rights
and the repository exists.

github pull in /data/www/twoptwo.com
ssh: Could not resolve hostname github.com: Temporary failure in name resolution
fatal: Could not read from remote repository.

Please make sure you have the correct access rights
and the repository exists.


executing periodlog.py in /home/lachaume/git/autolog/scripts

daily.sh at 2022-07-06T16:02:01-04:00
-------------------------------------

github pull in /home/lachaume/git/autolog
Traceback (most recent call last):
  File "/usr/lib/python3/dist-packages/urllib3/connection.py", line 169, in _new_conn
    conn = connection.create_connection(
  File "/usr/lib/python3/dist-packages/urllib3/util/connection.py", line 73, in create_connection
    for res in socket.getaddrinfo(host, port, family, socket.SOCK_STREAM):
  File "/usr/lib/python3.10/socket.py", line 955, in getaddrinfo
    for res in _socket.getaddrinfo(host, port, family, type, proto, flags):
socket.gaierror: [Errno -3] Temporary failure in name resolution

During handling of the above exception, another exception occurred:

Traceback (most recent call last):
  File "/usr/lib/python3/dist-packages/urllib3/connectionpool.py", line 699, in urlopen
    httplib_response = self._make_request(
  File "/usr/lib/python3/dist-packages/urllib3/connectionpool.py", line 394, in _make_request
    conn.request(method, url, **httplib_request_kw)
  File "/usr/lib/python3/dist-packages/urllib3/connection.py", line 234, in request
    super(HTTPConnection, self).request(method, url, body=body, headers=headers)
  File "/usr/lib/python3.10/http/client.py", line 1282, in request
    self._send_request(method, url, body, headers, encode_chunked)
  File "/usr/lib/python3.10/http/client.py", line 1328, in _send_request
    self.endheaders(body, encode_chunked=encode_chunked)
  File "/usr/lib/python3.10/http/client.py", line 1277, in endheaders
    self._send_output(message_body, encode_chunked=encode_chunked)
  File "/usr/lib/python3.10/http/client.py", line 1037, in _send_output
    self.send(msg)
  File "/usr/lib/python3.10/http/client.py", line 975, in send
    self.connect()
  File "/usr/lib/python3/dist-packages/urllib3/connection.py", line 200, in connect
    conn = self._new_conn()
  File "/usr/lib/python3/dist-packages/urllib3/connection.py", line 181, in _new_conn
    raise NewConnectionError(
urllib3.exceptions.NewConnectionError: <urllib3.connection.HTTPConnection object at 0x7f54f964b880>: Failed to establish a new connection: [Errno -3] Temporary failure in name resolution

During handling of the above exception, another exception occurred:

Traceback (most recent call last):
  File "/usr/lib/python3/dist-packages/requests/adapters.py", line 439, in send
    resp = conn.urlopen(
  File "/usr/lib/python3/dist-packages/urllib3/connectionpool.py", line 755, in urlopen
    retries = retries.increment(
  File "/usr/lib/python3/dist-packages/urllib3/util/retry.py", line 574, in increment
    raise MaxRetryError(_pool, url, error or ResponseError(cause))
urllib3.exceptions.MaxRetryError: HTTPConnectionPool(host='archive.eso.org', port=80): Max retries exceeded with url: /tap_obs/sync (Caused by NewConnectionError('<urllib3.connection.HTTPConnection object at 0x7f54f964b880>: Failed to establish a new connection: [Errno -3] Temporary failure in name resolution'))

During handling of the above exception, another exception occurred:

Traceback (most recent call last):
  File "/usr/local/lib/python3.10/dist-packages/pyvo/dal/query.py", line 242, in execute_votable
    return votableparse(self.execute_stream(post=post).read)
  File "/usr/local/lib/python3.10/dist-packages/pyvo/dal/tap.py", line 926, in execute_stream
    return super().execute_stream(post=post)
  File "/usr/local/lib/python3.10/dist-packages/pyvo/utils/decorators.py", line 9, in wrapper
    raw = func(*args, **kwargs)
  File "/usr/local/lib/python3.10/dist-packages/pyvo/dal/query.py", line 191, in execute_stream
    response = self.submit(post=post)
  File "/usr/local/lib/python3.10/dist-packages/pyvo/dal/tap.py", line 959, in submit
    response = self._session.post(
  File "/usr/lib/python3/dist-packages/requests/sessions.py", line 590, in post
    return self.request('POST', url, data=data, json=json, **kwargs)
  File "/usr/lib/python3/dist-packages/requests/sessions.py", line 542, in request
    resp = self.send(prep, **send_kwargs)
  File "/usr/lib/python3/dist-packages/requests/sessions.py", line 655, in send
    r = adapter.send(request, **kwargs)
  File "/usr/lib/python3/dist-packages/requests/adapters.py", line 516, in send
    raise ConnectionError(e, request=request)
requests.exceptions.ConnectionError: HTTPConnectionPool(host='archive.eso.org', port=80): Max retries exceeded with url: /tap_obs/sync (Caused by NewConnectionError('<urllib3.connection.HTTPConnection object at 0x7f54f964b880>: Failed to establish a new connection: [Errno -3] Temporary failure in name resolution'))

During handling of the above exception, another exception occurred:

Traceback (most recent call last):
  File "/home/lachaume/git/autolog/scripts/./periodlog.py", line 22, in <module>
    log = PeriodLog.fetch(telescope, period, **opts) 
  File "/home/lachaume/git/autolog/scripts/../autolog/eso/periodlog.py", line 56, in fetch
    logs = [NightLog.fetch(telescope, night, **opts)
  File "/home/lachaume/git/autolog/scripts/../autolog/eso/periodlog.py", line 56, in <listcomp>
    logs = [NightLog.fetch(telescope, night, **opts)
  File "/home/lachaume/git/autolog/scripts/../autolog/eso/nightlog.py", line 67, in fetch
    log = query.fetch(night=night, use_tap_cache=use_tap_cache)
  File "/home/lachaume/git/autolog/scripts/../autolog/eso/tapquery.py", line 115, in fetch
    tab = tap.execute().to_table()
  File "/usr/local/lib/python3.10/dist-packages/pyvo/dal/tap.py", line 942, in execute
    return TAPResults(self.execute_votable(), url=self.queryurl, session=self._session)
  File "/usr/local/lib/python3.10/dist-packages/pyvo/dal/query.py", line 245, in execute_votable
    raise DALFormatError(e, self.queryurl)
pyvo.dal.exceptions.DALFormatError: ConnectionError: HTTPConnectionPool(host='archive.eso.org', port=80): Max retries exceeded with url: /tap_obs/sync (Caused by NewConnectionError('<urllib3.connection.HTTPConnection object at 0x7f54f964b880>: Failed to establish a new connection: [Errno -3] Temporary failure in name resolution'))

git add * in /home/lachaume/git/autolog
git commit
git push
ssh: Could not resolve hostname github.com: Temporary failure in name resolution
fatal: Could not read from remote repository.

Please make sure you have the correct access rights
and the repository exists.

github pull in /data/www/twoptwo.com
ssh: Could not resolve hostname github.com: Temporary failure in name resolution
fatal: Could not read from remote repository.

Please make sure you have the correct access rights
and the repository exists.

ssh: Could not resolve hostname github.com: Temporary failure in name resolution
fatal: Could not read from remote repository.

Please make sure you have the correct access rights
and the repository exists.

executing periodlog.py in /home/lachaume/git/autolog/scripts

git add * in /data/www/twoptwo.com
git commit

daily.sh at 2022-07-06T16:03:01-04:00
-------------------------------------

github pull in /home/lachaume/git/autolog
Traceback (most recent call last):
  File "/usr/lib/python3/dist-packages/urllib3/connection.py", line 169, in _new_conn
    conn = connection.create_connection(
  File "/usr/lib/python3/dist-packages/urllib3/util/connection.py", line 73, in create_connection
    for res in socket.getaddrinfo(host, port, family, socket.SOCK_STREAM):
  File "/usr/lib/python3.10/socket.py", line 955, in getaddrinfo
    for res in _socket.getaddrinfo(host, port, family, type, proto, flags):
socket.gaierror: [Errno -3] Temporary failure in name resolution

During handling of the above exception, another exception occurred:

Traceback (most recent call last):
  File "/usr/lib/python3/dist-packages/urllib3/connectionpool.py", line 699, in urlopen
    httplib_response = self._make_request(
  File "/usr/lib/python3/dist-packages/urllib3/connectionpool.py", line 394, in _make_request
    conn.request(method, url, **httplib_request_kw)
  File "/usr/lib/python3/dist-packages/urllib3/connection.py", line 234, in request
    super(HTTPConnection, self).request(method, url, body=body, headers=headers)
  File "/usr/lib/python3.10/http/client.py", line 1282, in request
    self._send_request(method, url, body, headers, encode_chunked)
  File "/usr/lib/python3.10/http/client.py", line 1328, in _send_request
    self.endheaders(body, encode_chunked=encode_chunked)
  File "/usr/lib/python3.10/http/client.py", line 1277, in endheaders
    self._send_output(message_body, encode_chunked=encode_chunked)
  File "/usr/lib/python3.10/http/client.py", line 1037, in _send_output
    self.send(msg)
  File "/usr/lib/python3.10/http/client.py", line 975, in send
    self.connect()
  File "/usr/lib/python3/dist-packages/urllib3/connection.py", line 200, in connect
    conn = self._new_conn()
  File "/usr/lib/python3/dist-packages/urllib3/connection.py", line 181, in _new_conn
    raise NewConnectionError(
urllib3.exceptions.NewConnectionError: <urllib3.connection.HTTPConnection object at 0x7fbe5dca03a0>: Failed to establish a new connection: [Errno -3] Temporary failure in name resolution

During handling of the above exception, another exception occurred:

Traceback (most recent call last):
  File "/usr/lib/python3/dist-packages/requests/adapters.py", line 439, in send
    resp = conn.urlopen(
  File "/usr/lib/python3/dist-packages/urllib3/connectionpool.py", line 755, in urlopen
    retries = retries.increment(
  File "/usr/lib/python3/dist-packages/urllib3/util/retry.py", line 574, in increment
    raise MaxRetryError(_pool, url, error or ResponseError(cause))
urllib3.exceptions.MaxRetryError: HTTPConnectionPool(host='archive.eso.org', port=80): Max retries exceeded with url: /tap_obs/sync (Caused by NewConnectionError('<urllib3.connection.HTTPConnection object at 0x7fbe5dca03a0>: Failed to establish a new connection: [Errno -3] Temporary failure in name resolution'))

During handling of the above exception, another exception occurred:

Traceback (most recent call last):
  File "/usr/local/lib/python3.10/dist-packages/pyvo/dal/query.py", line 242, in execute_votable
    return votableparse(self.execute_stream(post=post).read)
  File "/usr/local/lib/python3.10/dist-packages/pyvo/dal/tap.py", line 926, in execute_stream
    return super().execute_stream(post=post)
  File "/usr/local/lib/python3.10/dist-packages/pyvo/utils/decorators.py", line 9, in wrapper
    raw = func(*args, **kwargs)
  File "/usr/local/lib/python3.10/dist-packages/pyvo/dal/query.py", line 191, in execute_stream
    response = self.submit(post=post)
  File "/usr/local/lib/python3.10/dist-packages/pyvo/dal/tap.py", line 959, in submit
    response = self._session.post(
  File "/usr/lib/python3/dist-packages/requests/sessions.py", line 590, in post
    return self.request('POST', url, data=data, json=json, **kwargs)
  File "/usr/lib/python3/dist-packages/requests/sessions.py", line 542, in request
    resp = self.send(prep, **send_kwargs)
  File "/usr/lib/python3/dist-packages/requests/sessions.py", line 655, in send
    r = adapter.send(request, **kwargs)
  File "/usr/lib/python3/dist-packages/requests/adapters.py", line 516, in send
    raise ConnectionError(e, request=request)
requests.exceptions.ConnectionError: HTTPConnectionPool(host='archive.eso.org', port=80): Max retries exceeded with url: /tap_obs/sync (Caused by NewConnectionError('<urllib3.connection.HTTPConnection object at 0x7fbe5dca03a0>: Failed to establish a new connection: [Errno -3] Temporary failure in name resolution'))

During handling of the above exception, another exception occurred:

Traceback (most recent call last):
  File "/home/lachaume/git/autolog/scripts/./periodlog.py", line 22, in <module>
    log = PeriodLog.fetch(telescope, period, **opts) 
  File "/home/lachaume/git/autolog/scripts/../autolog/eso/periodlog.py", line 56, in fetch
    logs = [NightLog.fetch(telescope, night, **opts)
  File "/home/lachaume/git/autolog/scripts/../autolog/eso/periodlog.py", line 56, in <listcomp>
    logs = [NightLog.fetch(telescope, night, **opts)
  File "/home/lachaume/git/autolog/scripts/../autolog/eso/nightlog.py", line 67, in fetch
    log = query.fetch(night=night, use_tap_cache=use_tap_cache)
  File "/home/lachaume/git/autolog/scripts/../autolog/eso/tapquery.py", line 115, in fetch
    tab = tap.execute().to_table()
  File "/usr/local/lib/python3.10/dist-packages/pyvo/dal/tap.py", line 942, in execute
    return TAPResults(self.execute_votable(), url=self.queryurl, session=self._session)
  File "/usr/local/lib/python3.10/dist-packages/pyvo/dal/query.py", line 245, in execute_votable
    raise DALFormatError(e, self.queryurl)
pyvo.dal.exceptions.DALFormatError: ConnectionError: HTTPConnectionPool(host='archive.eso.org', port=80): Max retries exceeded with url: /tap_obs/sync (Caused by NewConnectionError('<urllib3.connection.HTTPConnection object at 0x7fbe5dca03a0>: Failed to establish a new connection: [Errno -3] Temporary failure in name resolution'))

git add * in /home/lachaume/git/autolog
git commit
git push
Everything up-to-date

warning: fetch updated the current branch head.
fast-forwarding your working tree from
commit 0c666324a0582f9e1ae823fbe230080e13dd9d36.
error: Your local changes to the following files would be overwritten by merge:
	scripts/logs/2022-07-06.err
	scripts/logs/2022-07-06.log
Please commit your changes or stash them before you merge.
Aborting
fatal: Cannot fast-forward your working tree.
After making sure that you saved anything precious from
$ git diff 0c666324a0582f9e1ae823fbe230080e13dd9d36
output, run
$ git reset --hard
to recover.

github pull in /data/www/twoptwo.com
To github.com:loqueelvientoajuarez/obslog.git
   4f5ae40..d892d72  master -> master


executing periodlog.py in /home/lachaume/git/autolog/scripts

git add * in /data/www/twoptwo.com
git commit
Everything up-to-date


daily.sh at 2022-07-06T16:04:01-04:00
-------------------------------------

github pull in /home/lachaume/git/autolog
Traceback (most recent call last):
  File "/usr/lib/python3/dist-packages/urllib3/connection.py", line 169, in _new_conn
    conn = connection.create_connection(
  File "/usr/lib/python3/dist-packages/urllib3/util/connection.py", line 73, in create_connection
    for res in socket.getaddrinfo(host, port, family, socket.SOCK_STREAM):
  File "/usr/lib/python3.10/socket.py", line 955, in getaddrinfo
    for res in _socket.getaddrinfo(host, port, family, type, proto, flags):
socket.gaierror: [Errno -3] Temporary failure in name resolution

During handling of the above exception, another exception occurred:

Traceback (most recent call last):
  File "/usr/lib/python3/dist-packages/urllib3/connectionpool.py", line 699, in urlopen
    httplib_response = self._make_request(
  File "/usr/lib/python3/dist-packages/urllib3/connectionpool.py", line 394, in _make_request
    conn.request(method, url, **httplib_request_kw)
  File "/usr/lib/python3/dist-packages/urllib3/connection.py", line 234, in request
    super(HTTPConnection, self).request(method, url, body=body, headers=headers)
  File "/usr/lib/python3.10/http/client.py", line 1282, in request
    self._send_request(method, url, body, headers, encode_chunked)
  File "/usr/lib/python3.10/http/client.py", line 1328, in _send_request
    self.endheaders(body, encode_chunked=encode_chunked)
  File "/usr/lib/python3.10/http/client.py", line 1277, in endheaders
    self._send_output(message_body, encode_chunked=encode_chunked)
  File "/usr/lib/python3.10/http/client.py", line 1037, in _send_output
    self.send(msg)
  File "/usr/lib/python3.10/http/client.py", line 975, in send
    self.connect()
  File "/usr/lib/python3/dist-packages/urllib3/connection.py", line 200, in connect
    conn = self._new_conn()
  File "/usr/lib/python3/dist-packages/urllib3/connection.py", line 181, in _new_conn
    raise NewConnectionError(
urllib3.exceptions.NewConnectionError: <urllib3.connection.HTTPConnection object at 0x7f0598354880>: Failed to establish a new connection: [Errno -3] Temporary failure in name resolution

During handling of the above exception, another exception occurred:

Traceback (most recent call last):
  File "/usr/lib/python3/dist-packages/requests/adapters.py", line 439, in send
    resp = conn.urlopen(
  File "/usr/lib/python3/dist-packages/urllib3/connectionpool.py", line 755, in urlopen
    retries = retries.increment(
  File "/usr/lib/python3/dist-packages/urllib3/util/retry.py", line 574, in increment
    raise MaxRetryError(_pool, url, error or ResponseError(cause))
urllib3.exceptions.MaxRetryError: HTTPConnectionPool(host='archive.eso.org', port=80): Max retries exceeded with url: /tap_obs/sync (Caused by NewConnectionError('<urllib3.connection.HTTPConnection object at 0x7f0598354880>: Failed to establish a new connection: [Errno -3] Temporary failure in name resolution'))

During handling of the above exception, another exception occurred:

Traceback (most recent call last):
  File "/usr/local/lib/python3.10/dist-packages/pyvo/dal/query.py", line 242, in execute_votable
    return votableparse(self.execute_stream(post=post).read)
  File "/usr/local/lib/python3.10/dist-packages/pyvo/dal/tap.py", line 926, in execute_stream
    return super().execute_stream(post=post)
  File "/usr/local/lib/python3.10/dist-packages/pyvo/utils/decorators.py", line 9, in wrapper
    raw = func(*args, **kwargs)
  File "/usr/local/lib/python3.10/dist-packages/pyvo/dal/query.py", line 191, in execute_stream
    response = self.submit(post=post)
  File "/usr/local/lib/python3.10/dist-packages/pyvo/dal/tap.py", line 959, in submit
    response = self._session.post(
  File "/usr/lib/python3/dist-packages/requests/sessions.py", line 590, in post
    return self.request('POST', url, data=data, json=json, **kwargs)
  File "/usr/lib/python3/dist-packages/requests/sessions.py", line 542, in request
    resp = self.send(prep, **send_kwargs)
  File "/usr/lib/python3/dist-packages/requests/sessions.py", line 655, in send
    r = adapter.send(request, **kwargs)
  File "/usr/lib/python3/dist-packages/requests/adapters.py", line 516, in send
    raise ConnectionError(e, request=request)
requests.exceptions.ConnectionError: HTTPConnectionPool(host='archive.eso.org', port=80): Max retries exceeded with url: /tap_obs/sync (Caused by NewConnectionError('<urllib3.connection.HTTPConnection object at 0x7f0598354880>: Failed to establish a new connection: [Errno -3] Temporary failure in name resolution'))

During handling of the above exception, another exception occurred:

Traceback (most recent call last):
  File "/home/lachaume/git/autolog/scripts/./periodlog.py", line 22, in <module>
    log = PeriodLog.fetch(telescope, period, **opts) 
  File "/home/lachaume/git/autolog/scripts/../autolog/eso/periodlog.py", line 56, in fetch
    logs = [NightLog.fetch(telescope, night, **opts)
  File "/home/lachaume/git/autolog/scripts/../autolog/eso/periodlog.py", line 56, in <listcomp>
    logs = [NightLog.fetch(telescope, night, **opts)
  File "/home/lachaume/git/autolog/scripts/../autolog/eso/nightlog.py", line 67, in fetch
    log = query.fetch(night=night, use_tap_cache=use_tap_cache)
  File "/home/lachaume/git/autolog/scripts/../autolog/eso/tapquery.py", line 115, in fetch
    tab = tap.execute().to_table()
  File "/usr/local/lib/python3.10/dist-packages/pyvo/dal/tap.py", line 942, in execute
    return TAPResults(self.execute_votable(), url=self.queryurl, session=self._session)
  File "/usr/local/lib/python3.10/dist-packages/pyvo/dal/query.py", line 245, in execute_votable
    raise DALFormatError(e, self.queryurl)
pyvo.dal.exceptions.DALFormatError: ConnectionError: HTTPConnectionPool(host='archive.eso.org', port=80): Max retries exceeded with url: /tap_obs/sync (Caused by NewConnectionError('<urllib3.connection.HTTPConnection object at 0x7f0598354880>: Failed to establish a new connection: [Errno -3] Temporary failure in name resolution'))

git add * in /home/lachaume/git/autolog
git commit
git push
ssh: Could not resolve hostname github.com: Temporary failure in name resolution
fatal: Could not read from remote repository.

Please make sure you have the correct access rights
and the repository exists.

github pull in /data/www/twoptwo.com
ssh: Could not resolve hostname github.com: Temporary failure in name resolution
fatal: Could not read from remote repository.

Please make sure you have the correct access rights
and the repository exists.

ssh: Could not resolve hostname github.com: Temporary failure in name resolution
fatal: Could not read from remote repository.

Please make sure you have the correct access rights
and the repository exists.

executing periodlog.py in /home/lachaume/git/autolog/scripts

git add * in /data/www/twoptwo.com
git commit
Everything up-to-date


daily.sh at 2022-07-06T16:05:01-04:00
-------------------------------------

github pull in /home/lachaume/git/autolog

daily.sh at 2022-07-06T16:06:01-04:00
-------------------------------------

github pull in /home/lachaume/git/autolog

github pull in /data/www/twoptwo.com

executing periodlog.py in /home/lachaume/git/autolog/scripts

github pull in /data/www/twoptwo.com

executing periodlog.py in /home/lachaume/git/autolog/scripts

daily.sh at 2022-07-06T16:07:01-04:00
-------------------------------------

github pull in /home/lachaume/git/autolog
Traceback (most recent call last):
  File "/usr/lib/python3/dist-packages/urllib3/connection.py", line 169, in _new_conn
    conn = connection.create_connection(
  File "/usr/lib/python3/dist-packages/urllib3/util/connection.py", line 73, in create_connection
    for res in socket.getaddrinfo(host, port, family, socket.SOCK_STREAM):
  File "/usr/lib/python3.10/socket.py", line 955, in getaddrinfo
    for res in _socket.getaddrinfo(host, port, family, type, proto, flags):
socket.gaierror: [Errno -3] Temporary failure in name resolution

During handling of the above exception, another exception occurred:

Traceback (most recent call last):
  File "/usr/lib/python3/dist-packages/urllib3/connectionpool.py", line 699, in urlopen
    httplib_response = self._make_request(
  File "/usr/lib/python3/dist-packages/urllib3/connectionpool.py", line 394, in _make_request
    conn.request(method, url, **httplib_request_kw)
  File "/usr/lib/python3/dist-packages/urllib3/connection.py", line 234, in request
    super(HTTPConnection, self).request(method, url, body=body, headers=headers)
  File "/usr/lib/python3.10/http/client.py", line 1282, in request
    self._send_request(method, url, body, headers, encode_chunked)
  File "/usr/lib/python3.10/http/client.py", line 1328, in _send_request
    self.endheaders(body, encode_chunked=encode_chunked)
  File "/usr/lib/python3.10/http/client.py", line 1277, in endheaders
    self._send_output(message_body, encode_chunked=encode_chunked)
  File "/usr/lib/python3.10/http/client.py", line 1037, in _send_output
    self.send(msg)
  File "/usr/lib/python3.10/http/client.py", line 975, in send
    self.connect()
  File "/usr/lib/python3/dist-packages/urllib3/connection.py", line 200, in connect
    conn = self._new_conn()
  File "/usr/lib/python3/dist-packages/urllib3/connection.py", line 181, in _new_conn
    raise NewConnectionError(
urllib3.exceptions.NewConnectionError: <urllib3.connection.HTTPConnection object at 0x7f8060eaefb0>: Failed to establish a new connection: [Errno -3] Temporary failure in name resolution

During handling of the above exception, another exception occurred:

Traceback (most recent call last):
  File "/usr/lib/python3/dist-packages/requests/adapters.py", line 439, in send
    resp = conn.urlopen(
  File "/usr/lib/python3/dist-packages/urllib3/connectionpool.py", line 755, in urlopen
    retries = retries.increment(
  File "/usr/lib/python3/dist-packages/urllib3/util/retry.py", line 574, in increment
    raise MaxRetryError(_pool, url, error or ResponseError(cause))
urllib3.exceptions.MaxRetryError: HTTPConnectionPool(host='archive.eso.org', port=80): Max retries exceeded with url: /tap_obs/sync (Caused by NewConnectionError('<urllib3.connection.HTTPConnection object at 0x7f8060eaefb0>: Failed to establish a new connection: [Errno -3] Temporary failure in name resolution'))

During handling of the above exception, another exception occurred:

Traceback (most recent call last):
  File "/usr/local/lib/python3.10/dist-packages/pyvo/dal/query.py", line 242, in execute_votable
    return votableparse(self.execute_stream(post=post).read)
  File "/usr/local/lib/python3.10/dist-packages/pyvo/dal/tap.py", line 926, in execute_stream
    return super().execute_stream(post=post)
  File "/usr/local/lib/python3.10/dist-packages/pyvo/utils/decorators.py", line 9, in wrapper
    raw = func(*args, **kwargs)
  File "/usr/local/lib/python3.10/dist-packages/pyvo/dal/query.py", line 191, in execute_stream
    response = self.submit(post=post)
  File "/usr/local/lib/python3.10/dist-packages/pyvo/dal/tap.py", line 959, in submit
    response = self._session.post(
  File "/usr/lib/python3/dist-packages/requests/sessions.py", line 590, in post
    return self.request('POST', url, data=data, json=json, **kwargs)
  File "/usr/lib/python3/dist-packages/requests/sessions.py", line 542, in request
    resp = self.send(prep, **send_kwargs)
  File "/usr/lib/python3/dist-packages/requests/sessions.py", line 655, in send
    r = adapter.send(request, **kwargs)
  File "/usr/lib/python3/dist-packages/requests/adapters.py", line 516, in send
    raise ConnectionError(e, request=request)
requests.exceptions.ConnectionError: HTTPConnectionPool(host='archive.eso.org', port=80): Max retries exceeded with url: /tap_obs/sync (Caused by NewConnectionError('<urllib3.connection.HTTPConnection object at 0x7f8060eaefb0>: Failed to establish a new connection: [Errno -3] Temporary failure in name resolution'))

During handling of the above exception, another exception occurred:

Traceback (most recent call last):
  File "/home/lachaume/git/autolog/scripts/./periodlog.py", line 22, in <module>
    log = PeriodLog.fetch(telescope, period, **opts) 
  File "/home/lachaume/git/autolog/scripts/../autolog/eso/periodlog.py", line 56, in fetch
    logs = [NightLog.fetch(telescope, night, **opts)
  File "/home/lachaume/git/autolog/scripts/../autolog/eso/periodlog.py", line 56, in <listcomp>
    logs = [NightLog.fetch(telescope, night, **opts)
  File "/home/lachaume/git/autolog/scripts/../autolog/eso/nightlog.py", line 67, in fetch
    log = query.fetch(night=night, use_tap_cache=use_tap_cache)
  File "/home/lachaume/git/autolog/scripts/../autolog/eso/tapquery.py", line 115, in fetch
    tab = tap.execute().to_table()
  File "/usr/local/lib/python3.10/dist-packages/pyvo/dal/tap.py", line 942, in execute
    return TAPResults(self.execute_votable(), url=self.queryurl, session=self._session)
  File "/usr/local/lib/python3.10/dist-packages/pyvo/dal/query.py", line 245, in execute_votable
    raise DALFormatError(e, self.queryurl)
pyvo.dal.exceptions.DALFormatError: ConnectionError: HTTPConnectionPool(host='archive.eso.org', port=80): Max retries exceeded with url: /tap_obs/sync (Caused by NewConnectionError('<urllib3.connection.HTTPConnection object at 0x7f8060eaefb0>: Failed to establish a new connection: [Errno -3] Temporary failure in name resolution'))

git add * in /home/lachaume/git/autolog
git commit
git push
Traceback (most recent call last):
  File "/usr/lib/python3/dist-packages/urllib3/connection.py", line 169, in _new_conn
    conn = connection.create_connection(
  File "/usr/lib/python3/dist-packages/urllib3/util/connection.py", line 73, in create_connection
    for res in socket.getaddrinfo(host, port, family, socket.SOCK_STREAM):
  File "/usr/lib/python3.10/socket.py", line 955, in getaddrinfo
    for res in _socket.getaddrinfo(host, port, family, type, proto, flags):
socket.gaierror: [Errno -3] Temporary failure in name resolution

During handling of the above exception, another exception occurred:

Traceback (most recent call last):
  File "/usr/lib/python3/dist-packages/urllib3/connectionpool.py", line 699, in urlopen
    httplib_response = self._make_request(
  File "/usr/lib/python3/dist-packages/urllib3/connectionpool.py", line 394, in _make_request
    conn.request(method, url, **httplib_request_kw)
  File "/usr/lib/python3/dist-packages/urllib3/connection.py", line 234, in request
    super(HTTPConnection, self).request(method, url, body=body, headers=headers)
  File "/usr/lib/python3.10/http/client.py", line 1282, in request
    self._send_request(method, url, body, headers, encode_chunked)
  File "/usr/lib/python3.10/http/client.py", line 1328, in _send_request
    self.endheaders(body, encode_chunked=encode_chunked)
  File "/usr/lib/python3.10/http/client.py", line 1277, in endheaders
    self._send_output(message_body, encode_chunked=encode_chunked)
  File "/usr/lib/python3.10/http/client.py", line 1037, in _send_output
    self.send(msg)
  File "/usr/lib/python3.10/http/client.py", line 975, in send
    self.connect()
  File "/usr/lib/python3/dist-packages/urllib3/connection.py", line 200, in connect
    conn = self._new_conn()
  File "/usr/lib/python3/dist-packages/urllib3/connection.py", line 181, in _new_conn
    raise NewConnectionError(
urllib3.exceptions.NewConnectionError: <urllib3.connection.HTTPConnection object at 0x7f2c0c72b8b0>: Failed to establish a new connection: [Errno -3] Temporary failure in name resolution

During handling of the above exception, another exception occurred:

Traceback (most recent call last):
  File "/usr/lib/python3/dist-packages/requests/adapters.py", line 439, in send
    resp = conn.urlopen(
  File "/usr/lib/python3/dist-packages/urllib3/connectionpool.py", line 755, in urlopen
    retries = retries.increment(
  File "/usr/lib/python3/dist-packages/urllib3/util/retry.py", line 574, in increment
    raise MaxRetryError(_pool, url, error or ResponseError(cause))
urllib3.exceptions.MaxRetryError: HTTPConnectionPool(host='archive.eso.org', port=80): Max retries exceeded with url: /tap_obs/sync (Caused by NewConnectionError('<urllib3.connection.HTTPConnection object at 0x7f2c0c72b8b0>: Failed to establish a new connection: [Errno -3] Temporary failure in name resolution'))

During handling of the above exception, another exception occurred:

Traceback (most recent call last):
  File "/usr/local/lib/python3.10/dist-packages/pyvo/dal/query.py", line 242, in execute_votable
    return votableparse(self.execute_stream(post=post).read)
  File "/usr/local/lib/python3.10/dist-packages/pyvo/dal/tap.py", line 926, in execute_stream
    return super().execute_stream(post=post)
  File "/usr/local/lib/python3.10/dist-packages/pyvo/utils/decorators.py", line 9, in wrapper
    raw = func(*args, **kwargs)
  File "/usr/local/lib/python3.10/dist-packages/pyvo/dal/query.py", line 191, in execute_stream
    response = self.submit(post=post)
  File "/usr/local/lib/python3.10/dist-packages/pyvo/dal/tap.py", line 959, in submit
    response = self._session.post(
  File "/usr/lib/python3/dist-packages/requests/sessions.py", line 590, in post
    return self.request('POST', url, data=data, json=json, **kwargs)
  File "/usr/lib/python3/dist-packages/requests/sessions.py", line 542, in request
    resp = self.send(prep, **send_kwargs)
  File "/usr/lib/python3/dist-packages/requests/sessions.py", line 655, in send
    r = adapter.send(request, **kwargs)
  File "/usr/lib/python3/dist-packages/requests/adapters.py", line 516, in send
    raise ConnectionError(e, request=request)
requests.exceptions.ConnectionError: HTTPConnectionPool(host='archive.eso.org', port=80): Max retries exceeded with url: /tap_obs/sync (Caused by NewConnectionError('<urllib3.connection.HTTPConnection object at 0x7f2c0c72b8b0>: Failed to establish a new connection: [Errno -3] Temporary failure in name resolution'))

During handling of the above exception, another exception occurred:

Traceback (most recent call last):
  File "/home/lachaume/git/autolog/scripts/./periodlog.py", line 22, in <module>
    log = PeriodLog.fetch(telescope, period, **opts) 
  File "/home/lachaume/git/autolog/scripts/../autolog/eso/periodlog.py", line 56, in fetch
    logs = [NightLog.fetch(telescope, night, **opts)
  File "/home/lachaume/git/autolog/scripts/../autolog/eso/periodlog.py", line 56, in <listcomp>
    logs = [NightLog.fetch(telescope, night, **opts)
  File "/home/lachaume/git/autolog/scripts/../autolog/eso/nightlog.py", line 67, in fetch
    log = query.fetch(night=night, use_tap_cache=use_tap_cache)
  File "/home/lachaume/git/autolog/scripts/../autolog/eso/tapquery.py", line 115, in fetch
    tab = tap.execute().to_table()
  File "/usr/local/lib/python3.10/dist-packages/pyvo/dal/tap.py", line 942, in execute
    return TAPResults(self.execute_votable(), url=self.queryurl, session=self._session)
  File "/usr/local/lib/python3.10/dist-packages/pyvo/dal/query.py", line 245, in execute_votable
    raise DALFormatError(e, self.queryurl)
pyvo.dal.exceptions.DALFormatError: ConnectionError: HTTPConnectionPool(host='archive.eso.org', port=80): Max retries exceeded with url: /tap_obs/sync (Caused by NewConnectionError('<urllib3.connection.HTTPConnection object at 0x7f2c0c72b8b0>: Failed to establish a new connection: [Errno -3] Temporary failure in name resolution'))

git add * in /home/lachaume/git/autolog
git commit
git push
ssh: Could not resolve hostname github.com: Temporary failure in name resolution
fatal: Could not read from remote repository.

Please make sure you have the correct access rights
and the repository exists.

github pull in /data/www/twoptwo.com
Traceback (most recent call last):
  File "/usr/lib/python3/dist-packages/urllib3/connection.py", line 169, in _new_conn
    conn = connection.create_connection(
  File "/usr/lib/python3/dist-packages/urllib3/util/connection.py", line 96, in create_connection
    raise err
  File "/usr/lib/python3/dist-packages/urllib3/util/connection.py", line 86, in create_connection
    sock.connect(sa)
TimeoutError: [Errno 110] Connection timed out

During handling of the above exception, another exception occurred:

Traceback (most recent call last):
  File "/usr/lib/python3/dist-packages/urllib3/connectionpool.py", line 699, in urlopen
    httplib_response = self._make_request(
  File "/usr/lib/python3/dist-packages/urllib3/connectionpool.py", line 394, in _make_request
    conn.request(method, url, **httplib_request_kw)
  File "/usr/lib/python3/dist-packages/urllib3/connection.py", line 234, in request
    super(HTTPConnection, self).request(method, url, body=body, headers=headers)
  File "/usr/lib/python3.10/http/client.py", line 1282, in request
    self._send_request(method, url, body, headers, encode_chunked)
  File "/usr/lib/python3.10/http/client.py", line 1328, in _send_request
    self.endheaders(body, encode_chunked=encode_chunked)
  File "/usr/lib/python3.10/http/client.py", line 1277, in endheaders
    self._send_output(message_body, encode_chunked=encode_chunked)
  File "/usr/lib/python3.10/http/client.py", line 1037, in _send_output
    self.send(msg)
  File "/usr/lib/python3.10/http/client.py", line 975, in send
    self.connect()
  File "/usr/lib/python3/dist-packages/urllib3/connection.py", line 200, in connect
    conn = self._new_conn()
  File "/usr/lib/python3/dist-packages/urllib3/connection.py", line 174, in _new_conn
    raise ConnectTimeoutError(
urllib3.exceptions.ConnectTimeoutError: (<urllib3.connection.HTTPConnection object at 0x7f5b61bab4c0>, 'Connection to archive.eso.org timed out. (connect timeout=None)')

During handling of the above exception, another exception occurred:

Traceback (most recent call last):
  File "/usr/lib/python3/dist-packages/requests/adapters.py", line 439, in send
    resp = conn.urlopen(
  File "/usr/lib/python3/dist-packages/urllib3/connectionpool.py", line 755, in urlopen
    retries = retries.increment(
  File "/usr/lib/python3/dist-packages/urllib3/util/retry.py", line 574, in increment
    raise MaxRetryError(_pool, url, error or ResponseError(cause))
urllib3.exceptions.MaxRetryError: HTTPConnectionPool(host='archive.eso.org', port=80): Max retries exceeded with url: /tap_obs/sync (Caused by ConnectTimeoutError(<urllib3.connection.HTTPConnection object at 0x7f5b61bab4c0>, 'Connection to archive.eso.org timed out. (connect timeout=None)'))

During handling of the above exception, another exception occurred:

Traceback (most recent call last):
  File "/usr/local/lib/python3.10/dist-packages/pyvo/dal/query.py", line 242, in execute_votable
    return votableparse(self.execute_stream(post=post).read)
  File "/usr/local/lib/python3.10/dist-packages/pyvo/dal/tap.py", line 926, in execute_stream
    return super().execute_stream(post=post)
  File "/usr/local/lib/python3.10/dist-packages/pyvo/utils/decorators.py", line 9, in wrapper
    raw = func(*args, **kwargs)
  File "/usr/local/lib/python3.10/dist-packages/pyvo/dal/query.py", line 191, in execute_stream
    response = self.submit(post=post)
  File "/usr/local/lib/python3.10/dist-packages/pyvo/dal/tap.py", line 959, in submit
    response = self._session.post(
  File "/usr/lib/python3/dist-packages/requests/sessions.py", line 590, in post
    return self.request('POST', url, data=data, json=json, **kwargs)
  File "/usr/lib/python3/dist-packages/requests/sessions.py", line 542, in request
    resp = self.send(prep, **send_kwargs)
  File "/usr/lib/python3/dist-packages/requests/sessions.py", line 655, in send
    r = adapter.send(request, **kwargs)
  File "/usr/lib/python3/dist-packages/requests/adapters.py", line 504, in send
    raise ConnectTimeout(e, request=request)
requests.exceptions.ConnectTimeout: HTTPConnectionPool(host='archive.eso.org', port=80): Max retries exceeded with url: /tap_obs/sync (Caused by ConnectTimeoutError(<urllib3.connection.HTTPConnection object at 0x7f5b61bab4c0>, 'Connection to archive.eso.org timed out. (connect timeout=None)'))

During handling of the above exception, another exception occurred:

Traceback (most recent call last):
  File "/home/lachaume/git/autolog/scripts/./periodlog.py", line 22, in <module>
    log = PeriodLog.fetch(telescope, period, **opts) 
  File "/home/lachaume/git/autolog/scripts/../autolog/eso/periodlog.py", line 56, in fetch
    logs = [NightLog.fetch(telescope, night, **opts)
  File "/home/lachaume/git/autolog/scripts/../autolog/eso/periodlog.py", line 56, in <listcomp>
    logs = [NightLog.fetch(telescope, night, **opts)
  File "/home/lachaume/git/autolog/scripts/../autolog/eso/nightlog.py", line 67, in fetch
    log = query.fetch(night=night, use_tap_cache=use_tap_cache)
  File "/home/lachaume/git/autolog/scripts/../autolog/eso/tapquery.py", line 115, in fetch
    tab = tap.execute().to_table()
  File "/usr/local/lib/python3.10/dist-packages/pyvo/dal/tap.py", line 942, in execute
    return TAPResults(self.execute_votable(), url=self.queryurl, session=self._session)
  File "/usr/local/lib/python3.10/dist-packages/pyvo/dal/query.py", line 245, in execute_votable
    raise DALFormatError(e, self.queryurl)
pyvo.dal.exceptions.DALFormatError: ConnectTimeout: HTTPConnectionPool(host='archive.eso.org', port=80): Max retries exceeded with url: /tap_obs/sync (Caused by ConnectTimeoutError(<urllib3.connection.HTTPConnection object at 0x7f5b61bab4c0>, 'Connection to archive.eso.org timed out. (connect timeout=None)'))

git add * in /home/lachaume/git/autolog
git commit
git push
ssh: Could not resolve hostname github.com: Temporary failure in name resolution
fatal: Could not read from remote repository.

Please make sure you have the correct access rights
and the repository exists.

ssh: Could not resolve hostname github.com: Temporary failure in name resolution
fatal: Could not read from remote repository.

Please make sure you have the correct access rights
and the repository exists.

ssh: Could not resolve hostname github.com: Temporary failure in name resolution
fatal: Could not read from remote repository.

Please make sure you have the correct access rights
and the repository exists.

executing periodlog.py in /home/lachaume/git/autolog/scripts
ssh: Could not resolve hostname github.com: Temporary failure in name resolution
fatal: Could not read from remote repository.

Please make sure you have the correct access rights
and the repository exists.


git add * in /data/www/twoptwo.com
git commit

git add * in /data/www/twoptwo.com
git commit
Everything up-to-date

Everything up-to-date


git add * in /data/www/twoptwo.com
git commit

daily.sh at 2022-07-06T16:08:01-04:00
-------------------------------------

github pull in /home/lachaume/git/autolog
Everything up-to-date


github pull in /data/www/twoptwo.com

executing periodlog.py in /home/lachaume/git/autolog/scripts
Traceback (most recent call last):
  File "/usr/lib/python3/dist-packages/urllib3/connection.py", line 169, in _new_conn
    conn = connection.create_connection(
  File "/usr/lib/python3/dist-packages/urllib3/util/connection.py", line 73, in create_connection
    for res in socket.getaddrinfo(host, port, family, socket.SOCK_STREAM):
  File "/usr/lib/python3.10/socket.py", line 955, in getaddrinfo
    for res in _socket.getaddrinfo(host, port, family, type, proto, flags):
socket.gaierror: [Errno -3] Temporary failure in name resolution

During handling of the above exception, another exception occurred:

Traceback (most recent call last):
  File "/usr/lib/python3/dist-packages/urllib3/connectionpool.py", line 699, in urlopen
    httplib_response = self._make_request(
  File "/usr/lib/python3/dist-packages/urllib3/connectionpool.py", line 394, in _make_request
    conn.request(method, url, **httplib_request_kw)
  File "/usr/lib/python3/dist-packages/urllib3/connection.py", line 234, in request
    super(HTTPConnection, self).request(method, url, body=body, headers=headers)
  File "/usr/lib/python3.10/http/client.py", line 1282, in request
    self._send_request(method, url, body, headers, encode_chunked)
  File "/usr/lib/python3.10/http/client.py", line 1328, in _send_request
    self.endheaders(body, encode_chunked=encode_chunked)
  File "/usr/lib/python3.10/http/client.py", line 1277, in endheaders
    self._send_output(message_body, encode_chunked=encode_chunked)
  File "/usr/lib/python3.10/http/client.py", line 1037, in _send_output
    self.send(msg)
  File "/usr/lib/python3.10/http/client.py", line 975, in send
    self.connect()
  File "/usr/lib/python3/dist-packages/urllib3/connection.py", line 200, in connect
    conn = self._new_conn()
  File "/usr/lib/python3/dist-packages/urllib3/connection.py", line 181, in _new_conn
    raise NewConnectionError(
urllib3.exceptions.NewConnectionError: <urllib3.connection.HTTPConnection object at 0x7f0c0442b730>: Failed to establish a new connection: [Errno -3] Temporary failure in name resolution

During handling of the above exception, another exception occurred:

Traceback (most recent call last):
  File "/usr/lib/python3/dist-packages/requests/adapters.py", line 439, in send
    resp = conn.urlopen(
  File "/usr/lib/python3/dist-packages/urllib3/connectionpool.py", line 755, in urlopen
    retries = retries.increment(
  File "/usr/lib/python3/dist-packages/urllib3/util/retry.py", line 574, in increment
    raise MaxRetryError(_pool, url, error or ResponseError(cause))
urllib3.exceptions.MaxRetryError: HTTPConnectionPool(host='archive.eso.org', port=80): Max retries exceeded with url: /tap_obs/sync (Caused by NewConnectionError('<urllib3.connection.HTTPConnection object at 0x7f0c0442b730>: Failed to establish a new connection: [Errno -3] Temporary failure in name resolution'))

During handling of the above exception, another exception occurred:

Traceback (most recent call last):
  File "/usr/local/lib/python3.10/dist-packages/pyvo/dal/query.py", line 242, in execute_votable
    return votableparse(self.execute_stream(post=post).read)
  File "/usr/local/lib/python3.10/dist-packages/pyvo/dal/tap.py", line 926, in execute_stream
    return super().execute_stream(post=post)
  File "/usr/local/lib/python3.10/dist-packages/pyvo/utils/decorators.py", line 9, in wrapper
    raw = func(*args, **kwargs)
  File "/usr/local/lib/python3.10/dist-packages/pyvo/dal/query.py", line 191, in execute_stream
    response = self.submit(post=post)
  File "/usr/local/lib/python3.10/dist-packages/pyvo/dal/tap.py", line 959, in submit
    response = self._session.post(
  File "/usr/lib/python3/dist-packages/requests/sessions.py", line 590, in post
    return self.request('POST', url, data=data, json=json, **kwargs)
  File "/usr/lib/python3/dist-packages/requests/sessions.py", line 542, in request
    resp = self.send(prep, **send_kwargs)
  File "/usr/lib/python3/dist-packages/requests/sessions.py", line 655, in send
    r = adapter.send(request, **kwargs)
  File "/usr/lib/python3/dist-packages/requests/adapters.py", line 516, in send
    raise ConnectionError(e, request=request)
requests.exceptions.ConnectionError: HTTPConnectionPool(host='archive.eso.org', port=80): Max retries exceeded with url: /tap_obs/sync (Caused by NewConnectionError('<urllib3.connection.HTTPConnection object at 0x7f0c0442b730>: Failed to establish a new connection: [Errno -3] Temporary failure in name resolution'))

During handling of the above exception, another exception occurred:

Traceback (most recent call last):
  File "/home/lachaume/git/autolog/scripts/./periodlog.py", line 22, in <module>
    log = PeriodLog.fetch(telescope, period, **opts) 
  File "/home/lachaume/git/autolog/scripts/../autolog/eso/periodlog.py", line 56, in fetch
    logs = [NightLog.fetch(telescope, night, **opts)
  File "/home/lachaume/git/autolog/scripts/../autolog/eso/periodlog.py", line 56, in <listcomp>
    logs = [NightLog.fetch(telescope, night, **opts)
  File "/home/lachaume/git/autolog/scripts/../autolog/eso/nightlog.py", line 67, in fetch
    log = query.fetch(night=night, use_tap_cache=use_tap_cache)
  File "/home/lachaume/git/autolog/scripts/../autolog/eso/tapquery.py", line 115, in fetch
    tab = tap.execute().to_table()
  File "/usr/local/lib/python3.10/dist-packages/pyvo/dal/tap.py", line 942, in execute
    return TAPResults(self.execute_votable(), url=self.queryurl, session=self._session)
  File "/usr/local/lib/python3.10/dist-packages/pyvo/dal/query.py", line 245, in execute_votable
    raise DALFormatError(e, self.queryurl)
pyvo.dal.exceptions.DALFormatError: ConnectionError: HTTPConnectionPool(host='archive.eso.org', port=80): Max retries exceeded with url: /tap_obs/sync (Caused by NewConnectionError('<urllib3.connection.HTTPConnection object at 0x7f0c0442b730>: Failed to establish a new connection: [Errno -3] Temporary failure in name resolution'))

git add * in /home/lachaume/git/autolog
git commit
git push
ssh: Could not resolve hostname github.com: Temporary failure in name resolution
fatal: Could not read from remote repository.

Please make sure you have the correct access rights
and the repository exists.


daily.sh at 2022-07-06T16:09:01-04:00
-------------------------------------

github pull in /home/lachaume/git/autolog

git add * in /data/www/twoptwo.com
git commit
ssh: Could not resolve hostname github.com: Temporary failure in name resolution
fatal: Could not read from remote repository.

Please make sure you have the correct access rights
and the repository exists.

github pull in /data/www/twoptwo.com
ssh: Could not resolve hostname github.com: Temporary failure in name resolution
fatal: Could not read from remote repository.

Please make sure you have the correct access rights
and the repository exists.

ssh: Could not resolve hostname github.com: Temporary failure in name resolution
fatal: Could not read from remote repository.

Please make sure you have the correct access rights
and the repository exists.

executing periodlog.py in /home/lachaume/git/autolog/scripts

daily.sh at 2022-07-06T16:10:01-04:00
-------------------------------------

github pull in /home/lachaume/git/autolog

daily.sh at 2022-07-06T16:11:01-04:00
-------------------------------------

github pull in /home/lachaume/git/autolog

github pull in /data/www/twoptwo.com

github pull in /data/www/twoptwo.com

executing periodlog.py in /home/lachaume/git/autolog/scripts

executing periodlog.py in /home/lachaume/git/autolog/scripts
Traceback (most recent call last):
  File "/usr/lib/python3/dist-packages/urllib3/connection.py", line 169, in _new_conn
    conn = connection.create_connection(
  File "/usr/lib/python3/dist-packages/urllib3/util/connection.py", line 73, in create_connection
    for res in socket.getaddrinfo(host, port, family, socket.SOCK_STREAM):
  File "/usr/lib/python3.10/socket.py", line 955, in getaddrinfo
    for res in _socket.getaddrinfo(host, port, family, type, proto, flags):
socket.gaierror: [Errno -3] Temporary failure in name resolution

During handling of the above exception, another exception occurred:

Traceback (most recent call last):
  File "/usr/lib/python3/dist-packages/urllib3/connectionpool.py", line 699, in urlopen
    httplib_response = self._make_request(
  File "/usr/lib/python3/dist-packages/urllib3/connectionpool.py", line 394, in _make_request
    conn.request(method, url, **httplib_request_kw)
  File "/usr/lib/python3/dist-packages/urllib3/connection.py", line 234, in request
    super(HTTPConnection, self).request(method, url, body=body, headers=headers)
  File "/usr/lib/python3.10/http/client.py", line 1282, in request
    self._send_request(method, url, body, headers, encode_chunked)
  File "/usr/lib/python3.10/http/client.py", line 1328, in _send_request
    self.endheaders(body, encode_chunked=encode_chunked)
  File "/usr/lib/python3.10/http/client.py", line 1277, in endheaders
    self._send_output(message_body, encode_chunked=encode_chunked)
  File "/usr/lib/python3.10/http/client.py", line 1037, in _send_output
    self.send(msg)
  File "/usr/lib/python3.10/http/client.py", line 975, in send
    self.connect()
  File "/usr/lib/python3/dist-packages/urllib3/connection.py", line 200, in connect
    conn = self._new_conn()
  File "/usr/lib/python3/dist-packages/urllib3/connection.py", line 181, in _new_conn
    raise NewConnectionError(
urllib3.exceptions.NewConnectionError: <urllib3.connection.HTTPConnection object at 0x7f19c183bbb0>: Failed to establish a new connection: [Errno -3] Temporary failure in name resolution

During handling of the above exception, another exception occurred:

Traceback (most recent call last):
  File "/usr/lib/python3/dist-packages/requests/adapters.py", line 439, in send
    resp = conn.urlopen(
  File "/usr/lib/python3/dist-packages/urllib3/connectionpool.py", line 755, in urlopen
    retries = retries.increment(
  File "/usr/lib/python3/dist-packages/urllib3/util/retry.py", line 574, in increment
    raise MaxRetryError(_pool, url, error or ResponseError(cause))
urllib3.exceptions.MaxRetryError: HTTPConnectionPool(host='archive.eso.org', port=80): Max retries exceeded with url: /tap_obs/sync (Caused by NewConnectionError('<urllib3.connection.HTTPConnection object at 0x7f19c183bbb0>: Failed to establish a new connection: [Errno -3] Temporary failure in name resolution'))

During handling of the above exception, another exception occurred:

Traceback (most recent call last):
  File "/usr/local/lib/python3.10/dist-packages/pyvo/dal/query.py", line 242, in execute_votable
    return votableparse(self.execute_stream(post=post).read)
  File "/usr/local/lib/python3.10/dist-packages/pyvo/dal/tap.py", line 926, in execute_stream
    return super().execute_stream(post=post)
  File "/usr/local/lib/python3.10/dist-packages/pyvo/utils/decorators.py", line 9, in wrapper
    raw = func(*args, **kwargs)
  File "/usr/local/lib/python3.10/dist-packages/pyvo/dal/query.py", line 191, in execute_stream
    response = self.submit(post=post)
  File "/usr/local/lib/python3.10/dist-packages/pyvo/dal/tap.py", line 959, in submit
    response = self._session.post(
  File "/usr/lib/python3/dist-packages/requests/sessions.py", line 590, in post
    return self.request('POST', url, data=data, json=json, **kwargs)
  File "/usr/lib/python3/dist-packages/requests/sessions.py", line 542, in request
    resp = self.send(prep, **send_kwargs)
  File "/usr/lib/python3/dist-packages/requests/sessions.py", line 655, in send
    r = adapter.send(request, **kwargs)
  File "/usr/lib/python3/dist-packages/requests/adapters.py", line 516, in send
    raise ConnectionError(e, request=request)
requests.exceptions.ConnectionError: HTTPConnectionPool(host='archive.eso.org', port=80): Max retries exceeded with url: /tap_obs/sync (Caused by NewConnectionError('<urllib3.connection.HTTPConnection object at 0x7f19c183bbb0>: Failed to establish a new connection: [Errno -3] Temporary failure in name resolution'))

During handling of the above exception, another exception occurred:

Traceback (most recent call last):
  File "/home/lachaume/git/autolog/scripts/./periodlog.py", line 22, in <module>
    log = PeriodLog.fetch(telescope, period, **opts) 
  File "/home/lachaume/git/autolog/scripts/../autolog/eso/periodlog.py", line 56, in fetch
    logs = [NightLog.fetch(telescope, night, **opts)
  File "/home/lachaume/git/autolog/scripts/../autolog/eso/periodlog.py", line 56, in <listcomp>
    logs = [NightLog.fetch(telescope, night, **opts)
  File "/home/lachaume/git/autolog/scripts/../autolog/eso/nightlog.py", line 67, in fetch
    log = query.fetch(night=night, use_tap_cache=use_tap_cache)
  File "/home/lachaume/git/autolog/scripts/../autolog/eso/tapquery.py", line 115, in fetch
    tab = tap.execute().to_table()
  File "/usr/local/lib/python3.10/dist-packages/pyvo/dal/tap.py", line 942, in execute
    return TAPResults(self.execute_votable(), url=self.queryurl, session=self._session)
  File "/usr/local/lib/python3.10/dist-packages/pyvo/dal/query.py", line 245, in execute_votable
    raise DALFormatError(e, self.queryurl)
pyvo.dal.exceptions.DALFormatError: ConnectionError: HTTPConnectionPool(host='archive.eso.org', port=80): Max retries exceeded with url: /tap_obs/sync (Caused by NewConnectionError('<urllib3.connection.HTTPConnection object at 0x7f19c183bbb0>: Failed to establish a new connection: [Errno -3] Temporary failure in name resolution'))

git add * in /home/lachaume/git/autolog
git commit
git push

daily.sh at 2022-07-06T16:12:01-04:00
-------------------------------------

github pull in /home/lachaume/git/autolog
ssh: Could not resolve hostname github.com: Temporary failure in name resolution
fatal: Could not read from remote repository.

Please make sure you have the correct access rights
and the repository exists.

ssh: Could not resolve hostname github.com: Temporary failure in name resolution
fatal: Could not read from remote repository.

Please make sure you have the correct access rights
and the repository exists.

github pull in /data/www/twoptwo.com

git add * in /data/www/twoptwo.com
git commit
ssh: Could not resolve hostname github.com: Temporary failure in name resolution
fatal: Could not read from remote repository.

Please make sure you have the correct access rights
and the repository exists.

executing periodlog.py in /home/lachaume/git/autolog/scripts

daily.sh at 2022-07-06T16:13:01-04:00
-------------------------------------

github pull in /home/lachaume/git/autolog
Traceback (most recent call last):
  File "/usr/lib/python3/dist-packages/urllib3/connection.py", line 169, in _new_conn
    conn = connection.create_connection(
  File "/usr/lib/python3/dist-packages/urllib3/util/connection.py", line 73, in create_connection
    for res in socket.getaddrinfo(host, port, family, socket.SOCK_STREAM):
  File "/usr/lib/python3.10/socket.py", line 955, in getaddrinfo
    for res in _socket.getaddrinfo(host, port, family, type, proto, flags):
socket.gaierror: [Errno -3] Temporary failure in name resolution

During handling of the above exception, another exception occurred:

Traceback (most recent call last):
  File "/usr/lib/python3/dist-packages/urllib3/connectionpool.py", line 699, in urlopen
    httplib_response = self._make_request(
  File "/usr/lib/python3/dist-packages/urllib3/connectionpool.py", line 394, in _make_request
    conn.request(method, url, **httplib_request_kw)
  File "/usr/lib/python3/dist-packages/urllib3/connection.py", line 234, in request
    super(HTTPConnection, self).request(method, url, body=body, headers=headers)
  File "/usr/lib/python3.10/http/client.py", line 1282, in request
    self._send_request(method, url, body, headers, encode_chunked)
  File "/usr/lib/python3.10/http/client.py", line 1328, in _send_request
    self.endheaders(body, encode_chunked=encode_chunked)
  File "/usr/lib/python3.10/http/client.py", line 1277, in endheaders
    self._send_output(message_body, encode_chunked=encode_chunked)
  File "/usr/lib/python3.10/http/client.py", line 1037, in _send_output
    self.send(msg)
  File "/usr/lib/python3.10/http/client.py", line 975, in send
    self.connect()
  File "/usr/lib/python3/dist-packages/urllib3/connection.py", line 200, in connect
    conn = self._new_conn()
  File "/usr/lib/python3/dist-packages/urllib3/connection.py", line 181, in _new_conn
    raise NewConnectionError(
urllib3.exceptions.NewConnectionError: <urllib3.connection.HTTPConnection object at 0x7f4b003980d0>: Failed to establish a new connection: [Errno -3] Temporary failure in name resolution

During handling of the above exception, another exception occurred:

Traceback (most recent call last):
  File "/usr/lib/python3/dist-packages/requests/adapters.py", line 439, in send
    resp = conn.urlopen(
  File "/usr/lib/python3/dist-packages/urllib3/connectionpool.py", line 755, in urlopen
    retries = retries.increment(
  File "/usr/lib/python3/dist-packages/urllib3/util/retry.py", line 574, in increment
    raise MaxRetryError(_pool, url, error or ResponseError(cause))
urllib3.exceptions.MaxRetryError: HTTPConnectionPool(host='archive.eso.org', port=80): Max retries exceeded with url: /tap_obs/sync (Caused by NewConnectionError('<urllib3.connection.HTTPConnection object at 0x7f4b003980d0>: Failed to establish a new connection: [Errno -3] Temporary failure in name resolution'))

During handling of the above exception, another exception occurred:

Traceback (most recent call last):
  File "/usr/local/lib/python3.10/dist-packages/pyvo/dal/query.py", line 242, in execute_votable
    return votableparse(self.execute_stream(post=post).read)
  File "/usr/local/lib/python3.10/dist-packages/pyvo/dal/tap.py", line 926, in execute_stream
    return super().execute_stream(post=post)
  File "/usr/local/lib/python3.10/dist-packages/pyvo/utils/decorators.py", line 9, in wrapper
    raw = func(*args, **kwargs)
  File "/usr/local/lib/python3.10/dist-packages/pyvo/dal/query.py", line 191, in execute_stream
    response = self.submit(post=post)
  File "/usr/local/lib/python3.10/dist-packages/pyvo/dal/tap.py", line 959, in submit
    response = self._session.post(
  File "/usr/lib/python3/dist-packages/requests/sessions.py", line 590, in post
    return self.request('POST', url, data=data, json=json, **kwargs)
  File "/usr/lib/python3/dist-packages/requests/sessions.py", line 542, in request
    resp = self.send(prep, **send_kwargs)
  File "/usr/lib/python3/dist-packages/requests/sessions.py", line 655, in send
    r = adapter.send(request, **kwargs)
  File "/usr/lib/python3/dist-packages/requests/adapters.py", line 516, in send
    raise ConnectionError(e, request=request)
requests.exceptions.ConnectionError: HTTPConnectionPool(host='archive.eso.org', port=80): Max retries exceeded with url: /tap_obs/sync (Caused by NewConnectionError('<urllib3.connection.HTTPConnection object at 0x7f4b003980d0>: Failed to establish a new connection: [Errno -3] Temporary failure in name resolution'))

During handling of the above exception, another exception occurred:

Traceback (most recent call last):
  File "/home/lachaume/git/autolog/scripts/./periodlog.py", line 22, in <module>
    log = PeriodLog.fetch(telescope, period, **opts) 
  File "/home/lachaume/git/autolog/scripts/../autolog/eso/periodlog.py", line 56, in fetch
    logs = [NightLog.fetch(telescope, night, **opts)
  File "/home/lachaume/git/autolog/scripts/../autolog/eso/periodlog.py", line 56, in <listcomp>
    logs = [NightLog.fetch(telescope, night, **opts)
  File "/home/lachaume/git/autolog/scripts/../autolog/eso/nightlog.py", line 67, in fetch
    log = query.fetch(night=night, use_tap_cache=use_tap_cache)
  File "/home/lachaume/git/autolog/scripts/../autolog/eso/tapquery.py", line 115, in fetch
    tab = tap.execute().to_table()
  File "/usr/local/lib/python3.10/dist-packages/pyvo/dal/tap.py", line 942, in execute
    return TAPResults(self.execute_votable(), url=self.queryurl, session=self._session)
  File "/usr/local/lib/python3.10/dist-packages/pyvo/dal/query.py", line 245, in execute_votable
    raise DALFormatError(e, self.queryurl)
pyvo.dal.exceptions.DALFormatError: ConnectionError: HTTPConnectionPool(host='archive.eso.org', port=80): Max retries exceeded with url: /tap_obs/sync (Caused by NewConnectionError('<urllib3.connection.HTTPConnection object at 0x7f4b003980d0>: Failed to establish a new connection: [Errno -3] Temporary failure in name resolution'))

git add * in /home/lachaume/git/autolog
git commit
git push
ssh: Could not resolve hostname github.com: Temporary failure in name resolution
fatal: Could not read from remote repository.

Please make sure you have the correct access rights
and the repository exists.

github pull in /data/www/twoptwo.com
ssh: Could not resolve hostname github.com: Temporary failure in name resolution
fatal: Could not read from remote repository.

Please make sure you have the correct access rights
and the repository exists.

ssh: Could not resolve hostname github.com: Temporary failure in name resolution
fatal: Could not read from remote repository.

Please make sure you have the correct access rights
and the repository exists.

executing periodlog.py in /home/lachaume/git/autolog/scripts

git add * in /data/www/twoptwo.com
git commit

daily.sh at 2022-07-06T16:14:01-04:00
-------------------------------------

github pull in /home/lachaume/git/autolog
Traceback (most recent call last):
  File "/usr/lib/python3/dist-packages/urllib3/connection.py", line 169, in _new_conn
    conn = connection.create_connection(
  File "/usr/lib/python3/dist-packages/urllib3/util/connection.py", line 73, in create_connection
    for res in socket.getaddrinfo(host, port, family, socket.SOCK_STREAM):
  File "/usr/lib/python3.10/socket.py", line 955, in getaddrinfo
    for res in _socket.getaddrinfo(host, port, family, type, proto, flags):
socket.gaierror: [Errno -3] Temporary failure in name resolution

During handling of the above exception, another exception occurred:

Traceback (most recent call last):
  File "/usr/lib/python3/dist-packages/urllib3/connectionpool.py", line 699, in urlopen
    httplib_response = self._make_request(
  File "/usr/lib/python3/dist-packages/urllib3/connectionpool.py", line 394, in _make_request
    conn.request(method, url, **httplib_request_kw)
  File "/usr/lib/python3/dist-packages/urllib3/connection.py", line 234, in request
    super(HTTPConnection, self).request(method, url, body=body, headers=headers)
  File "/usr/lib/python3.10/http/client.py", line 1282, in request
    self._send_request(method, url, body, headers, encode_chunked)
  File "/usr/lib/python3.10/http/client.py", line 1328, in _send_request
    self.endheaders(body, encode_chunked=encode_chunked)
  File "/usr/lib/python3.10/http/client.py", line 1277, in endheaders
    self._send_output(message_body, encode_chunked=encode_chunked)
  File "/usr/lib/python3.10/http/client.py", line 1037, in _send_output
    self.send(msg)
  File "/usr/lib/python3.10/http/client.py", line 975, in send
    self.connect()
  File "/usr/lib/python3/dist-packages/urllib3/connection.py", line 200, in connect
    conn = self._new_conn()
  File "/usr/lib/python3/dist-packages/urllib3/connection.py", line 181, in _new_conn
    raise NewConnectionError(
urllib3.exceptions.NewConnectionError: <urllib3.connection.HTTPConnection object at 0x7f4c1b610670>: Failed to establish a new connection: [Errno -3] Temporary failure in name resolution

During handling of the above exception, another exception occurred:

Traceback (most recent call last):
  File "/usr/lib/python3/dist-packages/requests/adapters.py", line 439, in send
    resp = conn.urlopen(
  File "/usr/lib/python3/dist-packages/urllib3/connectionpool.py", line 755, in urlopen
    retries = retries.increment(
  File "/usr/lib/python3/dist-packages/urllib3/util/retry.py", line 574, in increment
    raise MaxRetryError(_pool, url, error or ResponseError(cause))
urllib3.exceptions.MaxRetryError: HTTPConnectionPool(host='archive.eso.org', port=80): Max retries exceeded with url: /tap_obs/sync (Caused by NewConnectionError('<urllib3.connection.HTTPConnection object at 0x7f4c1b610670>: Failed to establish a new connection: [Errno -3] Temporary failure in name resolution'))

During handling of the above exception, another exception occurred:

Traceback (most recent call last):
  File "/usr/local/lib/python3.10/dist-packages/pyvo/dal/query.py", line 242, in execute_votable
    return votableparse(self.execute_stream(post=post).read)
  File "/usr/local/lib/python3.10/dist-packages/pyvo/dal/tap.py", line 926, in execute_stream
    return super().execute_stream(post=post)
  File "/usr/local/lib/python3.10/dist-packages/pyvo/utils/decorators.py", line 9, in wrapper
    raw = func(*args, **kwargs)
  File "/usr/local/lib/python3.10/dist-packages/pyvo/dal/query.py", line 191, in execute_stream
    response = self.submit(post=post)
  File "/usr/local/lib/python3.10/dist-packages/pyvo/dal/tap.py", line 959, in submit
    response = self._session.post(
  File "/usr/lib/python3/dist-packages/requests/sessions.py", line 590, in post
    return self.request('POST', url, data=data, json=json, **kwargs)
  File "/usr/lib/python3/dist-packages/requests/sessions.py", line 542, in request
    resp = self.send(prep, **send_kwargs)
  File "/usr/lib/python3/dist-packages/requests/sessions.py", line 655, in send
    r = adapter.send(request, **kwargs)
  File "/usr/lib/python3/dist-packages/requests/adapters.py", line 516, in send
    raise ConnectionError(e, request=request)
requests.exceptions.ConnectionError: HTTPConnectionPool(host='archive.eso.org', port=80): Max retries exceeded with url: /tap_obs/sync (Caused by NewConnectionError('<urllib3.connection.HTTPConnection object at 0x7f4c1b610670>: Failed to establish a new connection: [Errno -3] Temporary failure in name resolution'))

During handling of the above exception, another exception occurred:

Traceback (most recent call last):
  File "/home/lachaume/git/autolog/scripts/./periodlog.py", line 22, in <module>
    log = PeriodLog.fetch(telescope, period, **opts) 
  File "/home/lachaume/git/autolog/scripts/../autolog/eso/periodlog.py", line 56, in fetch
    logs = [NightLog.fetch(telescope, night, **opts)
  File "/home/lachaume/git/autolog/scripts/../autolog/eso/periodlog.py", line 56, in <listcomp>
    logs = [NightLog.fetch(telescope, night, **opts)
  File "/home/lachaume/git/autolog/scripts/../autolog/eso/nightlog.py", line 67, in fetch
    log = query.fetch(night=night, use_tap_cache=use_tap_cache)
  File "/home/lachaume/git/autolog/scripts/../autolog/eso/tapquery.py", line 115, in fetch
    tab = tap.execute().to_table()
  File "/usr/local/lib/python3.10/dist-packages/pyvo/dal/tap.py", line 942, in execute
    return TAPResults(self.execute_votable(), url=self.queryurl, session=self._session)
  File "/usr/local/lib/python3.10/dist-packages/pyvo/dal/query.py", line 245, in execute_votable
    raise DALFormatError(e, self.queryurl)
pyvo.dal.exceptions.DALFormatError: ConnectionError: HTTPConnectionPool(host='archive.eso.org', port=80): Max retries exceeded with url: /tap_obs/sync (Caused by NewConnectionError('<urllib3.connection.HTTPConnection object at 0x7f4c1b610670>: Failed to establish a new connection: [Errno -3] Temporary failure in name resolution'))

git add * in /home/lachaume/git/autolog
git commit
git push
ssh: Could not resolve hostname github.com: Temporary failure in name resolution
fatal: Could not read from remote repository.

Please make sure you have the correct access rights
and the repository exists.

ssh: Could not resolve hostname github.com: Temporary failure in name resolution
fatal: Could not read from remote repository.

Please make sure you have the correct access rights
and the repository exists.

github pull in /data/www/twoptwo.com
ssh: Could not resolve hostname github.com: Temporary failure in name resolution
fatal: Could not read from remote repository.

Please make sure you have the correct access rights
and the repository exists.


executing periodlog.py in /home/lachaume/git/autolog/scripts

git add * in /data/www/twoptwo.com
git commit
Everything up-to-date


daily.sh at 2022-07-06T16:15:01-04:00
-------------------------------------

github pull in /home/lachaume/git/autolog
ssh: Could not resolve hostname github.com: Temporary failure in name resolution
fatal: Could not read from remote repository.

Please make sure you have the correct access rights
and the repository exists.

github pull in /data/www/twoptwo.com
ssh: Could not resolve hostname github.com: Temporary failure in name resolution
fatal: Could not read from remote repository.

Please make sure you have the correct access rights
and the repository exists.

executing periodlog.py in /home/lachaume/git/autolog/scripts

daily.sh at 2022-07-06T16:16:01-04:00
-------------------------------------

github pull in /home/lachaume/git/autolog
Traceback (most recent call last):
  File "/usr/lib/python3/dist-packages/urllib3/connection.py", line 169, in _new_conn
    conn = connection.create_connection(
  File "/usr/lib/python3/dist-packages/urllib3/util/connection.py", line 73, in create_connection
    for res in socket.getaddrinfo(host, port, family, socket.SOCK_STREAM):
  File "/usr/lib/python3.10/socket.py", line 955, in getaddrinfo
    for res in _socket.getaddrinfo(host, port, family, type, proto, flags):
socket.gaierror: [Errno -3] Temporary failure in name resolution

During handling of the above exception, another exception occurred:

Traceback (most recent call last):
  File "/usr/lib/python3/dist-packages/urllib3/connectionpool.py", line 699, in urlopen
    httplib_response = self._make_request(
  File "/usr/lib/python3/dist-packages/urllib3/connectionpool.py", line 394, in _make_request
    conn.request(method, url, **httplib_request_kw)
  File "/usr/lib/python3/dist-packages/urllib3/connection.py", line 234, in request
    super(HTTPConnection, self).request(method, url, body=body, headers=headers)
  File "/usr/lib/python3.10/http/client.py", line 1282, in request
    self._send_request(method, url, body, headers, encode_chunked)
  File "/usr/lib/python3.10/http/client.py", line 1328, in _send_request
    self.endheaders(body, encode_chunked=encode_chunked)
  File "/usr/lib/python3.10/http/client.py", line 1277, in endheaders
    self._send_output(message_body, encode_chunked=encode_chunked)
  File "/usr/lib/python3.10/http/client.py", line 1037, in _send_output
    self.send(msg)
  File "/usr/lib/python3.10/http/client.py", line 975, in send
    self.connect()
  File "/usr/lib/python3/dist-packages/urllib3/connection.py", line 200, in connect
    conn = self._new_conn()
  File "/usr/lib/python3/dist-packages/urllib3/connection.py", line 181, in _new_conn
    raise NewConnectionError(
urllib3.exceptions.NewConnectionError: <urllib3.connection.HTTPConnection object at 0x7fabbbb946d0>: Failed to establish a new connection: [Errno -3] Temporary failure in name resolution

During handling of the above exception, another exception occurred:

Traceback (most recent call last):
  File "/usr/lib/python3/dist-packages/requests/adapters.py", line 439, in send
    resp = conn.urlopen(
  File "/usr/lib/python3/dist-packages/urllib3/connectionpool.py", line 755, in urlopen
    retries = retries.increment(
  File "/usr/lib/python3/dist-packages/urllib3/util/retry.py", line 574, in increment
    raise MaxRetryError(_pool, url, error or ResponseError(cause))
urllib3.exceptions.MaxRetryError: HTTPConnectionPool(host='archive.eso.org', port=80): Max retries exceeded with url: /tap_obs/sync (Caused by NewConnectionError('<urllib3.connection.HTTPConnection object at 0x7fabbbb946d0>: Failed to establish a new connection: [Errno -3] Temporary failure in name resolution'))

During handling of the above exception, another exception occurred:

Traceback (most recent call last):
  File "/usr/local/lib/python3.10/dist-packages/pyvo/dal/query.py", line 242, in execute_votable
    return votableparse(self.execute_stream(post=post).read)
  File "/usr/local/lib/python3.10/dist-packages/pyvo/dal/tap.py", line 926, in execute_stream
    return super().execute_stream(post=post)
  File "/usr/local/lib/python3.10/dist-packages/pyvo/utils/decorators.py", line 9, in wrapper
    raw = func(*args, **kwargs)
  File "/usr/local/lib/python3.10/dist-packages/pyvo/dal/query.py", line 191, in execute_stream
    response = self.submit(post=post)
  File "/usr/local/lib/python3.10/dist-packages/pyvo/dal/tap.py", line 959, in submit
    response = self._session.post(
  File "/usr/lib/python3/dist-packages/requests/sessions.py", line 590, in post
    return self.request('POST', url, data=data, json=json, **kwargs)
  File "/usr/lib/python3/dist-packages/requests/sessions.py", line 542, in request
    resp = self.send(prep, **send_kwargs)
  File "/usr/lib/python3/dist-packages/requests/sessions.py", line 655, in send
    r = adapter.send(request, **kwargs)
  File "/usr/lib/python3/dist-packages/requests/adapters.py", line 516, in send
    raise ConnectionError(e, request=request)
requests.exceptions.ConnectionError: HTTPConnectionPool(host='archive.eso.org', port=80): Max retries exceeded with url: /tap_obs/sync (Caused by NewConnectionError('<urllib3.connection.HTTPConnection object at 0x7fabbbb946d0>: Failed to establish a new connection: [Errno -3] Temporary failure in name resolution'))

During handling of the above exception, another exception occurred:

Traceback (most recent call last):
  File "/home/lachaume/git/autolog/scripts/./periodlog.py", line 22, in <module>
    log = PeriodLog.fetch(telescope, period, **opts) 
  File "/home/lachaume/git/autolog/scripts/../autolog/eso/periodlog.py", line 56, in fetch
    logs = [NightLog.fetch(telescope, night, **opts)
  File "/home/lachaume/git/autolog/scripts/../autolog/eso/periodlog.py", line 56, in <listcomp>
    logs = [NightLog.fetch(telescope, night, **opts)
  File "/home/lachaume/git/autolog/scripts/../autolog/eso/nightlog.py", line 67, in fetch
    log = query.fetch(night=night, use_tap_cache=use_tap_cache)
  File "/home/lachaume/git/autolog/scripts/../autolog/eso/tapquery.py", line 115, in fetch
    tab = tap.execute().to_table()
  File "/usr/local/lib/python3.10/dist-packages/pyvo/dal/tap.py", line 942, in execute
    return TAPResults(self.execute_votable(), url=self.queryurl, session=self._session)
  File "/usr/local/lib/python3.10/dist-packages/pyvo/dal/query.py", line 245, in execute_votable
    raise DALFormatError(e, self.queryurl)
pyvo.dal.exceptions.DALFormatError: ConnectionError: HTTPConnectionPool(host='archive.eso.org', port=80): Max retries exceeded with url: /tap_obs/sync (Caused by NewConnectionError('<urllib3.connection.HTTPConnection object at 0x7fabbbb946d0>: Failed to establish a new connection: [Errno -3] Temporary failure in name resolution'))

git add * in /home/lachaume/git/autolog
git commit
git push
warning: fetch updated the current branch head.
fast-forwarding your working tree from
commit d9555df8db393b7e1108485fb4ba2b103f47f195.
error: Your local changes to the following files would be overwritten by merge:
	scripts/logs/2022-07-06.err
	scripts/logs/2022-07-06.log
Please commit your changes or stash them before you merge.
Aborting
fatal: Cannot fast-forward your working tree.
After making sure that you saved anything precious from
$ git diff d9555df8db393b7e1108485fb4ba2b103f47f195
output, run
$ git reset --hard
to recover.

github pull in /data/www/twoptwo.com
To github.com:loqueelvientoajuarez/obslog.git
   d892d72..123be01  master -> master


executing periodlog.py in /home/lachaume/git/autolog/scripts

git add * in /data/www/twoptwo.com
git commit
Everything up-to-date


daily.sh at 2022-07-06T16:17:01-04:00
-------------------------------------

github pull in /home/lachaume/git/autolog
ssh: Could not resolve hostname github.com: Temporary failure in name resolution
fatal: Could not read from remote repository.

Please make sure you have the correct access rights
and the repository exists.

github pull in /data/www/twoptwo.com
ssh: Could not resolve hostname github.com: Temporary failure in name resolution
fatal: Could not read from remote repository.

Please make sure you have the correct access rights
and the repository exists.

executing periodlog.py in /home/lachaume/git/autolog/scripts

daily.sh at 2022-07-06T16:18:01-04:00
-------------------------------------

github pull in /home/lachaume/git/autolog
Traceback (most recent call last):
  File "/usr/lib/python3/dist-packages/urllib3/connection.py", line 169, in _new_conn
    conn = connection.create_connection(
  File "/usr/lib/python3/dist-packages/urllib3/util/connection.py", line 73, in create_connection
    for res in socket.getaddrinfo(host, port, family, socket.SOCK_STREAM):
  File "/usr/lib/python3.10/socket.py", line 955, in getaddrinfo
    for res in _socket.getaddrinfo(host, port, family, type, proto, flags):
socket.gaierror: [Errno -3] Temporary failure in name resolution

During handling of the above exception, another exception occurred:

Traceback (most recent call last):
  File "/usr/lib/python3/dist-packages/urllib3/connectionpool.py", line 699, in urlopen
    httplib_response = self._make_request(
  File "/usr/lib/python3/dist-packages/urllib3/connectionpool.py", line 394, in _make_request
    conn.request(method, url, **httplib_request_kw)
  File "/usr/lib/python3/dist-packages/urllib3/connection.py", line 234, in request
    super(HTTPConnection, self).request(method, url, body=body, headers=headers)
  File "/usr/lib/python3.10/http/client.py", line 1282, in request
    self._send_request(method, url, body, headers, encode_chunked)
  File "/usr/lib/python3.10/http/client.py", line 1328, in _send_request
    self.endheaders(body, encode_chunked=encode_chunked)
  File "/usr/lib/python3.10/http/client.py", line 1277, in endheaders
    self._send_output(message_body, encode_chunked=encode_chunked)
  File "/usr/lib/python3.10/http/client.py", line 1037, in _send_output
    self.send(msg)
  File "/usr/lib/python3.10/http/client.py", line 975, in send
    self.connect()
  File "/usr/lib/python3/dist-packages/urllib3/connection.py", line 200, in connect
    conn = self._new_conn()
  File "/usr/lib/python3/dist-packages/urllib3/connection.py", line 181, in _new_conn
    raise NewConnectionError(
urllib3.exceptions.NewConnectionError: <urllib3.connection.HTTPConnection object at 0x7f79d2afbe50>: Failed to establish a new connection: [Errno -3] Temporary failure in name resolution

During handling of the above exception, another exception occurred:

Traceback (most recent call last):
  File "/usr/lib/python3/dist-packages/requests/adapters.py", line 439, in send
    resp = conn.urlopen(
  File "/usr/lib/python3/dist-packages/urllib3/connectionpool.py", line 755, in urlopen
    retries = retries.increment(
  File "/usr/lib/python3/dist-packages/urllib3/util/retry.py", line 574, in increment
    raise MaxRetryError(_pool, url, error or ResponseError(cause))
urllib3.exceptions.MaxRetryError: HTTPConnectionPool(host='archive.eso.org', port=80): Max retries exceeded with url: /tap_obs/sync (Caused by NewConnectionError('<urllib3.connection.HTTPConnection object at 0x7f79d2afbe50>: Failed to establish a new connection: [Errno -3] Temporary failure in name resolution'))

During handling of the above exception, another exception occurred:

Traceback (most recent call last):
  File "/usr/local/lib/python3.10/dist-packages/pyvo/dal/query.py", line 242, in execute_votable
    return votableparse(self.execute_stream(post=post).read)
  File "/usr/local/lib/python3.10/dist-packages/pyvo/dal/tap.py", line 926, in execute_stream
    return super().execute_stream(post=post)
  File "/usr/local/lib/python3.10/dist-packages/pyvo/utils/decorators.py", line 9, in wrapper
    raw = func(*args, **kwargs)
  File "/usr/local/lib/python3.10/dist-packages/pyvo/dal/query.py", line 191, in execute_stream
    response = self.submit(post=post)
  File "/usr/local/lib/python3.10/dist-packages/pyvo/dal/tap.py", line 959, in submit
    response = self._session.post(
  File "/usr/lib/python3/dist-packages/requests/sessions.py", line 590, in post
    return self.request('POST', url, data=data, json=json, **kwargs)
  File "/usr/lib/python3/dist-packages/requests/sessions.py", line 542, in request
    resp = self.send(prep, **send_kwargs)
  File "/usr/lib/python3/dist-packages/requests/sessions.py", line 655, in send
    r = adapter.send(request, **kwargs)
  File "/usr/lib/python3/dist-packages/requests/adapters.py", line 516, in send
    raise ConnectionError(e, request=request)
requests.exceptions.ConnectionError: HTTPConnectionPool(host='archive.eso.org', port=80): Max retries exceeded with url: /tap_obs/sync (Caused by NewConnectionError('<urllib3.connection.HTTPConnection object at 0x7f79d2afbe50>: Failed to establish a new connection: [Errno -3] Temporary failure in name resolution'))

During handling of the above exception, another exception occurred:

Traceback (most recent call last):
  File "/home/lachaume/git/autolog/scripts/./periodlog.py", line 22, in <module>
    log = PeriodLog.fetch(telescope, period, **opts) 
  File "/home/lachaume/git/autolog/scripts/../autolog/eso/periodlog.py", line 56, in fetch
    logs = [NightLog.fetch(telescope, night, **opts)
  File "/home/lachaume/git/autolog/scripts/../autolog/eso/periodlog.py", line 56, in <listcomp>
    logs = [NightLog.fetch(telescope, night, **opts)
  File "/home/lachaume/git/autolog/scripts/../autolog/eso/nightlog.py", line 67, in fetch
    log = query.fetch(night=night, use_tap_cache=use_tap_cache)
  File "/home/lachaume/git/autolog/scripts/../autolog/eso/tapquery.py", line 115, in fetch
    tab = tap.execute().to_table()
  File "/usr/local/lib/python3.10/dist-packages/pyvo/dal/tap.py", line 942, in execute
    return TAPResults(self.execute_votable(), url=self.queryurl, session=self._session)
  File "/usr/local/lib/python3.10/dist-packages/pyvo/dal/query.py", line 245, in execute_votable
    raise DALFormatError(e, self.queryurl)
pyvo.dal.exceptions.DALFormatError: ConnectionError: HTTPConnectionPool(host='archive.eso.org', port=80): Max retries exceeded with url: /tap_obs/sync (Caused by NewConnectionError('<urllib3.connection.HTTPConnection object at 0x7f79d2afbe50>: Failed to establish a new connection: [Errno -3] Temporary failure in name resolution'))

git add * in /home/lachaume/git/autolog
git commit
git push
warning: fetch updated the current branch head.
fast-forwarding your working tree from
commit 123be01817e36462434be24c78850cb3172bd077.
error: Your local changes to the following files would be overwritten by merge:
	scripts/logs/2022-07-06.err
	scripts/logs/2022-07-06.log
Please commit your changes or stash them before you merge.
Aborting
fatal: Cannot fast-forward your working tree.
After making sure that you saved anything precious from
$ git diff 123be01817e36462434be24c78850cb3172bd077
output, run
$ git reset --hard
to recover.

github pull in /data/www/twoptwo.com
To github.com:loqueelvientoajuarez/obslog.git
   123be01..33b5abd  master -> master


executing periodlog.py in /home/lachaume/git/autolog/scripts

git add * in /data/www/twoptwo.com
git commit

daily.sh at 2022-07-06T16:19:01-04:00
-------------------------------------

github pull in /home/lachaume/git/autolog
ssh: Could not resolve hostname github.com: Temporary failure in name resolution
fatal: Could not read from remote repository.

Please make sure you have the correct access rights
and the repository exists.

github pull in /data/www/twoptwo.com

executing periodlog.py in /home/lachaume/git/autolog/scripts
Traceback (most recent call last):
  File "/usr/lib/python3.10/http/client.py", line 591, in _read_chunked
    value.append(self._safe_read(chunk_left))
  File "/usr/lib/python3.10/http/client.py", line 632, in _safe_read
    raise IncompleteRead(data, amt-len(data))
http.client.IncompleteRead: IncompleteRead(2268 bytes read, 5225 more expected)

During handling of the above exception, another exception occurred:

Traceback (most recent call last):
  File "/usr/lib/python3/dist-packages/urllib3/response.py", line 438, in _error_catcher
    yield
  File "/usr/lib/python3/dist-packages/urllib3/response.py", line 519, in read
    data = self._fp.read(amt) if not fp_closed else b""
  File "/usr/lib/python3.10/http/client.py", line 459, in read
    return self._read_chunked(amt)
  File "/usr/lib/python3.10/http/client.py", line 597, in _read_chunked
    raise IncompleteRead(b''.join(value))
http.client.IncompleteRead: IncompleteRead(8192 bytes read)

During handling of the above exception, another exception occurred:

Traceback (most recent call last):
  File "/usr/local/lib/python3.10/dist-packages/pyvo/dal/query.py", line 242, in execute_votable
    return votableparse(self.execute_stream(post=post).read)
  File "/usr/local/lib/python3.10/dist-packages/astropy/utils/decorators.py", line 546, in wrapper
    return function(*args, **kwargs)
  File "/usr/local/lib/python3.10/dist-packages/astropy/io/votable/table.py", line 160, in parse
    config=config, pos=(1, 1)).parse(iterator, config)
  File "/usr/local/lib/python3.10/dist-packages/astropy/io/votable/tree.py", line 3615, in parse
    tag_mapping.get(tag, self._add_unknown_tag)(
  File "/usr/local/lib/python3.10/dist-packages/astropy/io/votable/tree.py", line 3494, in _add_resource
    resource.parse(self, iterator, config)
  File "/usr/local/lib/python3.10/dist-packages/astropy/io/votable/tree.py", line 3292, in parse
    tag_mapping.get(tag, self._add_unknown_tag)(
  File "/usr/local/lib/python3.10/dist-packages/astropy/io/votable/tree.py", line 3238, in _add_table
    table.parse(iterator, config)
  File "/usr/local/lib/python3.10/dist-packages/astropy/io/votable/tree.py", line 2513, in parse
    self.array = self._parse_tabledata(
  File "/usr/local/lib/python3.10/dist-packages/astropy/io/votable/tree.py", line 2591, in _parse_tabledata
    for start, tag, data, pos in iterator:
  File "/usr/lib/python3/dist-packages/urllib3/response.py", line 512, in read
    with self._error_catcher():
  File "/usr/lib/python3.10/contextlib.py", line 153, in __exit__
    self.gen.throw(typ, value, traceback)
  File "/usr/lib/python3/dist-packages/urllib3/response.py", line 455, in _error_catcher
    raise ProtocolError("Connection broken: %r" % e, e)
urllib3.exceptions.ProtocolError: ('Connection broken: IncompleteRead(8192 bytes read)', IncompleteRead(8192 bytes read))

During handling of the above exception, another exception occurred:

Traceback (most recent call last):
  File "/home/lachaume/git/autolog/scripts/./periodlog.py", line 22, in <module>
    log = PeriodLog.fetch(telescope, period, **opts) 
  File "/home/lachaume/git/autolog/scripts/../autolog/eso/periodlog.py", line 56, in fetch
    logs = [NightLog.fetch(telescope, night, **opts)
  File "/home/lachaume/git/autolog/scripts/../autolog/eso/periodlog.py", line 56, in <listcomp>
    logs = [NightLog.fetch(telescope, night, **opts)
  File "/home/lachaume/git/autolog/scripts/../autolog/eso/nightlog.py", line 67, in fetch
    log = query.fetch(night=night, use_tap_cache=use_tap_cache)
  File "/home/lachaume/git/autolog/scripts/../autolog/eso/tapquery.py", line 115, in fetch
    tab = tap.execute().to_table()
  File "/usr/local/lib/python3.10/dist-packages/pyvo/dal/tap.py", line 942, in execute
    return TAPResults(self.execute_votable(), url=self.queryurl, session=self._session)
  File "/usr/local/lib/python3.10/dist-packages/pyvo/dal/query.py", line 245, in execute_votable
    raise DALFormatError(e, self.queryurl)
pyvo.dal.exceptions.DALFormatError: ProtocolError: ('Connection broken: IncompleteRead(8192 bytes read)', IncompleteRead(8192 bytes read))

git add * in /home/lachaume/git/autolog
git commit
git push
To github.com:loqueelvientoajuarez/obslog.git
   33b5abd..9e58bc4  master -> master


git add * in /data/www/twoptwo.com
git commit
Everything up-to-date

Traceback (most recent call last):
  File "/usr/lib/python3.10/http/client.py", line 591, in _read_chunked
    value.append(self._safe_read(chunk_left))
  File "/usr/lib/python3.10/http/client.py", line 632, in _safe_read
    raise IncompleteRead(data, amt-len(data))
http.client.IncompleteRead: IncompleteRead(2268 bytes read, 5225 more expected)

During handling of the above exception, another exception occurred:

Traceback (most recent call last):
  File "/usr/lib/python3/dist-packages/urllib3/response.py", line 438, in _error_catcher
    yield
  File "/usr/lib/python3/dist-packages/urllib3/response.py", line 519, in read
    data = self._fp.read(amt) if not fp_closed else b""
  File "/usr/lib/python3.10/http/client.py", line 459, in read
    return self._read_chunked(amt)
  File "/usr/lib/python3.10/http/client.py", line 597, in _read_chunked
    raise IncompleteRead(b''.join(value))
http.client.IncompleteRead: IncompleteRead(8192 bytes read)

During handling of the above exception, another exception occurred:

Traceback (most recent call last):
  File "/usr/local/lib/python3.10/dist-packages/pyvo/dal/query.py", line 242, in execute_votable
    return votableparse(self.execute_stream(post=post).read)
  File "/usr/local/lib/python3.10/dist-packages/astropy/utils/decorators.py", line 546, in wrapper
    return function(*args, **kwargs)
  File "/usr/local/lib/python3.10/dist-packages/astropy/io/votable/table.py", line 160, in parse
    config=config, pos=(1, 1)).parse(iterator, config)
  File "/usr/local/lib/python3.10/dist-packages/astropy/io/votable/tree.py", line 3615, in parse
    tag_mapping.get(tag, self._add_unknown_tag)(
  File "/usr/local/lib/python3.10/dist-packages/astropy/io/votable/tree.py", line 3494, in _add_resource
    resource.parse(self, iterator, config)
  File "/usr/local/lib/python3.10/dist-packages/astropy/io/votable/tree.py", line 3292, in parse
    tag_mapping.get(tag, self._add_unknown_tag)(
  File "/usr/local/lib/python3.10/dist-packages/astropy/io/votable/tree.py", line 3238, in _add_table
    table.parse(iterator, config)
  File "/usr/local/lib/python3.10/dist-packages/astropy/io/votable/tree.py", line 2513, in parse
    self.array = self._parse_tabledata(
  File "/usr/local/lib/python3.10/dist-packages/astropy/io/votable/tree.py", line 2591, in _parse_tabledata
    for start, tag, data, pos in iterator:
  File "/usr/lib/python3/dist-packages/urllib3/response.py", line 512, in read
    with self._error_catcher():
  File "/usr/lib/python3.10/contextlib.py", line 153, in __exit__
    self.gen.throw(typ, value, traceback)
  File "/usr/lib/python3/dist-packages/urllib3/response.py", line 455, in _error_catcher
    raise ProtocolError("Connection broken: %r" % e, e)
urllib3.exceptions.ProtocolError: ('Connection broken: IncompleteRead(8192 bytes read)', IncompleteRead(8192 bytes read))

During handling of the above exception, another exception occurred:

Traceback (most recent call last):
  File "/home/lachaume/git/autolog/scripts/./periodlog.py", line 22, in <module>
    log = PeriodLog.fetch(telescope, period, **opts) 
  File "/home/lachaume/git/autolog/scripts/../autolog/eso/periodlog.py", line 56, in fetch
    logs = [NightLog.fetch(telescope, night, **opts)
  File "/home/lachaume/git/autolog/scripts/../autolog/eso/periodlog.py", line 56, in <listcomp>
    logs = [NightLog.fetch(telescope, night, **opts)
  File "/home/lachaume/git/autolog/scripts/../autolog/eso/nightlog.py", line 67, in fetch
    log = query.fetch(night=night, use_tap_cache=use_tap_cache)
  File "/home/lachaume/git/autolog/scripts/../autolog/eso/tapquery.py", line 115, in fetch
    tab = tap.execute().to_table()
  File "/usr/local/lib/python3.10/dist-packages/pyvo/dal/tap.py", line 942, in execute
    return TAPResults(self.execute_votable(), url=self.queryurl, session=self._session)
  File "/usr/local/lib/python3.10/dist-packages/pyvo/dal/query.py", line 245, in execute_votable
    raise DALFormatError(e, self.queryurl)
pyvo.dal.exceptions.DALFormatError: ProtocolError: ('Connection broken: IncompleteRead(8192 bytes read)', IncompleteRead(8192 bytes read))

git add * in /home/lachaume/git/autolog
git commit
git push
To github.com:loqueelvientoajuarez/obslog.git
   9e58bc4..f0ceb69  master -> master


git add * in /data/www/twoptwo.com
git commit
Everything up-to-date


daily.sh at 2022-07-06T16:20:01-04:00
-------------------------------------

github pull in /home/lachaume/git/autolog

daily.sh at 2022-07-06T16:21:01-04:00
-------------------------------------

github pull in /home/lachaume/git/autolog

github pull in /data/www/twoptwo.com

executing periodlog.py in /home/lachaume/git/autolog/scripts
Everything up-to-date


daily.sh at 2022-07-06T16:22:01-04:00
-------------------------------------

github pull in /home/lachaume/git/autolog
Traceback (most recent call last):
  File "/usr/lib/python3/dist-packages/urllib3/connection.py", line 169, in _new_conn
    conn = connection.create_connection(
  File "/usr/lib/python3/dist-packages/urllib3/util/connection.py", line 73, in create_connection
    for res in socket.getaddrinfo(host, port, family, socket.SOCK_STREAM):
  File "/usr/lib/python3.10/socket.py", line 955, in getaddrinfo
    for res in _socket.getaddrinfo(host, port, family, type, proto, flags):
socket.gaierror: [Errno -3] Temporary failure in name resolution

During handling of the above exception, another exception occurred:

Traceback (most recent call last):
  File "/usr/lib/python3/dist-packages/urllib3/connectionpool.py", line 699, in urlopen
    httplib_response = self._make_request(
  File "/usr/lib/python3/dist-packages/urllib3/connectionpool.py", line 394, in _make_request
    conn.request(method, url, **httplib_request_kw)
  File "/usr/lib/python3/dist-packages/urllib3/connection.py", line 234, in request
    super(HTTPConnection, self).request(method, url, body=body, headers=headers)
  File "/usr/lib/python3.10/http/client.py", line 1282, in request
    self._send_request(method, url, body, headers, encode_chunked)
  File "/usr/lib/python3.10/http/client.py", line 1328, in _send_request
    self.endheaders(body, encode_chunked=encode_chunked)
  File "/usr/lib/python3.10/http/client.py", line 1277, in endheaders
    self._send_output(message_body, encode_chunked=encode_chunked)
  File "/usr/lib/python3.10/http/client.py", line 1037, in _send_output
    self.send(msg)
  File "/usr/lib/python3.10/http/client.py", line 975, in send
    self.connect()
  File "/usr/lib/python3/dist-packages/urllib3/connection.py", line 200, in connect
    conn = self._new_conn()
  File "/usr/lib/python3/dist-packages/urllib3/connection.py", line 181, in _new_conn
    raise NewConnectionError(
urllib3.exceptions.NewConnectionError: <urllib3.connection.HTTPConnection object at 0x7fdfd95bab60>: Failed to establish a new connection: [Errno -3] Temporary failure in name resolution

During handling of the above exception, another exception occurred:

Traceback (most recent call last):
  File "/usr/lib/python3/dist-packages/requests/adapters.py", line 439, in send
    resp = conn.urlopen(
  File "/usr/lib/python3/dist-packages/urllib3/connectionpool.py", line 755, in urlopen
    retries = retries.increment(
  File "/usr/lib/python3/dist-packages/urllib3/util/retry.py", line 574, in increment
    raise MaxRetryError(_pool, url, error or ResponseError(cause))
urllib3.exceptions.MaxRetryError: HTTPConnectionPool(host='archive.eso.org', port=80): Max retries exceeded with url: /tap_obs/sync (Caused by NewConnectionError('<urllib3.connection.HTTPConnection object at 0x7fdfd95bab60>: Failed to establish a new connection: [Errno -3] Temporary failure in name resolution'))

During handling of the above exception, another exception occurred:

Traceback (most recent call last):
  File "/usr/local/lib/python3.10/dist-packages/pyvo/dal/query.py", line 242, in execute_votable
    return votableparse(self.execute_stream(post=post).read)
  File "/usr/local/lib/python3.10/dist-packages/pyvo/dal/tap.py", line 926, in execute_stream
    return super().execute_stream(post=post)
  File "/usr/local/lib/python3.10/dist-packages/pyvo/utils/decorators.py", line 9, in wrapper
    raw = func(*args, **kwargs)
  File "/usr/local/lib/python3.10/dist-packages/pyvo/dal/query.py", line 191, in execute_stream
    response = self.submit(post=post)
  File "/usr/local/lib/python3.10/dist-packages/pyvo/dal/tap.py", line 959, in submit
    response = self._session.post(
  File "/usr/lib/python3/dist-packages/requests/sessions.py", line 590, in post
    return self.request('POST', url, data=data, json=json, **kwargs)
  File "/usr/lib/python3/dist-packages/requests/sessions.py", line 542, in request
    resp = self.send(prep, **send_kwargs)
  File "/usr/lib/python3/dist-packages/requests/sessions.py", line 655, in send
    r = adapter.send(request, **kwargs)
  File "/usr/lib/python3/dist-packages/requests/adapters.py", line 516, in send
    raise ConnectionError(e, request=request)
requests.exceptions.ConnectionError: HTTPConnectionPool(host='archive.eso.org', port=80): Max retries exceeded with url: /tap_obs/sync (Caused by NewConnectionError('<urllib3.connection.HTTPConnection object at 0x7fdfd95bab60>: Failed to establish a new connection: [Errno -3] Temporary failure in name resolution'))

During handling of the above exception, another exception occurred:

Traceback (most recent call last):
  File "/home/lachaume/git/autolog/scripts/./periodlog.py", line 22, in <module>
    log = PeriodLog.fetch(telescope, period, **opts) 
  File "/home/lachaume/git/autolog/scripts/../autolog/eso/periodlog.py", line 56, in fetch
    logs = [NightLog.fetch(telescope, night, **opts)
  File "/home/lachaume/git/autolog/scripts/../autolog/eso/periodlog.py", line 56, in <listcomp>
    logs = [NightLog.fetch(telescope, night, **opts)
  File "/home/lachaume/git/autolog/scripts/../autolog/eso/nightlog.py", line 67, in fetch
    log = query.fetch(night=night, use_tap_cache=use_tap_cache)
  File "/home/lachaume/git/autolog/scripts/../autolog/eso/tapquery.py", line 115, in fetch
    tab = tap.execute().to_table()
  File "/usr/local/lib/python3.10/dist-packages/pyvo/dal/tap.py", line 942, in execute
    return TAPResults(self.execute_votable(), url=self.queryurl, session=self._session)
  File "/usr/local/lib/python3.10/dist-packages/pyvo/dal/query.py", line 245, in execute_votable
    raise DALFormatError(e, self.queryurl)
pyvo.dal.exceptions.DALFormatError: ConnectionError: HTTPConnectionPool(host='archive.eso.org', port=80): Max retries exceeded with url: /tap_obs/sync (Caused by NewConnectionError('<urllib3.connection.HTTPConnection object at 0x7fdfd95bab60>: Failed to establish a new connection: [Errno -3] Temporary failure in name resolution'))

git add * in /home/lachaume/git/autolog
git commit
git push
ssh: Could not resolve hostname github.com: Temporary failure in name resolution
fatal: Could not read from remote repository.

Please make sure you have the correct access rights
and the repository exists.

github pull in /data/www/twoptwo.com

executing periodlog.py in /home/lachaume/git/autolog/scripts
To github.com:loqueelvientoajuarez/obslog.git
   f0ceb69..2cf2af6  master -> master


git add * in /data/www/twoptwo.com
git commit
Everything up-to-date


daily.sh at 2022-07-06T16:23:01-04:00
-------------------------------------

github pull in /home/lachaume/git/autolog
ssh: Could not resolve hostname github.com: Temporary failure in name resolution
fatal: Could not read from remote repository.

Please make sure you have the correct access rights
and the repository exists.

github pull in /data/www/twoptwo.com

executing periodlog.py in /home/lachaume/git/autolog/scripts

daily.sh at 2022-07-06T16:24:01-04:00
-------------------------------------

github pull in /home/lachaume/git/autolog
Traceback (most recent call last):
  File "/usr/lib/python3/dist-packages/urllib3/connection.py", line 169, in _new_conn
    conn = connection.create_connection(
  File "/usr/lib/python3/dist-packages/urllib3/util/connection.py", line 73, in create_connection
    for res in socket.getaddrinfo(host, port, family, socket.SOCK_STREAM):
  File "/usr/lib/python3.10/socket.py", line 955, in getaddrinfo
    for res in _socket.getaddrinfo(host, port, family, type, proto, flags):
socket.gaierror: [Errno -3] Temporary failure in name resolution

During handling of the above exception, another exception occurred:

Traceback (most recent call last):
  File "/usr/lib/python3/dist-packages/urllib3/connectionpool.py", line 699, in urlopen
    httplib_response = self._make_request(
  File "/usr/lib/python3/dist-packages/urllib3/connectionpool.py", line 394, in _make_request
    conn.request(method, url, **httplib_request_kw)
  File "/usr/lib/python3/dist-packages/urllib3/connection.py", line 234, in request
    super(HTTPConnection, self).request(method, url, body=body, headers=headers)
  File "/usr/lib/python3.10/http/client.py", line 1282, in request
    self._send_request(method, url, body, headers, encode_chunked)
  File "/usr/lib/python3.10/http/client.py", line 1328, in _send_request
    self.endheaders(body, encode_chunked=encode_chunked)
  File "/usr/lib/python3.10/http/client.py", line 1277, in endheaders
    self._send_output(message_body, encode_chunked=encode_chunked)
  File "/usr/lib/python3.10/http/client.py", line 1037, in _send_output
    self.send(msg)
  File "/usr/lib/python3.10/http/client.py", line 975, in send
    self.connect()
  File "/usr/lib/python3/dist-packages/urllib3/connection.py", line 200, in connect
    conn = self._new_conn()
  File "/usr/lib/python3/dist-packages/urllib3/connection.py", line 181, in _new_conn
    raise NewConnectionError(
urllib3.exceptions.NewConnectionError: <urllib3.connection.HTTPConnection object at 0x7f45ac2f2710>: Failed to establish a new connection: [Errno -3] Temporary failure in name resolution

During handling of the above exception, another exception occurred:

Traceback (most recent call last):
  File "/usr/lib/python3/dist-packages/requests/adapters.py", line 439, in send
    resp = conn.urlopen(
  File "/usr/lib/python3/dist-packages/urllib3/connectionpool.py", line 755, in urlopen
    retries = retries.increment(
  File "/usr/lib/python3/dist-packages/urllib3/util/retry.py", line 574, in increment
    raise MaxRetryError(_pool, url, error or ResponseError(cause))
urllib3.exceptions.MaxRetryError: HTTPConnectionPool(host='archive.eso.org', port=80): Max retries exceeded with url: /tap_obs/sync (Caused by NewConnectionError('<urllib3.connection.HTTPConnection object at 0x7f45ac2f2710>: Failed to establish a new connection: [Errno -3] Temporary failure in name resolution'))

During handling of the above exception, another exception occurred:

Traceback (most recent call last):
  File "/usr/local/lib/python3.10/dist-packages/pyvo/dal/query.py", line 242, in execute_votable
    return votableparse(self.execute_stream(post=post).read)
  File "/usr/local/lib/python3.10/dist-packages/pyvo/dal/tap.py", line 926, in execute_stream
    return super().execute_stream(post=post)
  File "/usr/local/lib/python3.10/dist-packages/pyvo/utils/decorators.py", line 9, in wrapper
    raw = func(*args, **kwargs)
  File "/usr/local/lib/python3.10/dist-packages/pyvo/dal/query.py", line 191, in execute_stream
    response = self.submit(post=post)
  File "/usr/local/lib/python3.10/dist-packages/pyvo/dal/tap.py", line 959, in submit
    response = self._session.post(
  File "/usr/lib/python3/dist-packages/requests/sessions.py", line 590, in post
    return self.request('POST', url, data=data, json=json, **kwargs)
  File "/usr/lib/python3/dist-packages/requests/sessions.py", line 542, in request
    resp = self.send(prep, **send_kwargs)
  File "/usr/lib/python3/dist-packages/requests/sessions.py", line 655, in send
    r = adapter.send(request, **kwargs)
  File "/usr/lib/python3/dist-packages/requests/adapters.py", line 516, in send
    raise ConnectionError(e, request=request)
requests.exceptions.ConnectionError: HTTPConnectionPool(host='archive.eso.org', port=80): Max retries exceeded with url: /tap_obs/sync (Caused by NewConnectionError('<urllib3.connection.HTTPConnection object at 0x7f45ac2f2710>: Failed to establish a new connection: [Errno -3] Temporary failure in name resolution'))

During handling of the above exception, another exception occurred:

Traceback (most recent call last):
  File "/home/lachaume/git/autolog/scripts/./periodlog.py", line 22, in <module>
    log = PeriodLog.fetch(telescope, period, **opts) 
  File "/home/lachaume/git/autolog/scripts/../autolog/eso/periodlog.py", line 56, in fetch
    logs = [NightLog.fetch(telescope, night, **opts)
  File "/home/lachaume/git/autolog/scripts/../autolog/eso/periodlog.py", line 56, in <listcomp>
    logs = [NightLog.fetch(telescope, night, **opts)
  File "/home/lachaume/git/autolog/scripts/../autolog/eso/nightlog.py", line 67, in fetch
    log = query.fetch(night=night, use_tap_cache=use_tap_cache)
  File "/home/lachaume/git/autolog/scripts/../autolog/eso/tapquery.py", line 115, in fetch
    tab = tap.execute().to_table()
  File "/usr/local/lib/python3.10/dist-packages/pyvo/dal/tap.py", line 942, in execute
    return TAPResults(self.execute_votable(), url=self.queryurl, session=self._session)
  File "/usr/local/lib/python3.10/dist-packages/pyvo/dal/query.py", line 245, in execute_votable
    raise DALFormatError(e, self.queryurl)
pyvo.dal.exceptions.DALFormatError: ConnectionError: HTTPConnectionPool(host='archive.eso.org', port=80): Max retries exceeded with url: /tap_obs/sync (Caused by NewConnectionError('<urllib3.connection.HTTPConnection object at 0x7f45ac2f2710>: Failed to establish a new connection: [Errno -3] Temporary failure in name resolution'))

git add * in /home/lachaume/git/autolog
git commit
git push
warning: fetch updated the current branch head.
fast-forwarding your working tree from
commit 2cf2af696856c38c93c87cbe5fc7928617ae1361.
error: Your local changes to the following files would be overwritten by merge:
	scripts/logs/2022-07-06.err
	scripts/logs/2022-07-06.log
Please commit your changes or stash them before you merge.
Aborting
fatal: Cannot fast-forward your working tree.
After making sure that you saved anything precious from
$ git diff 2cf2af696856c38c93c87cbe5fc7928617ae1361
output, run
$ git reset --hard
to recover.

github pull in /data/www/twoptwo.com
To github.com:loqueelvientoajuarez/obslog.git
   2cf2af6..3ef2b62  master -> master


executing periodlog.py in /home/lachaume/git/autolog/scripts

git add * in /data/www/twoptwo.com
git commit
Traceback (most recent call last):
  File "/usr/lib/python3/dist-packages/urllib3/connection.py", line 169, in _new_conn
    conn = connection.create_connection(
  File "/usr/lib/python3/dist-packages/urllib3/util/connection.py", line 73, in create_connection
    for res in socket.getaddrinfo(host, port, family, socket.SOCK_STREAM):
  File "/usr/lib/python3.10/socket.py", line 955, in getaddrinfo
    for res in _socket.getaddrinfo(host, port, family, type, proto, flags):
socket.gaierror: [Errno -3] Temporary failure in name resolution

During handling of the above exception, another exception occurred:

Traceback (most recent call last):
  File "/usr/lib/python3/dist-packages/urllib3/connectionpool.py", line 699, in urlopen
    httplib_response = self._make_request(
  File "/usr/lib/python3/dist-packages/urllib3/connectionpool.py", line 394, in _make_request
    conn.request(method, url, **httplib_request_kw)
  File "/usr/lib/python3/dist-packages/urllib3/connection.py", line 234, in request
    super(HTTPConnection, self).request(method, url, body=body, headers=headers)
  File "/usr/lib/python3.10/http/client.py", line 1282, in request
    self._send_request(method, url, body, headers, encode_chunked)
  File "/usr/lib/python3.10/http/client.py", line 1328, in _send_request
    self.endheaders(body, encode_chunked=encode_chunked)
  File "/usr/lib/python3.10/http/client.py", line 1277, in endheaders
    self._send_output(message_body, encode_chunked=encode_chunked)
  File "/usr/lib/python3.10/http/client.py", line 1037, in _send_output
    self.send(msg)
  File "/usr/lib/python3.10/http/client.py", line 975, in send
    self.connect()
  File "/usr/lib/python3/dist-packages/urllib3/connection.py", line 200, in connect
    conn = self._new_conn()
  File "/usr/lib/python3/dist-packages/urllib3/connection.py", line 181, in _new_conn
    raise NewConnectionError(
urllib3.exceptions.NewConnectionError: <urllib3.connection.HTTPConnection object at 0x7f986625c700>: Failed to establish a new connection: [Errno -3] Temporary failure in name resolution

During handling of the above exception, another exception occurred:

Traceback (most recent call last):
  File "/usr/lib/python3/dist-packages/requests/adapters.py", line 439, in send
    resp = conn.urlopen(
  File "/usr/lib/python3/dist-packages/urllib3/connectionpool.py", line 755, in urlopen
    retries = retries.increment(
  File "/usr/lib/python3/dist-packages/urllib3/util/retry.py", line 574, in increment
    raise MaxRetryError(_pool, url, error or ResponseError(cause))
urllib3.exceptions.MaxRetryError: HTTPConnectionPool(host='archive.eso.org', port=80): Max retries exceeded with url: /tap_obs/sync (Caused by NewConnectionError('<urllib3.connection.HTTPConnection object at 0x7f986625c700>: Failed to establish a new connection: [Errno -3] Temporary failure in name resolution'))

During handling of the above exception, another exception occurred:

Traceback (most recent call last):
  File "/usr/local/lib/python3.10/dist-packages/pyvo/dal/query.py", line 242, in execute_votable
    return votableparse(self.execute_stream(post=post).read)
  File "/usr/local/lib/python3.10/dist-packages/pyvo/dal/tap.py", line 926, in execute_stream
    return super().execute_stream(post=post)
  File "/usr/local/lib/python3.10/dist-packages/pyvo/utils/decorators.py", line 9, in wrapper
    raw = func(*args, **kwargs)
  File "/usr/local/lib/python3.10/dist-packages/pyvo/dal/query.py", line 191, in execute_stream
    response = self.submit(post=post)
  File "/usr/local/lib/python3.10/dist-packages/pyvo/dal/tap.py", line 959, in submit
    response = self._session.post(
  File "/usr/lib/python3/dist-packages/requests/sessions.py", line 590, in post
    return self.request('POST', url, data=data, json=json, **kwargs)
  File "/usr/lib/python3/dist-packages/requests/sessions.py", line 542, in request
    resp = self.send(prep, **send_kwargs)
  File "/usr/lib/python3/dist-packages/requests/sessions.py", line 655, in send
    r = adapter.send(request, **kwargs)
  File "/usr/lib/python3/dist-packages/requests/adapters.py", line 516, in send
    raise ConnectionError(e, request=request)
requests.exceptions.ConnectionError: HTTPConnectionPool(host='archive.eso.org', port=80): Max retries exceeded with url: /tap_obs/sync (Caused by NewConnectionError('<urllib3.connection.HTTPConnection object at 0x7f986625c700>: Failed to establish a new connection: [Errno -3] Temporary failure in name resolution'))

During handling of the above exception, another exception occurred:

Traceback (most recent call last):
  File "/home/lachaume/git/autolog/scripts/./periodlog.py", line 22, in <module>
    log = PeriodLog.fetch(telescope, period, **opts) 
  File "/home/lachaume/git/autolog/scripts/../autolog/eso/periodlog.py", line 56, in fetch
    logs = [NightLog.fetch(telescope, night, **opts)
  File "/home/lachaume/git/autolog/scripts/../autolog/eso/periodlog.py", line 56, in <listcomp>
    logs = [NightLog.fetch(telescope, night, **opts)
  File "/home/lachaume/git/autolog/scripts/../autolog/eso/nightlog.py", line 67, in fetch
    log = query.fetch(night=night, use_tap_cache=use_tap_cache)
  File "/home/lachaume/git/autolog/scripts/../autolog/eso/tapquery.py", line 115, in fetch
    tab = tap.execute().to_table()
  File "/usr/local/lib/python3.10/dist-packages/pyvo/dal/tap.py", line 942, in execute
    return TAPResults(self.execute_votable(), url=self.queryurl, session=self._session)
  File "/usr/local/lib/python3.10/dist-packages/pyvo/dal/query.py", line 245, in execute_votable
    raise DALFormatError(e, self.queryurl)
pyvo.dal.exceptions.DALFormatError: ConnectionError: HTTPConnectionPool(host='archive.eso.org', port=80): Max retries exceeded with url: /tap_obs/sync (Caused by NewConnectionError('<urllib3.connection.HTTPConnection object at 0x7f986625c700>: Failed to establish a new connection: [Errno -3] Temporary failure in name resolution'))

git add * in /home/lachaume/git/autolog
git commit
git push
Everything up-to-date

To github.com:loqueelvientoajuarez/obslog.git
   3ef2b62..43d22e7  master -> master


git add * in /data/www/twoptwo.com
git commit
Everything up-to-date

Everything up-to-date

Traceback (most recent call last):
  File "/usr/lib/python3/dist-packages/urllib3/connection.py", line 169, in _new_conn
    conn = connection.create_connection(
  File "/usr/lib/python3/dist-packages/urllib3/util/connection.py", line 73, in create_connection
    for res in socket.getaddrinfo(host, port, family, socket.SOCK_STREAM):
  File "/usr/lib/python3.10/socket.py", line 955, in getaddrinfo
    for res in _socket.getaddrinfo(host, port, family, type, proto, flags):
socket.gaierror: [Errno -3] Temporary failure in name resolution

During handling of the above exception, another exception occurred:

Traceback (most recent call last):
  File "/usr/lib/python3/dist-packages/urllib3/connectionpool.py", line 699, in urlopen
    httplib_response = self._make_request(
  File "/usr/lib/python3/dist-packages/urllib3/connectionpool.py", line 394, in _make_request
    conn.request(method, url, **httplib_request_kw)
  File "/usr/lib/python3/dist-packages/urllib3/connection.py", line 234, in request
    super(HTTPConnection, self).request(method, url, body=body, headers=headers)
  File "/usr/lib/python3.10/http/client.py", line 1282, in request
    self._send_request(method, url, body, headers, encode_chunked)
  File "/usr/lib/python3.10/http/client.py", line 1328, in _send_request
    self.endheaders(body, encode_chunked=encode_chunked)
  File "/usr/lib/python3.10/http/client.py", line 1277, in endheaders
    self._send_output(message_body, encode_chunked=encode_chunked)
  File "/usr/lib/python3.10/http/client.py", line 1037, in _send_output
    self.send(msg)
  File "/usr/lib/python3.10/http/client.py", line 975, in send
    self.connect()
  File "/usr/lib/python3/dist-packages/urllib3/connection.py", line 200, in connect
    conn = self._new_conn()
  File "/usr/lib/python3/dist-packages/urllib3/connection.py", line 181, in _new_conn
    raise NewConnectionError(
urllib3.exceptions.NewConnectionError: <urllib3.connection.HTTPConnection object at 0x7fdc9399f7f0>: Failed to establish a new connection: [Errno -3] Temporary failure in name resolution

During handling of the above exception, another exception occurred:

Traceback (most recent call last):
  File "/usr/lib/python3/dist-packages/requests/adapters.py", line 439, in send
    resp = conn.urlopen(
  File "/usr/lib/python3/dist-packages/urllib3/connectionpool.py", line 755, in urlopen
    retries = retries.increment(
  File "/usr/lib/python3/dist-packages/urllib3/util/retry.py", line 574, in increment
    raise MaxRetryError(_pool, url, error or ResponseError(cause))
urllib3.exceptions.MaxRetryError: HTTPConnectionPool(host='archive.eso.org', port=80): Max retries exceeded with url: /tap_obs/sync (Caused by NewConnectionError('<urllib3.connection.HTTPConnection object at 0x7fdc9399f7f0>: Failed to establish a new connection: [Errno -3] Temporary failure in name resolution'))

During handling of the above exception, another exception occurred:

Traceback (most recent call last):
  File "/usr/local/lib/python3.10/dist-packages/pyvo/dal/query.py", line 242, in execute_votable
    return votableparse(self.execute_stream(post=post).read)
  File "/usr/local/lib/python3.10/dist-packages/pyvo/dal/tap.py", line 926, in execute_stream
    return super().execute_stream(post=post)
  File "/usr/local/lib/python3.10/dist-packages/pyvo/utils/decorators.py", line 9, in wrapper
    raw = func(*args, **kwargs)
  File "/usr/local/lib/python3.10/dist-packages/pyvo/dal/query.py", line 191, in execute_stream
    response = self.submit(post=post)
  File "/usr/local/lib/python3.10/dist-packages/pyvo/dal/tap.py", line 959, in submit
    response = self._session.post(
  File "/usr/lib/python3/dist-packages/requests/sessions.py", line 590, in post
    return self.request('POST', url, data=data, json=json, **kwargs)
  File "/usr/lib/python3/dist-packages/requests/sessions.py", line 542, in request
    resp = self.send(prep, **send_kwargs)
  File "/usr/lib/python3/dist-packages/requests/sessions.py", line 655, in send
    r = adapter.send(request, **kwargs)
  File "/usr/lib/python3/dist-packages/requests/adapters.py", line 516, in send
    raise ConnectionError(e, request=request)
requests.exceptions.ConnectionError: HTTPConnectionPool(host='archive.eso.org', port=80): Max retries exceeded with url: /tap_obs/sync (Caused by NewConnectionError('<urllib3.connection.HTTPConnection object at 0x7fdc9399f7f0>: Failed to establish a new connection: [Errno -3] Temporary failure in name resolution'))

During handling of the above exception, another exception occurred:

Traceback (most recent call last):
  File "/home/lachaume/git/autolog/scripts/./periodlog.py", line 22, in <module>
    log = PeriodLog.fetch(telescope, period, **opts) 
  File "/home/lachaume/git/autolog/scripts/../autolog/eso/periodlog.py", line 56, in fetch
    logs = [NightLog.fetch(telescope, night, **opts)
  File "/home/lachaume/git/autolog/scripts/../autolog/eso/periodlog.py", line 56, in <listcomp>
    logs = [NightLog.fetch(telescope, night, **opts)
  File "/home/lachaume/git/autolog/scripts/../autolog/eso/nightlog.py", line 67, in fetch
    log = query.fetch(night=night, use_tap_cache=use_tap_cache)
  File "/home/lachaume/git/autolog/scripts/../autolog/eso/tapquery.py", line 115, in fetch
    tab = tap.execute().to_table()
  File "/usr/local/lib/python3.10/dist-packages/pyvo/dal/tap.py", line 942, in execute
    return TAPResults(self.execute_votable(), url=self.queryurl, session=self._session)
  File "/usr/local/lib/python3.10/dist-packages/pyvo/dal/query.py", line 245, in execute_votable
    raise DALFormatError(e, self.queryurl)
pyvo.dal.exceptions.DALFormatError: ConnectionError: HTTPConnectionPool(host='archive.eso.org', port=80): Max retries exceeded with url: /tap_obs/sync (Caused by NewConnectionError('<urllib3.connection.HTTPConnection object at 0x7fdc9399f7f0>: Failed to establish a new connection: [Errno -3] Temporary failure in name resolution'))

git add * in /home/lachaume/git/autolog
git commit
git push

daily.sh at 2022-07-06T16:25:01-04:00
-------------------------------------

github pull in /home/lachaume/git/autolog

github pull in /data/www/twoptwo.com
To github.com:loqueelvientoajuarez/obslog.git
   43d22e7..388078e  master -> master


executing periodlog.py in /home/lachaume/git/autolog/scripts

git add * in /data/www/twoptwo.com
git commit
Everything up-to-date


daily.sh at 2022-07-06T16:26:01-04:00
-------------------------------------

github pull in /home/lachaume/git/autolog

github pull in /data/www/twoptwo.com

executing periodlog.py in /home/lachaume/git/autolog/scripts
Traceback (most recent call last):
  File "/usr/lib/python3/dist-packages/urllib3/connection.py", line 169, in _new_conn
    conn = connection.create_connection(
  File "/usr/lib/python3/dist-packages/urllib3/util/connection.py", line 73, in create_connection
    for res in socket.getaddrinfo(host, port, family, socket.SOCK_STREAM):
  File "/usr/lib/python3.10/socket.py", line 955, in getaddrinfo
    for res in _socket.getaddrinfo(host, port, family, type, proto, flags):
socket.gaierror: [Errno -3] Temporary failure in name resolution

During handling of the above exception, another exception occurred:

Traceback (most recent call last):
  File "/usr/lib/python3/dist-packages/urllib3/connectionpool.py", line 699, in urlopen
    httplib_response = self._make_request(
  File "/usr/lib/python3/dist-packages/urllib3/connectionpool.py", line 394, in _make_request
    conn.request(method, url, **httplib_request_kw)
  File "/usr/lib/python3/dist-packages/urllib3/connection.py", line 234, in request
    super(HTTPConnection, self).request(method, url, body=body, headers=headers)
  File "/usr/lib/python3.10/http/client.py", line 1282, in request
    self._send_request(method, url, body, headers, encode_chunked)
  File "/usr/lib/python3.10/http/client.py", line 1328, in _send_request
    self.endheaders(body, encode_chunked=encode_chunked)
  File "/usr/lib/python3.10/http/client.py", line 1277, in endheaders
    self._send_output(message_body, encode_chunked=encode_chunked)
  File "/usr/lib/python3.10/http/client.py", line 1037, in _send_output
    self.send(msg)
  File "/usr/lib/python3.10/http/client.py", line 975, in send
    self.connect()
  File "/usr/lib/python3/dist-packages/urllib3/connection.py", line 200, in connect
    conn = self._new_conn()
  File "/usr/lib/python3/dist-packages/urllib3/connection.py", line 181, in _new_conn
    raise NewConnectionError(
urllib3.exceptions.NewConnectionError: <urllib3.connection.HTTPConnection object at 0x7ffb6033ab00>: Failed to establish a new connection: [Errno -3] Temporary failure in name resolution

During handling of the above exception, another exception occurred:

Traceback (most recent call last):
  File "/usr/lib/python3/dist-packages/requests/adapters.py", line 439, in send
    resp = conn.urlopen(
  File "/usr/lib/python3/dist-packages/urllib3/connectionpool.py", line 755, in urlopen
    retries = retries.increment(
  File "/usr/lib/python3/dist-packages/urllib3/util/retry.py", line 574, in increment
    raise MaxRetryError(_pool, url, error or ResponseError(cause))
urllib3.exceptions.MaxRetryError: HTTPConnectionPool(host='archive.eso.org', port=80): Max retries exceeded with url: /tap_obs/sync (Caused by NewConnectionError('<urllib3.connection.HTTPConnection object at 0x7ffb6033ab00>: Failed to establish a new connection: [Errno -3] Temporary failure in name resolution'))

During handling of the above exception, another exception occurred:

Traceback (most recent call last):
  File "/usr/local/lib/python3.10/dist-packages/pyvo/dal/query.py", line 242, in execute_votable
    return votableparse(self.execute_stream(post=post).read)
  File "/usr/local/lib/python3.10/dist-packages/pyvo/dal/tap.py", line 926, in execute_stream
    return super().execute_stream(post=post)
  File "/usr/local/lib/python3.10/dist-packages/pyvo/utils/decorators.py", line 9, in wrapper
    raw = func(*args, **kwargs)
  File "/usr/local/lib/python3.10/dist-packages/pyvo/dal/query.py", line 191, in execute_stream
    response = self.submit(post=post)
  File "/usr/local/lib/python3.10/dist-packages/pyvo/dal/tap.py", line 959, in submit
    response = self._session.post(
  File "/usr/lib/python3/dist-packages/requests/sessions.py", line 590, in post
    return self.request('POST', url, data=data, json=json, **kwargs)
  File "/usr/lib/python3/dist-packages/requests/sessions.py", line 542, in request
    resp = self.send(prep, **send_kwargs)
  File "/usr/lib/python3/dist-packages/requests/sessions.py", line 655, in send
    r = adapter.send(request, **kwargs)
  File "/usr/lib/python3/dist-packages/requests/adapters.py", line 516, in send
    raise ConnectionError(e, request=request)
requests.exceptions.ConnectionError: HTTPConnectionPool(host='archive.eso.org', port=80): Max retries exceeded with url: /tap_obs/sync (Caused by NewConnectionError('<urllib3.connection.HTTPConnection object at 0x7ffb6033ab00>: Failed to establish a new connection: [Errno -3] Temporary failure in name resolution'))

During handling of the above exception, another exception occurred:

Traceback (most recent call last):
  File "/home/lachaume/git/autolog/scripts/./periodlog.py", line 22, in <module>
    log = PeriodLog.fetch(telescope, period, **opts) 
  File "/home/lachaume/git/autolog/scripts/../autolog/eso/periodlog.py", line 56, in fetch
    logs = [NightLog.fetch(telescope, night, **opts)
  File "/home/lachaume/git/autolog/scripts/../autolog/eso/periodlog.py", line 56, in <listcomp>
    logs = [NightLog.fetch(telescope, night, **opts)
  File "/home/lachaume/git/autolog/scripts/../autolog/eso/nightlog.py", line 67, in fetch
    log = query.fetch(night=night, use_tap_cache=use_tap_cache)
  File "/home/lachaume/git/autolog/scripts/../autolog/eso/tapquery.py", line 115, in fetch
    tab = tap.execute().to_table()
  File "/usr/local/lib/python3.10/dist-packages/pyvo/dal/tap.py", line 942, in execute
    return TAPResults(self.execute_votable(), url=self.queryurl, session=self._session)
  File "/usr/local/lib/python3.10/dist-packages/pyvo/dal/query.py", line 245, in execute_votable
    raise DALFormatError(e, self.queryurl)
pyvo.dal.exceptions.DALFormatError: ConnectionError: HTTPConnectionPool(host='archive.eso.org', port=80): Max retries exceeded with url: /tap_obs/sync (Caused by NewConnectionError('<urllib3.connection.HTTPConnection object at 0x7ffb6033ab00>: Failed to establish a new connection: [Errno -3] Temporary failure in name resolution'))

git add * in /home/lachaume/git/autolog
git commit
git push
ssh: Could not resolve hostname github.com: Temporary failure in name resolution
fatal: Could not read from remote repository.

Please make sure you have the correct access rights
and the repository exists.


daily.sh at 2022-07-06T16:27:01-04:00
-------------------------------------

github pull in /home/lachaume/git/autolog

git add * in /data/www/twoptwo.com
git commit
ssh: Could not resolve hostname github.com: Temporary failure in name resolution
fatal: Could not read from remote repository.

Please make sure you have the correct access rights
and the repository exists.

github pull in /data/www/twoptwo.com
ssh: Could not resolve hostname github.com: Temporary failure in name resolution
fatal: Could not read from remote repository.

Please make sure you have the correct access rights
and the repository exists.


executing periodlog.py in /home/lachaume/git/autolog/scripts
Traceback (most recent call last):
  File "/usr/lib/python3/dist-packages/urllib3/connection.py", line 169, in _new_conn
    conn = connection.create_connection(
  File "/usr/lib/python3/dist-packages/urllib3/util/connection.py", line 96, in create_connection
    raise err
  File "/usr/lib/python3/dist-packages/urllib3/util/connection.py", line 86, in create_connection
    sock.connect(sa)
TimeoutError: [Errno 110] Connection timed out

During handling of the above exception, another exception occurred:

Traceback (most recent call last):
  File "/usr/lib/python3/dist-packages/urllib3/connectionpool.py", line 699, in urlopen
    httplib_response = self._make_request(
  File "/usr/lib/python3/dist-packages/urllib3/connectionpool.py", line 394, in _make_request
    conn.request(method, url, **httplib_request_kw)
  File "/usr/lib/python3/dist-packages/urllib3/connection.py", line 234, in request
    super(HTTPConnection, self).request(method, url, body=body, headers=headers)
  File "/usr/lib/python3.10/http/client.py", line 1282, in request
    self._send_request(method, url, body, headers, encode_chunked)
  File "/usr/lib/python3.10/http/client.py", line 1328, in _send_request
    self.endheaders(body, encode_chunked=encode_chunked)
  File "/usr/lib/python3.10/http/client.py", line 1277, in endheaders
    self._send_output(message_body, encode_chunked=encode_chunked)
  File "/usr/lib/python3.10/http/client.py", line 1037, in _send_output
    self.send(msg)
  File "/usr/lib/python3.10/http/client.py", line 975, in send
    self.connect()
  File "/usr/lib/python3/dist-packages/urllib3/connection.py", line 200, in connect
    conn = self._new_conn()
  File "/usr/lib/python3/dist-packages/urllib3/connection.py", line 174, in _new_conn
    raise ConnectTimeoutError(
urllib3.exceptions.ConnectTimeoutError: (<urllib3.connection.HTTPConnection object at 0x7f66b5e1fac0>, 'Connection to archive.eso.org timed out. (connect timeout=None)')

During handling of the above exception, another exception occurred:

Traceback (most recent call last):
  File "/usr/lib/python3/dist-packages/requests/adapters.py", line 439, in send
    resp = conn.urlopen(
  File "/usr/lib/python3/dist-packages/urllib3/connectionpool.py", line 755, in urlopen
    retries = retries.increment(
  File "/usr/lib/python3/dist-packages/urllib3/util/retry.py", line 574, in increment
    raise MaxRetryError(_pool, url, error or ResponseError(cause))
urllib3.exceptions.MaxRetryError: HTTPConnectionPool(host='archive.eso.org', port=80): Max retries exceeded with url: /tap_obs/sync (Caused by ConnectTimeoutError(<urllib3.connection.HTTPConnection object at 0x7f66b5e1fac0>, 'Connection to archive.eso.org timed out. (connect timeout=None)'))

During handling of the above exception, another exception occurred:

Traceback (most recent call last):
  File "/usr/local/lib/python3.10/dist-packages/pyvo/dal/query.py", line 242, in execute_votable
    return votableparse(self.execute_stream(post=post).read)
  File "/usr/local/lib/python3.10/dist-packages/pyvo/dal/tap.py", line 926, in execute_stream
    return super().execute_stream(post=post)
  File "/usr/local/lib/python3.10/dist-packages/pyvo/utils/decorators.py", line 9, in wrapper
    raw = func(*args, **kwargs)
  File "/usr/local/lib/python3.10/dist-packages/pyvo/dal/query.py", line 191, in execute_stream
    response = self.submit(post=post)
  File "/usr/local/lib/python3.10/dist-packages/pyvo/dal/tap.py", line 959, in submit
    response = self._session.post(
  File "/usr/lib/python3/dist-packages/requests/sessions.py", line 590, in post
    return self.request('POST', url, data=data, json=json, **kwargs)
  File "/usr/lib/python3/dist-packages/requests/sessions.py", line 542, in request
    resp = self.send(prep, **send_kwargs)
  File "/usr/lib/python3/dist-packages/requests/sessions.py", line 655, in send
    r = adapter.send(request, **kwargs)
  File "/usr/lib/python3/dist-packages/requests/adapters.py", line 504, in send
    raise ConnectTimeout(e, request=request)
requests.exceptions.ConnectTimeout: HTTPConnectionPool(host='archive.eso.org', port=80): Max retries exceeded with url: /tap_obs/sync (Caused by ConnectTimeoutError(<urllib3.connection.HTTPConnection object at 0x7f66b5e1fac0>, 'Connection to archive.eso.org timed out. (connect timeout=None)'))

During handling of the above exception, another exception occurred:

Traceback (most recent call last):
  File "/home/lachaume/git/autolog/scripts/./periodlog.py", line 22, in <module>
    log = PeriodLog.fetch(telescope, period, **opts) 
  File "/home/lachaume/git/autolog/scripts/../autolog/eso/periodlog.py", line 56, in fetch
    logs = [NightLog.fetch(telescope, night, **opts)
  File "/home/lachaume/git/autolog/scripts/../autolog/eso/periodlog.py", line 56, in <listcomp>
    logs = [NightLog.fetch(telescope, night, **opts)
  File "/home/lachaume/git/autolog/scripts/../autolog/eso/nightlog.py", line 67, in fetch
    log = query.fetch(night=night, use_tap_cache=use_tap_cache)
  File "/home/lachaume/git/autolog/scripts/../autolog/eso/tapquery.py", line 115, in fetch
    tab = tap.execute().to_table()
  File "/usr/local/lib/python3.10/dist-packages/pyvo/dal/tap.py", line 942, in execute
    return TAPResults(self.execute_votable(), url=self.queryurl, session=self._session)
  File "/usr/local/lib/python3.10/dist-packages/pyvo/dal/query.py", line 245, in execute_votable
    raise DALFormatError(e, self.queryurl)
pyvo.dal.exceptions.DALFormatError: ConnectTimeout: HTTPConnectionPool(host='archive.eso.org', port=80): Max retries exceeded with url: /tap_obs/sync (Caused by ConnectTimeoutError(<urllib3.connection.HTTPConnection object at 0x7f66b5e1fac0>, 'Connection to archive.eso.org timed out. (connect timeout=None)'))

git add * in /home/lachaume/git/autolog
