
daily.sh at 2022-07-07T16:00:01-04:00
-------------------------------------

github pull in /home/lachaume/git/autolog
ssh: Could not resolve hostname github.com: Temporary failure in name resolution
fatal: Could not read from remote repository.

Please make sure you have the correct access rights
and the repository exists.

github pull in /data/www/twoptwo.com
ssh: Could not resolve hostname github.com: Temporary failure in name resolution
fatal: Could not read from remote repository.

Please make sure you have the correct access rights
and the repository exists.

executing periodlog.py in /home/lachaume/git/autolog/scripts

daily.sh at 2022-07-07T16:01:01-04:00
-------------------------------------

github pull in /home/lachaume/git/autolog
Traceback (most recent call last):
  File "/usr/lib/python3/dist-packages/urllib3/connection.py", line 169, in _new_conn
    conn = connection.create_connection(
  File "/usr/lib/python3/dist-packages/urllib3/util/connection.py", line 73, in create_connection
    for res in socket.getaddrinfo(host, port, family, socket.SOCK_STREAM):
  File "/usr/lib/python3.10/socket.py", line 955, in getaddrinfo
    for res in _socket.getaddrinfo(host, port, family, type, proto, flags):
socket.gaierror: [Errno -3] Temporary failure in name resolution

During handling of the above exception, another exception occurred:

Traceback (most recent call last):
  File "/usr/lib/python3/dist-packages/urllib3/connectionpool.py", line 699, in urlopen
    httplib_response = self._make_request(
  File "/usr/lib/python3/dist-packages/urllib3/connectionpool.py", line 394, in _make_request
    conn.request(method, url, **httplib_request_kw)
  File "/usr/lib/python3/dist-packages/urllib3/connection.py", line 234, in request
    super(HTTPConnection, self).request(method, url, body=body, headers=headers)
  File "/usr/lib/python3.10/http/client.py", line 1282, in request
    self._send_request(method, url, body, headers, encode_chunked)
  File "/usr/lib/python3.10/http/client.py", line 1328, in _send_request
    self.endheaders(body, encode_chunked=encode_chunked)
  File "/usr/lib/python3.10/http/client.py", line 1277, in endheaders
    self._send_output(message_body, encode_chunked=encode_chunked)
  File "/usr/lib/python3.10/http/client.py", line 1037, in _send_output
    self.send(msg)
  File "/usr/lib/python3.10/http/client.py", line 975, in send
    self.connect()
  File "/usr/lib/python3/dist-packages/urllib3/connection.py", line 200, in connect
    conn = self._new_conn()
  File "/usr/lib/python3/dist-packages/urllib3/connection.py", line 181, in _new_conn
    raise NewConnectionError(
urllib3.exceptions.NewConnectionError: <urllib3.connection.HTTPConnection object at 0x7f5f53a942e0>: Failed to establish a new connection: [Errno -3] Temporary failure in name resolution

During handling of the above exception, another exception occurred:

Traceback (most recent call last):
  File "/usr/lib/python3/dist-packages/requests/adapters.py", line 439, in send
    resp = conn.urlopen(
  File "/usr/lib/python3/dist-packages/urllib3/connectionpool.py", line 755, in urlopen
    retries = retries.increment(
  File "/usr/lib/python3/dist-packages/urllib3/util/retry.py", line 574, in increment
    raise MaxRetryError(_pool, url, error or ResponseError(cause))
urllib3.exceptions.MaxRetryError: HTTPConnectionPool(host='archive.eso.org', port=80): Max retries exceeded with url: /tap_obs/sync (Caused by NewConnectionError('<urllib3.connection.HTTPConnection object at 0x7f5f53a942e0>: Failed to establish a new connection: [Errno -3] Temporary failure in name resolution'))

During handling of the above exception, another exception occurred:

Traceback (most recent call last):
  File "/usr/local/lib/python3.10/dist-packages/pyvo/dal/query.py", line 242, in execute_votable
    return votableparse(self.execute_stream(post=post).read)
  File "/usr/local/lib/python3.10/dist-packages/pyvo/dal/tap.py", line 926, in execute_stream
    return super().execute_stream(post=post)
  File "/usr/local/lib/python3.10/dist-packages/pyvo/utils/decorators.py", line 9, in wrapper
    raw = func(*args, **kwargs)
  File "/usr/local/lib/python3.10/dist-packages/pyvo/dal/query.py", line 191, in execute_stream
    response = self.submit(post=post)
  File "/usr/local/lib/python3.10/dist-packages/pyvo/dal/tap.py", line 959, in submit
    response = self._session.post(
  File "/usr/lib/python3/dist-packages/requests/sessions.py", line 590, in post
    return self.request('POST', url, data=data, json=json, **kwargs)
  File "/usr/lib/python3/dist-packages/requests/sessions.py", line 542, in request
    resp = self.send(prep, **send_kwargs)
  File "/usr/lib/python3/dist-packages/requests/sessions.py", line 655, in send
    r = adapter.send(request, **kwargs)
  File "/usr/lib/python3/dist-packages/requests/adapters.py", line 516, in send
    raise ConnectionError(e, request=request)
requests.exceptions.ConnectionError: HTTPConnectionPool(host='archive.eso.org', port=80): Max retries exceeded with url: /tap_obs/sync (Caused by NewConnectionError('<urllib3.connection.HTTPConnection object at 0x7f5f53a942e0>: Failed to establish a new connection: [Errno -3] Temporary failure in name resolution'))

During handling of the above exception, another exception occurred:

Traceback (most recent call last):
  File "/home/lachaume/git/autolog/scripts/./periodlog.py", line 22, in <module>
    log = PeriodLog.fetch(telescope, period, **opts) 
  File "/home/lachaume/git/autolog/scripts/../autolog/eso/periodlog.py", line 56, in fetch
    logs = [NightLog.fetch(telescope, night, **opts)
  File "/home/lachaume/git/autolog/scripts/../autolog/eso/periodlog.py", line 56, in <listcomp>
    logs = [NightLog.fetch(telescope, night, **opts)
  File "/home/lachaume/git/autolog/scripts/../autolog/eso/nightlog.py", line 67, in fetch
    log = query.fetch(night=night, use_tap_cache=use_tap_cache)
  File "/home/lachaume/git/autolog/scripts/../autolog/eso/tapquery.py", line 115, in fetch
    tab = tap.execute().to_table()
  File "/usr/local/lib/python3.10/dist-packages/pyvo/dal/tap.py", line 942, in execute
    return TAPResults(self.execute_votable(), url=self.queryurl, session=self._session)
  File "/usr/local/lib/python3.10/dist-packages/pyvo/dal/query.py", line 245, in execute_votable
    raise DALFormatError(e, self.queryurl)
pyvo.dal.exceptions.DALFormatError: ConnectionError: HTTPConnectionPool(host='archive.eso.org', port=80): Max retries exceeded with url: /tap_obs/sync (Caused by NewConnectionError('<urllib3.connection.HTTPConnection object at 0x7f5f53a942e0>: Failed to establish a new connection: [Errno -3] Temporary failure in name resolution'))

git add * in /home/lachaume/git/autolog
git commit
git push
ssh: Could not resolve hostname github.com: Temporary failure in name resolution
fatal: Could not read from remote repository.

Please make sure you have the correct access rights
and the repository exists.

github pull in /data/www/twoptwo.com
ssh: Could not resolve hostname github.com: Temporary failure in name resolution
fatal: Could not read from remote repository.

Please make sure you have the correct access rights
and the repository exists.

ssh: Could not resolve hostname github.com: Temporary failure in name resolution
fatal: Could not read from remote repository.

Please make sure you have the correct access rights
and the repository exists.

executing periodlog.py in /home/lachaume/git/autolog/scripts

git add * in /data/www/twoptwo.com
git commit

daily.sh at 2022-07-07T16:02:01-04:00
-------------------------------------

github pull in /home/lachaume/git/autolog
ssh: Could not resolve hostname github.com: Temporary failure in name resolution
fatal: Could not read from remote repository.

Please make sure you have the correct access rights
and the repository exists.

github pull in /data/www/twoptwo.com
ssh: Could not resolve hostname github.com: Temporary failure in name resolution
fatal: Could not read from remote repository.

Please make sure you have the correct access rights
and the repository exists.

executing periodlog.py in /home/lachaume/git/autolog/scripts

daily.sh at 2022-07-07T16:03:01-04:00
-------------------------------------

github pull in /home/lachaume/git/autolog
Traceback (most recent call last):
  File "/usr/lib/python3/dist-packages/urllib3/connection.py", line 169, in _new_conn
    conn = connection.create_connection(
  File "/usr/lib/python3/dist-packages/urllib3/util/connection.py", line 73, in create_connection
    for res in socket.getaddrinfo(host, port, family, socket.SOCK_STREAM):
  File "/usr/lib/python3.10/socket.py", line 955, in getaddrinfo
    for res in _socket.getaddrinfo(host, port, family, type, proto, flags):
socket.gaierror: [Errno -3] Temporary failure in name resolution

During handling of the above exception, another exception occurred:

Traceback (most recent call last):
  File "/usr/lib/python3/dist-packages/urllib3/connectionpool.py", line 699, in urlopen
    httplib_response = self._make_request(
  File "/usr/lib/python3/dist-packages/urllib3/connectionpool.py", line 394, in _make_request
    conn.request(method, url, **httplib_request_kw)
  File "/usr/lib/python3/dist-packages/urllib3/connection.py", line 234, in request
    super(HTTPConnection, self).request(method, url, body=body, headers=headers)
  File "/usr/lib/python3.10/http/client.py", line 1282, in request
    self._send_request(method, url, body, headers, encode_chunked)
  File "/usr/lib/python3.10/http/client.py", line 1328, in _send_request
    self.endheaders(body, encode_chunked=encode_chunked)
  File "/usr/lib/python3.10/http/client.py", line 1277, in endheaders
    self._send_output(message_body, encode_chunked=encode_chunked)
  File "/usr/lib/python3.10/http/client.py", line 1037, in _send_output
    self.send(msg)
  File "/usr/lib/python3.10/http/client.py", line 975, in send
    self.connect()
  File "/usr/lib/python3/dist-packages/urllib3/connection.py", line 200, in connect
    conn = self._new_conn()
  File "/usr/lib/python3/dist-packages/urllib3/connection.py", line 181, in _new_conn
    raise NewConnectionError(
urllib3.exceptions.NewConnectionError: <urllib3.connection.HTTPConnection object at 0x7f4fef8240a0>: Failed to establish a new connection: [Errno -3] Temporary failure in name resolution

During handling of the above exception, another exception occurred:

Traceback (most recent call last):
  File "/usr/lib/python3/dist-packages/requests/adapters.py", line 439, in send
    resp = conn.urlopen(
  File "/usr/lib/python3/dist-packages/urllib3/connectionpool.py", line 755, in urlopen
    retries = retries.increment(
  File "/usr/lib/python3/dist-packages/urllib3/util/retry.py", line 574, in increment
    raise MaxRetryError(_pool, url, error or ResponseError(cause))
urllib3.exceptions.MaxRetryError: HTTPConnectionPool(host='archive.eso.org', port=80): Max retries exceeded with url: /tap_obs/sync (Caused by NewConnectionError('<urllib3.connection.HTTPConnection object at 0x7f4fef8240a0>: Failed to establish a new connection: [Errno -3] Temporary failure in name resolution'))

During handling of the above exception, another exception occurred:

Traceback (most recent call last):
  File "/usr/local/lib/python3.10/dist-packages/pyvo/dal/query.py", line 242, in execute_votable
    return votableparse(self.execute_stream(post=post).read)
  File "/usr/local/lib/python3.10/dist-packages/pyvo/dal/tap.py", line 926, in execute_stream
    return super().execute_stream(post=post)
  File "/usr/local/lib/python3.10/dist-packages/pyvo/utils/decorators.py", line 9, in wrapper
    raw = func(*args, **kwargs)
  File "/usr/local/lib/python3.10/dist-packages/pyvo/dal/query.py", line 191, in execute_stream
    response = self.submit(post=post)
  File "/usr/local/lib/python3.10/dist-packages/pyvo/dal/tap.py", line 959, in submit
    response = self._session.post(
  File "/usr/lib/python3/dist-packages/requests/sessions.py", line 590, in post
    return self.request('POST', url, data=data, json=json, **kwargs)
  File "/usr/lib/python3/dist-packages/requests/sessions.py", line 542, in request
    resp = self.send(prep, **send_kwargs)
  File "/usr/lib/python3/dist-packages/requests/sessions.py", line 655, in send
    r = adapter.send(request, **kwargs)
  File "/usr/lib/python3/dist-packages/requests/adapters.py", line 516, in send
    raise ConnectionError(e, request=request)
requests.exceptions.ConnectionError: HTTPConnectionPool(host='archive.eso.org', port=80): Max retries exceeded with url: /tap_obs/sync (Caused by NewConnectionError('<urllib3.connection.HTTPConnection object at 0x7f4fef8240a0>: Failed to establish a new connection: [Errno -3] Temporary failure in name resolution'))

During handling of the above exception, another exception occurred:

Traceback (most recent call last):
  File "/home/lachaume/git/autolog/scripts/./periodlog.py", line 22, in <module>
    log = PeriodLog.fetch(telescope, period, **opts) 
  File "/home/lachaume/git/autolog/scripts/../autolog/eso/periodlog.py", line 56, in fetch
    logs = [NightLog.fetch(telescope, night, **opts)
  File "/home/lachaume/git/autolog/scripts/../autolog/eso/periodlog.py", line 56, in <listcomp>
    logs = [NightLog.fetch(telescope, night, **opts)
  File "/home/lachaume/git/autolog/scripts/../autolog/eso/nightlog.py", line 67, in fetch
    log = query.fetch(night=night, use_tap_cache=use_tap_cache)
  File "/home/lachaume/git/autolog/scripts/../autolog/eso/tapquery.py", line 115, in fetch
    tab = tap.execute().to_table()
  File "/usr/local/lib/python3.10/dist-packages/pyvo/dal/tap.py", line 942, in execute
    return TAPResults(self.execute_votable(), url=self.queryurl, session=self._session)
  File "/usr/local/lib/python3.10/dist-packages/pyvo/dal/query.py", line 245, in execute_votable
    raise DALFormatError(e, self.queryurl)
pyvo.dal.exceptions.DALFormatError: ConnectionError: HTTPConnectionPool(host='archive.eso.org', port=80): Max retries exceeded with url: /tap_obs/sync (Caused by NewConnectionError('<urllib3.connection.HTTPConnection object at 0x7f4fef8240a0>: Failed to establish a new connection: [Errno -3] Temporary failure in name resolution'))

git add * in /home/lachaume/git/autolog
git commit
git push
Everything up-to-date


daily.sh at 2022-07-07T16:04:00-04:00
-------------------------------------

github pull in /home/lachaume/git/autolog

github pull in /data/www/twoptwo.com

executing periodlog.py in /home/lachaume/git/autolog/scripts

daily.sh at 2022-07-07T16:05:01-04:00
-------------------------------------

github pull in /home/lachaume/git/autolog
ssh: Could not resolve hostname github.com: Temporary failure in name resolution
fatal: Could not read from remote repository.

Please make sure you have the correct access rights
and the repository exists.

github pull in /data/www/twoptwo.com
ssh: Could not resolve hostname github.com: Temporary failure in name resolution
fatal: Could not read from remote repository.

Please make sure you have the correct access rights
and the repository exists.

executing periodlog.py in /home/lachaume/git/autolog/scripts

daily.sh at 2022-07-07T16:06:01-04:00
-------------------------------------

github pull in /home/lachaume/git/autolog
Traceback (most recent call last):
  File "/usr/lib/python3/dist-packages/urllib3/connection.py", line 169, in _new_conn
    conn = connection.create_connection(
  File "/usr/lib/python3/dist-packages/urllib3/util/connection.py", line 73, in create_connection
    for res in socket.getaddrinfo(host, port, family, socket.SOCK_STREAM):
  File "/usr/lib/python3.10/socket.py", line 955, in getaddrinfo
    for res in _socket.getaddrinfo(host, port, family, type, proto, flags):
socket.gaierror: [Errno -3] Temporary failure in name resolution

During handling of the above exception, another exception occurred:

Traceback (most recent call last):
  File "/usr/lib/python3/dist-packages/urllib3/connectionpool.py", line 699, in urlopen
    httplib_response = self._make_request(
  File "/usr/lib/python3/dist-packages/urllib3/connectionpool.py", line 394, in _make_request
    conn.request(method, url, **httplib_request_kw)
  File "/usr/lib/python3/dist-packages/urllib3/connection.py", line 234, in request
    super(HTTPConnection, self).request(method, url, body=body, headers=headers)
  File "/usr/lib/python3.10/http/client.py", line 1282, in request
    self._send_request(method, url, body, headers, encode_chunked)
  File "/usr/lib/python3.10/http/client.py", line 1328, in _send_request
    self.endheaders(body, encode_chunked=encode_chunked)
  File "/usr/lib/python3.10/http/client.py", line 1277, in endheaders
    self._send_output(message_body, encode_chunked=encode_chunked)
  File "/usr/lib/python3.10/http/client.py", line 1037, in _send_output
    self.send(msg)
  File "/usr/lib/python3.10/http/client.py", line 975, in send
    self.connect()
  File "/usr/lib/python3/dist-packages/urllib3/connection.py", line 200, in connect
    conn = self._new_conn()
  File "/usr/lib/python3/dist-packages/urllib3/connection.py", line 181, in _new_conn
    raise NewConnectionError(
urllib3.exceptions.NewConnectionError: <urllib3.connection.HTTPConnection object at 0x7f77634947f0>: Failed to establish a new connection: [Errno -3] Temporary failure in name resolution

During handling of the above exception, another exception occurred:

Traceback (most recent call last):
  File "/usr/lib/python3/dist-packages/requests/adapters.py", line 439, in send
    resp = conn.urlopen(
  File "/usr/lib/python3/dist-packages/urllib3/connectionpool.py", line 755, in urlopen
    retries = retries.increment(
  File "/usr/lib/python3/dist-packages/urllib3/util/retry.py", line 574, in increment
    raise MaxRetryError(_pool, url, error or ResponseError(cause))
urllib3.exceptions.MaxRetryError: HTTPConnectionPool(host='archive.eso.org', port=80): Max retries exceeded with url: /tap_obs/sync (Caused by NewConnectionError('<urllib3.connection.HTTPConnection object at 0x7f77634947f0>: Failed to establish a new connection: [Errno -3] Temporary failure in name resolution'))

During handling of the above exception, another exception occurred:

Traceback (most recent call last):
  File "/usr/local/lib/python3.10/dist-packages/pyvo/dal/query.py", line 242, in execute_votable
    return votableparse(self.execute_stream(post=post).read)
  File "/usr/local/lib/python3.10/dist-packages/pyvo/dal/tap.py", line 926, in execute_stream
    return super().execute_stream(post=post)
  File "/usr/local/lib/python3.10/dist-packages/pyvo/utils/decorators.py", line 9, in wrapper
    raw = func(*args, **kwargs)
  File "/usr/local/lib/python3.10/dist-packages/pyvo/dal/query.py", line 191, in execute_stream
    response = self.submit(post=post)
  File "/usr/local/lib/python3.10/dist-packages/pyvo/dal/tap.py", line 959, in submit
    response = self._session.post(
  File "/usr/lib/python3/dist-packages/requests/sessions.py", line 590, in post
    return self.request('POST', url, data=data, json=json, **kwargs)
  File "/usr/lib/python3/dist-packages/requests/sessions.py", line 542, in request
    resp = self.send(prep, **send_kwargs)
  File "/usr/lib/python3/dist-packages/requests/sessions.py", line 655, in send
    r = adapter.send(request, **kwargs)
  File "/usr/lib/python3/dist-packages/requests/adapters.py", line 516, in send
    raise ConnectionError(e, request=request)
requests.exceptions.ConnectionError: HTTPConnectionPool(host='archive.eso.org', port=80): Max retries exceeded with url: /tap_obs/sync (Caused by NewConnectionError('<urllib3.connection.HTTPConnection object at 0x7f77634947f0>: Failed to establish a new connection: [Errno -3] Temporary failure in name resolution'))

During handling of the above exception, another exception occurred:

Traceback (most recent call last):
  File "/home/lachaume/git/autolog/scripts/./periodlog.py", line 22, in <module>
    log = PeriodLog.fetch(telescope, period, **opts) 
  File "/home/lachaume/git/autolog/scripts/../autolog/eso/periodlog.py", line 56, in fetch
    logs = [NightLog.fetch(telescope, night, **opts)
  File "/home/lachaume/git/autolog/scripts/../autolog/eso/periodlog.py", line 56, in <listcomp>
    logs = [NightLog.fetch(telescope, night, **opts)
  File "/home/lachaume/git/autolog/scripts/../autolog/eso/nightlog.py", line 67, in fetch
    log = query.fetch(night=night, use_tap_cache=use_tap_cache)
  File "/home/lachaume/git/autolog/scripts/../autolog/eso/tapquery.py", line 115, in fetch
    tab = tap.execute().to_table()
  File "/usr/local/lib/python3.10/dist-packages/pyvo/dal/tap.py", line 942, in execute
    return TAPResults(self.execute_votable(), url=self.queryurl, session=self._session)
  File "/usr/local/lib/python3.10/dist-packages/pyvo/dal/query.py", line 245, in execute_votable
    raise DALFormatError(e, self.queryurl)
pyvo.dal.exceptions.DALFormatError: ConnectionError: HTTPConnectionPool(host='archive.eso.org', port=80): Max retries exceeded with url: /tap_obs/sync (Caused by NewConnectionError('<urllib3.connection.HTTPConnection object at 0x7f77634947f0>: Failed to establish a new connection: [Errno -3] Temporary failure in name resolution'))

git add * in /home/lachaume/git/autolog
git commit
git push
ssh: Could not resolve hostname github.com: Temporary failure in name resolution
fatal: Could not read from remote repository.

Please make sure you have the correct access rights
and the repository exists.

github pull in /data/www/twoptwo.com
ssh: Could not resolve hostname github.com: Temporary failure in name resolution
fatal: Could not read from remote repository.

Please make sure you have the correct access rights
and the repository exists.

ssh: Could not resolve hostname github.com: Temporary failure in name resolution
fatal: Could not read from remote repository.

Please make sure you have the correct access rights
and the repository exists.

executing periodlog.py in /home/lachaume/git/autolog/scripts

git add * in /data/www/twoptwo.com
git commit

daily.sh at 2022-07-07T16:07:01-04:00
-------------------------------------

github pull in /home/lachaume/git/autolog
Traceback (most recent call last):
  File "/usr/lib/python3/dist-packages/urllib3/connection.py", line 169, in _new_conn
    conn = connection.create_connection(
  File "/usr/lib/python3/dist-packages/urllib3/util/connection.py", line 73, in create_connection
    for res in socket.getaddrinfo(host, port, family, socket.SOCK_STREAM):
  File "/usr/lib/python3.10/socket.py", line 955, in getaddrinfo
    for res in _socket.getaddrinfo(host, port, family, type, proto, flags):
socket.gaierror: [Errno -3] Temporary failure in name resolution

During handling of the above exception, another exception occurred:

Traceback (most recent call last):
  File "/usr/lib/python3/dist-packages/urllib3/connectionpool.py", line 699, in urlopen
    httplib_response = self._make_request(
  File "/usr/lib/python3/dist-packages/urllib3/connectionpool.py", line 394, in _make_request
    conn.request(method, url, **httplib_request_kw)
  File "/usr/lib/python3/dist-packages/urllib3/connection.py", line 234, in request
    super(HTTPConnection, self).request(method, url, body=body, headers=headers)
  File "/usr/lib/python3.10/http/client.py", line 1282, in request
    self._send_request(method, url, body, headers, encode_chunked)
  File "/usr/lib/python3.10/http/client.py", line 1328, in _send_request
    self.endheaders(body, encode_chunked=encode_chunked)
  File "/usr/lib/python3.10/http/client.py", line 1277, in endheaders
    self._send_output(message_body, encode_chunked=encode_chunked)
  File "/usr/lib/python3.10/http/client.py", line 1037, in _send_output
    self.send(msg)
  File "/usr/lib/python3.10/http/client.py", line 975, in send
    self.connect()
  File "/usr/lib/python3/dist-packages/urllib3/connection.py", line 200, in connect
    conn = self._new_conn()
  File "/usr/lib/python3/dist-packages/urllib3/connection.py", line 181, in _new_conn
    raise NewConnectionError(
urllib3.exceptions.NewConnectionError: <urllib3.connection.HTTPConnection object at 0x7f23fc994100>: Failed to establish a new connection: [Errno -3] Temporary failure in name resolution

During handling of the above exception, another exception occurred:

Traceback (most recent call last):
  File "/usr/lib/python3/dist-packages/requests/adapters.py", line 439, in send
    resp = conn.urlopen(
  File "/usr/lib/python3/dist-packages/urllib3/connectionpool.py", line 755, in urlopen
    retries = retries.increment(
  File "/usr/lib/python3/dist-packages/urllib3/util/retry.py", line 574, in increment
    raise MaxRetryError(_pool, url, error or ResponseError(cause))
urllib3.exceptions.MaxRetryError: HTTPConnectionPool(host='archive.eso.org', port=80): Max retries exceeded with url: /tap_obs/sync (Caused by NewConnectionError('<urllib3.connection.HTTPConnection object at 0x7f23fc994100>: Failed to establish a new connection: [Errno -3] Temporary failure in name resolution'))

During handling of the above exception, another exception occurred:

Traceback (most recent call last):
  File "/usr/local/lib/python3.10/dist-packages/pyvo/dal/query.py", line 242, in execute_votable
    return votableparse(self.execute_stream(post=post).read)
  File "/usr/local/lib/python3.10/dist-packages/pyvo/dal/tap.py", line 926, in execute_stream
    return super().execute_stream(post=post)
  File "/usr/local/lib/python3.10/dist-packages/pyvo/utils/decorators.py", line 9, in wrapper
    raw = func(*args, **kwargs)
  File "/usr/local/lib/python3.10/dist-packages/pyvo/dal/query.py", line 191, in execute_stream
    response = self.submit(post=post)
  File "/usr/local/lib/python3.10/dist-packages/pyvo/dal/tap.py", line 959, in submit
    response = self._session.post(
  File "/usr/lib/python3/dist-packages/requests/sessions.py", line 590, in post
    return self.request('POST', url, data=data, json=json, **kwargs)
  File "/usr/lib/python3/dist-packages/requests/sessions.py", line 542, in request
    resp = self.send(prep, **send_kwargs)
  File "/usr/lib/python3/dist-packages/requests/sessions.py", line 655, in send
    r = adapter.send(request, **kwargs)
  File "/usr/lib/python3/dist-packages/requests/adapters.py", line 516, in send
    raise ConnectionError(e, request=request)
requests.exceptions.ConnectionError: HTTPConnectionPool(host='archive.eso.org', port=80): Max retries exceeded with url: /tap_obs/sync (Caused by NewConnectionError('<urllib3.connection.HTTPConnection object at 0x7f23fc994100>: Failed to establish a new connection: [Errno -3] Temporary failure in name resolution'))

During handling of the above exception, another exception occurred:

Traceback (most recent call last):
  File "/home/lachaume/git/autolog/scripts/./periodlog.py", line 22, in <module>
    log = PeriodLog.fetch(telescope, period, **opts) 
  File "/home/lachaume/git/autolog/scripts/../autolog/eso/periodlog.py", line 56, in fetch
    logs = [NightLog.fetch(telescope, night, **opts)
  File "/home/lachaume/git/autolog/scripts/../autolog/eso/periodlog.py", line 56, in <listcomp>
    logs = [NightLog.fetch(telescope, night, **opts)
  File "/home/lachaume/git/autolog/scripts/../autolog/eso/nightlog.py", line 67, in fetch
    log = query.fetch(night=night, use_tap_cache=use_tap_cache)
  File "/home/lachaume/git/autolog/scripts/../autolog/eso/tapquery.py", line 115, in fetch
    tab = tap.execute().to_table()
  File "/usr/local/lib/python3.10/dist-packages/pyvo/dal/tap.py", line 942, in execute
    return TAPResults(self.execute_votable(), url=self.queryurl, session=self._session)
  File "/usr/local/lib/python3.10/dist-packages/pyvo/dal/query.py", line 245, in execute_votable
    raise DALFormatError(e, self.queryurl)
pyvo.dal.exceptions.DALFormatError: ConnectionError: HTTPConnectionPool(host='archive.eso.org', port=80): Max retries exceeded with url: /tap_obs/sync (Caused by NewConnectionError('<urllib3.connection.HTTPConnection object at 0x7f23fc994100>: Failed to establish a new connection: [Errno -3] Temporary failure in name resolution'))

git add * in /home/lachaume/git/autolog
git commit
git push
ssh: Could not resolve hostname github.com: Temporary failure in name resolution
fatal: Could not read from remote repository.

Please make sure you have the correct access rights
and the repository exists.

ssh: Could not resolve hostname github.com: Temporary failure in name resolution
fatal: Could not read from remote repository.

Please make sure you have the correct access rights
and the repository exists.

github pull in /data/www/twoptwo.com
ssh: Could not resolve hostname github.com: Temporary failure in name resolution
fatal: Could not read from remote repository.

Please make sure you have the correct access rights
and the repository exists.


git add * in /data/www/twoptwo.com
git commit

executing periodlog.py in /home/lachaume/git/autolog/scripts

daily.sh at 2022-07-07T16:08:01-04:00
-------------------------------------

github pull in /home/lachaume/git/autolog
ssh: Could not resolve hostname github.com: Temporary failure in name resolution
fatal: Could not read from remote repository.

Please make sure you have the correct access rights
and the repository exists.

github pull in /data/www/twoptwo.com
ssh: Could not resolve hostname github.com: Temporary failure in name resolution
fatal: Could not read from remote repository.

Please make sure you have the correct access rights
and the repository exists.

executing periodlog.py in /home/lachaume/git/autolog/scripts

daily.sh at 2022-07-07T16:09:01-04:00
-------------------------------------

github pull in /home/lachaume/git/autolog
Traceback (most recent call last):
  File "/usr/lib/python3/dist-packages/urllib3/connection.py", line 169, in _new_conn
    conn = connection.create_connection(
  File "/usr/lib/python3/dist-packages/urllib3/util/connection.py", line 73, in create_connection
    for res in socket.getaddrinfo(host, port, family, socket.SOCK_STREAM):
  File "/usr/lib/python3.10/socket.py", line 955, in getaddrinfo
    for res in _socket.getaddrinfo(host, port, family, type, proto, flags):
socket.gaierror: [Errno -3] Temporary failure in name resolution

During handling of the above exception, another exception occurred:

Traceback (most recent call last):
  File "/usr/lib/python3/dist-packages/urllib3/connectionpool.py", line 699, in urlopen
    httplib_response = self._make_request(
  File "/usr/lib/python3/dist-packages/urllib3/connectionpool.py", line 394, in _make_request
    conn.request(method, url, **httplib_request_kw)
  File "/usr/lib/python3/dist-packages/urllib3/connection.py", line 234, in request
    super(HTTPConnection, self).request(method, url, body=body, headers=headers)
  File "/usr/lib/python3.10/http/client.py", line 1282, in request
    self._send_request(method, url, body, headers, encode_chunked)
  File "/usr/lib/python3.10/http/client.py", line 1328, in _send_request
    self.endheaders(body, encode_chunked=encode_chunked)
  File "/usr/lib/python3.10/http/client.py", line 1277, in endheaders
    self._send_output(message_body, encode_chunked=encode_chunked)
  File "/usr/lib/python3.10/http/client.py", line 1037, in _send_output
    self.send(msg)
  File "/usr/lib/python3.10/http/client.py", line 975, in send
    self.connect()
  File "/usr/lib/python3/dist-packages/urllib3/connection.py", line 200, in connect
    conn = self._new_conn()
  File "/usr/lib/python3/dist-packages/urllib3/connection.py", line 181, in _new_conn
    raise NewConnectionError(
urllib3.exceptions.NewConnectionError: <urllib3.connection.HTTPConnection object at 0x7ff09bdfc220>: Failed to establish a new connection: [Errno -3] Temporary failure in name resolution

During handling of the above exception, another exception occurred:

Traceback (most recent call last):
  File "/usr/lib/python3/dist-packages/requests/adapters.py", line 439, in send
    resp = conn.urlopen(
  File "/usr/lib/python3/dist-packages/urllib3/connectionpool.py", line 755, in urlopen
    retries = retries.increment(
  File "/usr/lib/python3/dist-packages/urllib3/util/retry.py", line 574, in increment
    raise MaxRetryError(_pool, url, error or ResponseError(cause))
urllib3.exceptions.MaxRetryError: HTTPConnectionPool(host='archive.eso.org', port=80): Max retries exceeded with url: /tap_obs/sync (Caused by NewConnectionError('<urllib3.connection.HTTPConnection object at 0x7ff09bdfc220>: Failed to establish a new connection: [Errno -3] Temporary failure in name resolution'))

During handling of the above exception, another exception occurred:

Traceback (most recent call last):
  File "/usr/local/lib/python3.10/dist-packages/pyvo/dal/query.py", line 242, in execute_votable
    return votableparse(self.execute_stream(post=post).read)
  File "/usr/local/lib/python3.10/dist-packages/pyvo/dal/tap.py", line 926, in execute_stream
    return super().execute_stream(post=post)
  File "/usr/local/lib/python3.10/dist-packages/pyvo/utils/decorators.py", line 9, in wrapper
    raw = func(*args, **kwargs)
  File "/usr/local/lib/python3.10/dist-packages/pyvo/dal/query.py", line 191, in execute_stream
    response = self.submit(post=post)
  File "/usr/local/lib/python3.10/dist-packages/pyvo/dal/tap.py", line 959, in submit
    response = self._session.post(
  File "/usr/lib/python3/dist-packages/requests/sessions.py", line 590, in post
    return self.request('POST', url, data=data, json=json, **kwargs)
  File "/usr/lib/python3/dist-packages/requests/sessions.py", line 542, in request
    resp = self.send(prep, **send_kwargs)
  File "/usr/lib/python3/dist-packages/requests/sessions.py", line 655, in send
    r = adapter.send(request, **kwargs)
  File "/usr/lib/python3/dist-packages/requests/adapters.py", line 516, in send
    raise ConnectionError(e, request=request)
requests.exceptions.ConnectionError: HTTPConnectionPool(host='archive.eso.org', port=80): Max retries exceeded with url: /tap_obs/sync (Caused by NewConnectionError('<urllib3.connection.HTTPConnection object at 0x7ff09bdfc220>: Failed to establish a new connection: [Errno -3] Temporary failure in name resolution'))

During handling of the above exception, another exception occurred:

Traceback (most recent call last):
  File "/home/lachaume/git/autolog/scripts/./periodlog.py", line 22, in <module>
    log = PeriodLog.fetch(telescope, period, **opts) 
  File "/home/lachaume/git/autolog/scripts/../autolog/eso/periodlog.py", line 56, in fetch
    logs = [NightLog.fetch(telescope, night, **opts)
  File "/home/lachaume/git/autolog/scripts/../autolog/eso/periodlog.py", line 56, in <listcomp>
    logs = [NightLog.fetch(telescope, night, **opts)
  File "/home/lachaume/git/autolog/scripts/../autolog/eso/nightlog.py", line 67, in fetch
    log = query.fetch(night=night, use_tap_cache=use_tap_cache)
  File "/home/lachaume/git/autolog/scripts/../autolog/eso/tapquery.py", line 115, in fetch
    tab = tap.execute().to_table()
  File "/usr/local/lib/python3.10/dist-packages/pyvo/dal/tap.py", line 942, in execute
    return TAPResults(self.execute_votable(), url=self.queryurl, session=self._session)
  File "/usr/local/lib/python3.10/dist-packages/pyvo/dal/query.py", line 245, in execute_votable
    raise DALFormatError(e, self.queryurl)
pyvo.dal.exceptions.DALFormatError: ConnectionError: HTTPConnectionPool(host='archive.eso.org', port=80): Max retries exceeded with url: /tap_obs/sync (Caused by NewConnectionError('<urllib3.connection.HTTPConnection object at 0x7ff09bdfc220>: Failed to establish a new connection: [Errno -3] Temporary failure in name resolution'))

git add * in /home/lachaume/git/autolog
git commit
git push
warning: fetch updated the current branch head.
fast-forwarding your working tree from
commit c42e66ca39b3946475fc002d81a09322f8fe8f11.
error: Your local changes to the following files would be overwritten by merge:
	scripts/logs/2022-07-07.err
	scripts/logs/2022-07-07.log
Please commit your changes or stash them before you merge.
Aborting
fatal: Cannot fast-forward your working tree.
After making sure that you saved anything precious from
$ git diff c42e66ca39b3946475fc002d81a09322f8fe8f11
output, run
$ git reset --hard
to recover.

github pull in /data/www/twoptwo.com
To github.com:loqueelvientoajuarez/obslog.git
   3cc26f2..c91f743  master -> master


executing periodlog.py in /home/lachaume/git/autolog/scripts

git add * in /data/www/twoptwo.com
git commit
Everything up-to-date

Everything up-to-date


daily.sh at 2022-07-07T16:10:01-04:00
-------------------------------------

github pull in /home/lachaume/git/autolog
ssh: Could not resolve hostname github.com: Temporary failure in name resolution
fatal: Could not read from remote repository.

Please make sure you have the correct access rights
and the repository exists.

github pull in /data/www/twoptwo.com
Traceback (most recent call last):
  File "/usr/lib/python3/dist-packages/urllib3/connection.py", line 169, in _new_conn
    conn = connection.create_connection(
  File "/usr/lib/python3/dist-packages/urllib3/util/connection.py", line 73, in create_connection
    for res in socket.getaddrinfo(host, port, family, socket.SOCK_STREAM):
  File "/usr/lib/python3.10/socket.py", line 955, in getaddrinfo
    for res in _socket.getaddrinfo(host, port, family, type, proto, flags):
socket.gaierror: [Errno -3] Temporary failure in name resolution

During handling of the above exception, another exception occurred:

Traceback (most recent call last):
  File "/usr/lib/python3/dist-packages/urllib3/connectionpool.py", line 699, in urlopen
    httplib_response = self._make_request(
  File "/usr/lib/python3/dist-packages/urllib3/connectionpool.py", line 394, in _make_request
    conn.request(method, url, **httplib_request_kw)
  File "/usr/lib/python3/dist-packages/urllib3/connection.py", line 234, in request
    super(HTTPConnection, self).request(method, url, body=body, headers=headers)
  File "/usr/lib/python3.10/http/client.py", line 1282, in request
    self._send_request(method, url, body, headers, encode_chunked)
  File "/usr/lib/python3.10/http/client.py", line 1328, in _send_request
    self.endheaders(body, encode_chunked=encode_chunked)
  File "/usr/lib/python3.10/http/client.py", line 1277, in endheaders
    self._send_output(message_body, encode_chunked=encode_chunked)
  File "/usr/lib/python3.10/http/client.py", line 1037, in _send_output
    self.send(msg)
  File "/usr/lib/python3.10/http/client.py", line 975, in send
    self.connect()
  File "/usr/lib/python3/dist-packages/urllib3/connection.py", line 200, in connect
    conn = self._new_conn()
  File "/usr/lib/python3/dist-packages/urllib3/connection.py", line 181, in _new_conn
    raise NewConnectionError(
urllib3.exceptions.NewConnectionError: <urllib3.connection.HTTPConnection object at 0x7f6408766410>: Failed to establish a new connection: [Errno -3] Temporary failure in name resolution

During handling of the above exception, another exception occurred:

Traceback (most recent call last):
  File "/usr/lib/python3/dist-packages/requests/adapters.py", line 439, in send
    resp = conn.urlopen(
  File "/usr/lib/python3/dist-packages/urllib3/connectionpool.py", line 755, in urlopen
    retries = retries.increment(
  File "/usr/lib/python3/dist-packages/urllib3/util/retry.py", line 574, in increment
    raise MaxRetryError(_pool, url, error or ResponseError(cause))
urllib3.exceptions.MaxRetryError: HTTPConnectionPool(host='archive.eso.org', port=80): Max retries exceeded with url: /tap_obs/sync (Caused by NewConnectionError('<urllib3.connection.HTTPConnection object at 0x7f6408766410>: Failed to establish a new connection: [Errno -3] Temporary failure in name resolution'))

During handling of the above exception, another exception occurred:

Traceback (most recent call last):
  File "/usr/local/lib/python3.10/dist-packages/pyvo/dal/query.py", line 242, in execute_votable
    return votableparse(self.execute_stream(post=post).read)
  File "/usr/local/lib/python3.10/dist-packages/pyvo/dal/tap.py", line 926, in execute_stream
    return super().execute_stream(post=post)
  File "/usr/local/lib/python3.10/dist-packages/pyvo/utils/decorators.py", line 9, in wrapper
    raw = func(*args, **kwargs)
  File "/usr/local/lib/python3.10/dist-packages/pyvo/dal/query.py", line 191, in execute_stream
    response = self.submit(post=post)
  File "/usr/local/lib/python3.10/dist-packages/pyvo/dal/tap.py", line 959, in submit
    response = self._session.post(
  File "/usr/lib/python3/dist-packages/requests/sessions.py", line 590, in post
    return self.request('POST', url, data=data, json=json, **kwargs)
  File "/usr/lib/python3/dist-packages/requests/sessions.py", line 542, in request
    resp = self.send(prep, **send_kwargs)
  File "/usr/lib/python3/dist-packages/requests/sessions.py", line 655, in send
    r = adapter.send(request, **kwargs)
  File "/usr/lib/python3/dist-packages/requests/adapters.py", line 516, in send
    raise ConnectionError(e, request=request)
requests.exceptions.ConnectionError: HTTPConnectionPool(host='archive.eso.org', port=80): Max retries exceeded with url: /tap_obs/sync (Caused by NewConnectionError('<urllib3.connection.HTTPConnection object at 0x7f6408766410>: Failed to establish a new connection: [Errno -3] Temporary failure in name resolution'))

During handling of the above exception, another exception occurred:

Traceback (most recent call last):
  File "/home/lachaume/git/autolog/scripts/./periodlog.py", line 22, in <module>
    log = PeriodLog.fetch(telescope, period, **opts) 
  File "/home/lachaume/git/autolog/scripts/../autolog/eso/periodlog.py", line 56, in fetch
    logs = [NightLog.fetch(telescope, night, **opts)
  File "/home/lachaume/git/autolog/scripts/../autolog/eso/periodlog.py", line 56, in <listcomp>
    logs = [NightLog.fetch(telescope, night, **opts)
  File "/home/lachaume/git/autolog/scripts/../autolog/eso/nightlog.py", line 67, in fetch
    log = query.fetch(night=night, use_tap_cache=use_tap_cache)
  File "/home/lachaume/git/autolog/scripts/../autolog/eso/tapquery.py", line 115, in fetch
    tab = tap.execute().to_table()
  File "/usr/local/lib/python3.10/dist-packages/pyvo/dal/tap.py", line 942, in execute
    return TAPResults(self.execute_votable(), url=self.queryurl, session=self._session)
  File "/usr/local/lib/python3.10/dist-packages/pyvo/dal/query.py", line 245, in execute_votable
    raise DALFormatError(e, self.queryurl)
pyvo.dal.exceptions.DALFormatError: ConnectionError: HTTPConnectionPool(host='archive.eso.org', port=80): Max retries exceeded with url: /tap_obs/sync (Caused by NewConnectionError('<urllib3.connection.HTTPConnection object at 0x7f6408766410>: Failed to establish a new connection: [Errno -3] Temporary failure in name resolution'))

git add * in /home/lachaume/git/autolog
git commit
git push
ssh: Could not resolve hostname github.com: Temporary failure in name resolution
fatal: Could not read from remote repository.

Please make sure you have the correct access rights
and the repository exists.

executing periodlog.py in /home/lachaume/git/autolog/scripts
ssh: Could not resolve hostname github.com: Temporary failure in name resolution
fatal: Could not read from remote repository.

Please make sure you have the correct access rights
and the repository exists.


daily.sh at 2022-07-07T16:11:01-04:00
-------------------------------------

github pull in /home/lachaume/git/autolog
Traceback (most recent call last):
  File "/usr/lib/python3/dist-packages/urllib3/connection.py", line 169, in _new_conn
    conn = connection.create_connection(
  File "/usr/lib/python3/dist-packages/urllib3/util/connection.py", line 73, in create_connection
    for res in socket.getaddrinfo(host, port, family, socket.SOCK_STREAM):
  File "/usr/lib/python3.10/socket.py", line 955, in getaddrinfo
    for res in _socket.getaddrinfo(host, port, family, type, proto, flags):
socket.gaierror: [Errno -3] Temporary failure in name resolution

During handling of the above exception, another exception occurred:

Traceback (most recent call last):
  File "/usr/lib/python3/dist-packages/urllib3/connectionpool.py", line 699, in urlopen
    httplib_response = self._make_request(
  File "/usr/lib/python3/dist-packages/urllib3/connectionpool.py", line 394, in _make_request
    conn.request(method, url, **httplib_request_kw)
  File "/usr/lib/python3/dist-packages/urllib3/connection.py", line 234, in request
    super(HTTPConnection, self).request(method, url, body=body, headers=headers)
  File "/usr/lib/python3.10/http/client.py", line 1282, in request
    self._send_request(method, url, body, headers, encode_chunked)
  File "/usr/lib/python3.10/http/client.py", line 1328, in _send_request
    self.endheaders(body, encode_chunked=encode_chunked)
  File "/usr/lib/python3.10/http/client.py", line 1277, in endheaders
    self._send_output(message_body, encode_chunked=encode_chunked)
  File "/usr/lib/python3.10/http/client.py", line 1037, in _send_output
    self.send(msg)
  File "/usr/lib/python3.10/http/client.py", line 975, in send
    self.connect()
  File "/usr/lib/python3/dist-packages/urllib3/connection.py", line 200, in connect
    conn = self._new_conn()
  File "/usr/lib/python3/dist-packages/urllib3/connection.py", line 181, in _new_conn
    raise NewConnectionError(
urllib3.exceptions.NewConnectionError: <urllib3.connection.HTTPConnection object at 0x7fcaebfd04c0>: Failed to establish a new connection: [Errno -3] Temporary failure in name resolution

During handling of the above exception, another exception occurred:

Traceback (most recent call last):
  File "/usr/lib/python3/dist-packages/requests/adapters.py", line 439, in send
    resp = conn.urlopen(
  File "/usr/lib/python3/dist-packages/urllib3/connectionpool.py", line 755, in urlopen
    retries = retries.increment(
  File "/usr/lib/python3/dist-packages/urllib3/util/retry.py", line 574, in increment
    raise MaxRetryError(_pool, url, error or ResponseError(cause))
urllib3.exceptions.MaxRetryError: HTTPConnectionPool(host='archive.eso.org', port=80): Max retries exceeded with url: /tap_obs/sync (Caused by NewConnectionError('<urllib3.connection.HTTPConnection object at 0x7fcaebfd04c0>: Failed to establish a new connection: [Errno -3] Temporary failure in name resolution'))

During handling of the above exception, another exception occurred:

Traceback (most recent call last):
  File "/usr/local/lib/python3.10/dist-packages/pyvo/dal/query.py", line 242, in execute_votable
    return votableparse(self.execute_stream(post=post).read)
  File "/usr/local/lib/python3.10/dist-packages/pyvo/dal/tap.py", line 926, in execute_stream
    return super().execute_stream(post=post)
  File "/usr/local/lib/python3.10/dist-packages/pyvo/utils/decorators.py", line 9, in wrapper
    raw = func(*args, **kwargs)
  File "/usr/local/lib/python3.10/dist-packages/pyvo/dal/query.py", line 191, in execute_stream
    response = self.submit(post=post)
  File "/usr/local/lib/python3.10/dist-packages/pyvo/dal/tap.py", line 959, in submit
    response = self._session.post(
  File "/usr/lib/python3/dist-packages/requests/sessions.py", line 590, in post
    return self.request('POST', url, data=data, json=json, **kwargs)
  File "/usr/lib/python3/dist-packages/requests/sessions.py", line 542, in request
    resp = self.send(prep, **send_kwargs)
  File "/usr/lib/python3/dist-packages/requests/sessions.py", line 655, in send
    r = adapter.send(request, **kwargs)
  File "/usr/lib/python3/dist-packages/requests/adapters.py", line 516, in send
    raise ConnectionError(e, request=request)
requests.exceptions.ConnectionError: HTTPConnectionPool(host='archive.eso.org', port=80): Max retries exceeded with url: /tap_obs/sync (Caused by NewConnectionError('<urllib3.connection.HTTPConnection object at 0x7fcaebfd04c0>: Failed to establish a new connection: [Errno -3] Temporary failure in name resolution'))

During handling of the above exception, another exception occurred:

Traceback (most recent call last):
  File "/home/lachaume/git/autolog/scripts/./periodlog.py", line 22, in <module>
    log = PeriodLog.fetch(telescope, period, **opts) 
  File "/home/lachaume/git/autolog/scripts/../autolog/eso/periodlog.py", line 56, in fetch
    logs = [NightLog.fetch(telescope, night, **opts)
  File "/home/lachaume/git/autolog/scripts/../autolog/eso/periodlog.py", line 56, in <listcomp>
    logs = [NightLog.fetch(telescope, night, **opts)
  File "/home/lachaume/git/autolog/scripts/../autolog/eso/nightlog.py", line 67, in fetch
    log = query.fetch(night=night, use_tap_cache=use_tap_cache)
  File "/home/lachaume/git/autolog/scripts/../autolog/eso/tapquery.py", line 115, in fetch
    tab = tap.execute().to_table()
  File "/usr/local/lib/python3.10/dist-packages/pyvo/dal/tap.py", line 942, in execute
    return TAPResults(self.execute_votable(), url=self.queryurl, session=self._session)
  File "/usr/local/lib/python3.10/dist-packages/pyvo/dal/query.py", line 245, in execute_votable
    raise DALFormatError(e, self.queryurl)
pyvo.dal.exceptions.DALFormatError: ConnectionError: HTTPConnectionPool(host='archive.eso.org', port=80): Max retries exceeded with url: /tap_obs/sync (Caused by NewConnectionError('<urllib3.connection.HTTPConnection object at 0x7fcaebfd04c0>: Failed to establish a new connection: [Errno -3] Temporary failure in name resolution'))

git add * in /home/lachaume/git/autolog
git commit
git push

git add * in /data/www/twoptwo.com
git commit
Everything up-to-date

warning: fetch updated the current branch head.
fast-forwarding your working tree from
commit f2df0aaab04a13f0f80a6594b712cca2d6ccdf07.
error: Your local changes to the following files would be overwritten by merge:
	scripts/logs/2022-07-07.err
	scripts/logs/2022-07-07.log
Please commit your changes or stash them before you merge.
Aborting
fatal: Cannot fast-forward your working tree.
After making sure that you saved anything precious from
$ git diff f2df0aaab04a13f0f80a6594b712cca2d6ccdf07
output, run
$ git reset --hard
to recover.

github pull in /data/www/twoptwo.com
To github.com:loqueelvientoajuarez/obslog.git
   c91f743..2b6c8eb  master -> master


executing periodlog.py in /home/lachaume/git/autolog/scripts

git add * in /data/www/twoptwo.com
git commit
Everything up-to-date


daily.sh at 2022-07-07T16:12:01-04:00
-------------------------------------

github pull in /home/lachaume/git/autolog
Traceback (most recent call last):
  File "/usr/lib/python3/dist-packages/urllib3/connection.py", line 169, in _new_conn
    conn = connection.create_connection(
  File "/usr/lib/python3/dist-packages/urllib3/util/connection.py", line 73, in create_connection
    for res in socket.getaddrinfo(host, port, family, socket.SOCK_STREAM):
  File "/usr/lib/python3.10/socket.py", line 955, in getaddrinfo
    for res in _socket.getaddrinfo(host, port, family, type, proto, flags):
socket.gaierror: [Errno -3] Temporary failure in name resolution

During handling of the above exception, another exception occurred:

Traceback (most recent call last):
  File "/usr/lib/python3/dist-packages/urllib3/connectionpool.py", line 699, in urlopen
    httplib_response = self._make_request(
  File "/usr/lib/python3/dist-packages/urllib3/connectionpool.py", line 394, in _make_request
    conn.request(method, url, **httplib_request_kw)
  File "/usr/lib/python3/dist-packages/urllib3/connection.py", line 234, in request
    super(HTTPConnection, self).request(method, url, body=body, headers=headers)
  File "/usr/lib/python3.10/http/client.py", line 1282, in request
    self._send_request(method, url, body, headers, encode_chunked)
  File "/usr/lib/python3.10/http/client.py", line 1328, in _send_request
    self.endheaders(body, encode_chunked=encode_chunked)
  File "/usr/lib/python3.10/http/client.py", line 1277, in endheaders
    self._send_output(message_body, encode_chunked=encode_chunked)
  File "/usr/lib/python3.10/http/client.py", line 1037, in _send_output
    self.send(msg)
  File "/usr/lib/python3.10/http/client.py", line 975, in send
    self.connect()
  File "/usr/lib/python3/dist-packages/urllib3/connection.py", line 200, in connect
    conn = self._new_conn()
  File "/usr/lib/python3/dist-packages/urllib3/connection.py", line 181, in _new_conn
    raise NewConnectionError(
urllib3.exceptions.NewConnectionError: <urllib3.connection.HTTPConnection object at 0x7f7ff5098070>: Failed to establish a new connection: [Errno -3] Temporary failure in name resolution

During handling of the above exception, another exception occurred:

Traceback (most recent call last):
  File "/usr/lib/python3/dist-packages/requests/adapters.py", line 439, in send
    resp = conn.urlopen(
  File "/usr/lib/python3/dist-packages/urllib3/connectionpool.py", line 755, in urlopen
    retries = retries.increment(
  File "/usr/lib/python3/dist-packages/urllib3/util/retry.py", line 574, in increment
    raise MaxRetryError(_pool, url, error or ResponseError(cause))
urllib3.exceptions.MaxRetryError: HTTPConnectionPool(host='archive.eso.org', port=80): Max retries exceeded with url: /tap_obs/sync (Caused by NewConnectionError('<urllib3.connection.HTTPConnection object at 0x7f7ff5098070>: Failed to establish a new connection: [Errno -3] Temporary failure in name resolution'))

During handling of the above exception, another exception occurred:

Traceback (most recent call last):
  File "/usr/local/lib/python3.10/dist-packages/pyvo/dal/query.py", line 242, in execute_votable
    return votableparse(self.execute_stream(post=post).read)
  File "/usr/local/lib/python3.10/dist-packages/pyvo/dal/tap.py", line 926, in execute_stream
    return super().execute_stream(post=post)
  File "/usr/local/lib/python3.10/dist-packages/pyvo/utils/decorators.py", line 9, in wrapper
    raw = func(*args, **kwargs)
  File "/usr/local/lib/python3.10/dist-packages/pyvo/dal/query.py", line 191, in execute_stream
    response = self.submit(post=post)
  File "/usr/local/lib/python3.10/dist-packages/pyvo/dal/tap.py", line 959, in submit
    response = self._session.post(
  File "/usr/lib/python3/dist-packages/requests/sessions.py", line 590, in post
    return self.request('POST', url, data=data, json=json, **kwargs)
  File "/usr/lib/python3/dist-packages/requests/sessions.py", line 542, in request
    resp = self.send(prep, **send_kwargs)
  File "/usr/lib/python3/dist-packages/requests/sessions.py", line 655, in send
    r = adapter.send(request, **kwargs)
  File "/usr/lib/python3/dist-packages/requests/adapters.py", line 516, in send
    raise ConnectionError(e, request=request)
requests.exceptions.ConnectionError: HTTPConnectionPool(host='archive.eso.org', port=80): Max retries exceeded with url: /tap_obs/sync (Caused by NewConnectionError('<urllib3.connection.HTTPConnection object at 0x7f7ff5098070>: Failed to establish a new connection: [Errno -3] Temporary failure in name resolution'))

During handling of the above exception, another exception occurred:

Traceback (most recent call last):
  File "/home/lachaume/git/autolog/scripts/./periodlog.py", line 22, in <module>
    log = PeriodLog.fetch(telescope, period, **opts) 
  File "/home/lachaume/git/autolog/scripts/../autolog/eso/periodlog.py", line 56, in fetch
    logs = [NightLog.fetch(telescope, night, **opts)
  File "/home/lachaume/git/autolog/scripts/../autolog/eso/periodlog.py", line 56, in <listcomp>
    logs = [NightLog.fetch(telescope, night, **opts)
  File "/home/lachaume/git/autolog/scripts/../autolog/eso/nightlog.py", line 67, in fetch
    log = query.fetch(night=night, use_tap_cache=use_tap_cache)
  File "/home/lachaume/git/autolog/scripts/../autolog/eso/tapquery.py", line 115, in fetch
    tab = tap.execute().to_table()
  File "/usr/local/lib/python3.10/dist-packages/pyvo/dal/tap.py", line 942, in execute
    return TAPResults(self.execute_votable(), url=self.queryurl, session=self._session)
  File "/usr/local/lib/python3.10/dist-packages/pyvo/dal/query.py", line 245, in execute_votable
    raise DALFormatError(e, self.queryurl)
pyvo.dal.exceptions.DALFormatError: ConnectionError: HTTPConnectionPool(host='archive.eso.org', port=80): Max retries exceeded with url: /tap_obs/sync (Caused by NewConnectionError('<urllib3.connection.HTTPConnection object at 0x7f7ff5098070>: Failed to establish a new connection: [Errno -3] Temporary failure in name resolution'))

git add * in /home/lachaume/git/autolog
git commit
git push
warning: fetch updated the current branch head.
fast-forwarding your working tree from
commit 2b6c8eb9a0816539471b8ac1403e601d18d1b011.
error: Your local changes to the following files would be overwritten by merge:
	scripts/logs/2022-07-07.err
	scripts/logs/2022-07-07.log
Please commit your changes or stash them before you merge.
Aborting
fatal: Cannot fast-forward your working tree.
After making sure that you saved anything precious from
$ git diff 2b6c8eb9a0816539471b8ac1403e601d18d1b011
output, run
$ git reset --hard
to recover.

github pull in /data/www/twoptwo.com
To github.com:loqueelvientoajuarez/obslog.git
   2b6c8eb..a0b8050  master -> master


git add * in /data/www/twoptwo.com
git commit

executing periodlog.py in /home/lachaume/git/autolog/scripts
Everything up-to-date

Traceback (most recent call last):
  File "/usr/lib/python3/dist-packages/urllib3/connection.py", line 169, in _new_conn
    conn = connection.create_connection(
  File "/usr/lib/python3/dist-packages/urllib3/util/connection.py", line 73, in create_connection
    for res in socket.getaddrinfo(host, port, family, socket.SOCK_STREAM):
  File "/usr/lib/python3.10/socket.py", line 955, in getaddrinfo
    for res in _socket.getaddrinfo(host, port, family, type, proto, flags):
socket.gaierror: [Errno -3] Temporary failure in name resolution

During handling of the above exception, another exception occurred:

Traceback (most recent call last):
  File "/usr/lib/python3/dist-packages/urllib3/connectionpool.py", line 699, in urlopen
    httplib_response = self._make_request(
  File "/usr/lib/python3/dist-packages/urllib3/connectionpool.py", line 394, in _make_request
    conn.request(method, url, **httplib_request_kw)
  File "/usr/lib/python3/dist-packages/urllib3/connection.py", line 234, in request
    super(HTTPConnection, self).request(method, url, body=body, headers=headers)
  File "/usr/lib/python3.10/http/client.py", line 1282, in request
    self._send_request(method, url, body, headers, encode_chunked)
  File "/usr/lib/python3.10/http/client.py", line 1328, in _send_request
    self.endheaders(body, encode_chunked=encode_chunked)
  File "/usr/lib/python3.10/http/client.py", line 1277, in endheaders
    self._send_output(message_body, encode_chunked=encode_chunked)
  File "/usr/lib/python3.10/http/client.py", line 1037, in _send_output
    self.send(msg)
  File "/usr/lib/python3.10/http/client.py", line 975, in send
    self.connect()
  File "/usr/lib/python3/dist-packages/urllib3/connection.py", line 200, in connect
    conn = self._new_conn()
  File "/usr/lib/python3/dist-packages/urllib3/connection.py", line 181, in _new_conn
    raise NewConnectionError(
urllib3.exceptions.NewConnectionError: <urllib3.connection.HTTPConnection object at 0x7f7598934700>: Failed to establish a new connection: [Errno -3] Temporary failure in name resolution

During handling of the above exception, another exception occurred:

Traceback (most recent call last):
  File "/usr/lib/python3/dist-packages/requests/adapters.py", line 439, in send
    resp = conn.urlopen(
  File "/usr/lib/python3/dist-packages/urllib3/connectionpool.py", line 755, in urlopen
    retries = retries.increment(
  File "/usr/lib/python3/dist-packages/urllib3/util/retry.py", line 574, in increment
    raise MaxRetryError(_pool, url, error or ResponseError(cause))
urllib3.exceptions.MaxRetryError: HTTPConnectionPool(host='archive.eso.org', port=80): Max retries exceeded with url: /tap_obs/sync (Caused by NewConnectionError('<urllib3.connection.HTTPConnection object at 0x7f7598934700>: Failed to establish a new connection: [Errno -3] Temporary failure in name resolution'))

During handling of the above exception, another exception occurred:

Traceback (most recent call last):
  File "/usr/local/lib/python3.10/dist-packages/pyvo/dal/query.py", line 242, in execute_votable
    return votableparse(self.execute_stream(post=post).read)
  File "/usr/local/lib/python3.10/dist-packages/pyvo/dal/tap.py", line 926, in execute_stream
    return super().execute_stream(post=post)
  File "/usr/local/lib/python3.10/dist-packages/pyvo/utils/decorators.py", line 9, in wrapper
    raw = func(*args, **kwargs)
  File "/usr/local/lib/python3.10/dist-packages/pyvo/dal/query.py", line 191, in execute_stream
    response = self.submit(post=post)
  File "/usr/local/lib/python3.10/dist-packages/pyvo/dal/tap.py", line 959, in submit
    response = self._session.post(
  File "/usr/lib/python3/dist-packages/requests/sessions.py", line 590, in post
    return self.request('POST', url, data=data, json=json, **kwargs)
  File "/usr/lib/python3/dist-packages/requests/sessions.py", line 542, in request
    resp = self.send(prep, **send_kwargs)
  File "/usr/lib/python3/dist-packages/requests/sessions.py", line 655, in send
    r = adapter.send(request, **kwargs)
  File "/usr/lib/python3/dist-packages/requests/adapters.py", line 516, in send
    raise ConnectionError(e, request=request)
requests.exceptions.ConnectionError: HTTPConnectionPool(host='archive.eso.org', port=80): Max retries exceeded with url: /tap_obs/sync (Caused by NewConnectionError('<urllib3.connection.HTTPConnection object at 0x7f7598934700>: Failed to establish a new connection: [Errno -3] Temporary failure in name resolution'))

During handling of the above exception, another exception occurred:

Traceback (most recent call last):
  File "/home/lachaume/git/autolog/scripts/./periodlog.py", line 22, in <module>
    log = PeriodLog.fetch(telescope, period, **opts) 
  File "/home/lachaume/git/autolog/scripts/../autolog/eso/periodlog.py", line 56, in fetch
    logs = [NightLog.fetch(telescope, night, **opts)
  File "/home/lachaume/git/autolog/scripts/../autolog/eso/periodlog.py", line 56, in <listcomp>
    logs = [NightLog.fetch(telescope, night, **opts)
  File "/home/lachaume/git/autolog/scripts/../autolog/eso/nightlog.py", line 67, in fetch
    log = query.fetch(night=night, use_tap_cache=use_tap_cache)
  File "/home/lachaume/git/autolog/scripts/../autolog/eso/tapquery.py", line 115, in fetch
    tab = tap.execute().to_table()
  File "/usr/local/lib/python3.10/dist-packages/pyvo/dal/tap.py", line 942, in execute
    return TAPResults(self.execute_votable(), url=self.queryurl, session=self._session)
  File "/usr/local/lib/python3.10/dist-packages/pyvo/dal/query.py", line 245, in execute_votable
    raise DALFormatError(e, self.queryurl)
pyvo.dal.exceptions.DALFormatError: ConnectionError: HTTPConnectionPool(host='archive.eso.org', port=80): Max retries exceeded with url: /tap_obs/sync (Caused by NewConnectionError('<urllib3.connection.HTTPConnection object at 0x7f7598934700>: Failed to establish a new connection: [Errno -3] Temporary failure in name resolution'))

git add * in /home/lachaume/git/autolog
git commit
git push
To github.com:loqueelvientoajuarez/obslog.git
   a0b8050..79c77c5  master -> master


git add * in /data/www/twoptwo.com
git commit
Everything up-to-date


daily.sh at 2022-07-07T16:13:01-04:00
-------------------------------------

github pull in /home/lachaume/git/autolog

github pull in /data/www/twoptwo.com

daily.sh at 2022-07-07T16:14:01-04:00
-------------------------------------

github pull in /home/lachaume/git/autolog
ssh: Could not resolve hostname github.com: Temporary failure in name resolution
fatal: Could not read from remote repository.

Please make sure you have the correct access rights
and the repository exists.

github pull in /data/www/twoptwo.com

executing periodlog.py in /home/lachaume/git/autolog/scripts

daily.sh at 2022-07-07T16:15:01-04:00
-------------------------------------

github pull in /home/lachaume/git/autolog
ssh: Could not resolve hostname github.com: Temporary failure in name resolution
fatal: Could not read from remote repository.

Please make sure you have the correct access rights
and the repository exists.

github pull in /data/www/twoptwo.com
ssh: Could not resolve hostname github.com: Temporary failure in name resolution
fatal: Could not read from remote repository.

Please make sure you have the correct access rights
and the repository exists.

executing periodlog.py in /home/lachaume/git/autolog/scripts

daily.sh at 2022-07-07T16:16:01-04:00
-------------------------------------

github pull in /home/lachaume/git/autolog
Traceback (most recent call last):
  File "/usr/lib/python3/dist-packages/urllib3/connection.py", line 169, in _new_conn
    conn = connection.create_connection(
  File "/usr/lib/python3/dist-packages/urllib3/util/connection.py", line 73, in create_connection
    for res in socket.getaddrinfo(host, port, family, socket.SOCK_STREAM):
  File "/usr/lib/python3.10/socket.py", line 955, in getaddrinfo
    for res in _socket.getaddrinfo(host, port, family, type, proto, flags):
socket.gaierror: [Errno -3] Temporary failure in name resolution

During handling of the above exception, another exception occurred:

Traceback (most recent call last):
  File "/usr/lib/python3/dist-packages/urllib3/connectionpool.py", line 699, in urlopen
    httplib_response = self._make_request(
  File "/usr/lib/python3/dist-packages/urllib3/connectionpool.py", line 394, in _make_request
    conn.request(method, url, **httplib_request_kw)
  File "/usr/lib/python3/dist-packages/urllib3/connection.py", line 234, in request
    super(HTTPConnection, self).request(method, url, body=body, headers=headers)
  File "/usr/lib/python3.10/http/client.py", line 1282, in request
    self._send_request(method, url, body, headers, encode_chunked)
  File "/usr/lib/python3.10/http/client.py", line 1328, in _send_request
    self.endheaders(body, encode_chunked=encode_chunked)
  File "/usr/lib/python3.10/http/client.py", line 1277, in endheaders
    self._send_output(message_body, encode_chunked=encode_chunked)
  File "/usr/lib/python3.10/http/client.py", line 1037, in _send_output
    self.send(msg)
  File "/usr/lib/python3.10/http/client.py", line 975, in send
    self.connect()
  File "/usr/lib/python3/dist-packages/urllib3/connection.py", line 200, in connect
    conn = self._new_conn()
  File "/usr/lib/python3/dist-packages/urllib3/connection.py", line 181, in _new_conn
    raise NewConnectionError(
urllib3.exceptions.NewConnectionError: <urllib3.connection.HTTPConnection object at 0x7f2e3d98bfa0>: Failed to establish a new connection: [Errno -3] Temporary failure in name resolution

During handling of the above exception, another exception occurred:

Traceback (most recent call last):
  File "/usr/lib/python3/dist-packages/requests/adapters.py", line 439, in send
    resp = conn.urlopen(
  File "/usr/lib/python3/dist-packages/urllib3/connectionpool.py", line 755, in urlopen
    retries = retries.increment(
  File "/usr/lib/python3/dist-packages/urllib3/util/retry.py", line 574, in increment
    raise MaxRetryError(_pool, url, error or ResponseError(cause))
urllib3.exceptions.MaxRetryError: HTTPConnectionPool(host='archive.eso.org', port=80): Max retries exceeded with url: /tap_obs/sync (Caused by NewConnectionError('<urllib3.connection.HTTPConnection object at 0x7f2e3d98bfa0>: Failed to establish a new connection: [Errno -3] Temporary failure in name resolution'))

During handling of the above exception, another exception occurred:

Traceback (most recent call last):
  File "/usr/local/lib/python3.10/dist-packages/pyvo/dal/query.py", line 242, in execute_votable
    return votableparse(self.execute_stream(post=post).read)
  File "/usr/local/lib/python3.10/dist-packages/pyvo/dal/tap.py", line 926, in execute_stream
    return super().execute_stream(post=post)
  File "/usr/local/lib/python3.10/dist-packages/pyvo/utils/decorators.py", line 9, in wrapper
    raw = func(*args, **kwargs)
  File "/usr/local/lib/python3.10/dist-packages/pyvo/dal/query.py", line 191, in execute_stream
    response = self.submit(post=post)
  File "/usr/local/lib/python3.10/dist-packages/pyvo/dal/tap.py", line 959, in submit
    response = self._session.post(
  File "/usr/lib/python3/dist-packages/requests/sessions.py", line 590, in post
    return self.request('POST', url, data=data, json=json, **kwargs)
  File "/usr/lib/python3/dist-packages/requests/sessions.py", line 542, in request
    resp = self.send(prep, **send_kwargs)
  File "/usr/lib/python3/dist-packages/requests/sessions.py", line 655, in send
    r = adapter.send(request, **kwargs)
  File "/usr/lib/python3/dist-packages/requests/adapters.py", line 516, in send
    raise ConnectionError(e, request=request)
requests.exceptions.ConnectionError: HTTPConnectionPool(host='archive.eso.org', port=80): Max retries exceeded with url: /tap_obs/sync (Caused by NewConnectionError('<urllib3.connection.HTTPConnection object at 0x7f2e3d98bfa0>: Failed to establish a new connection: [Errno -3] Temporary failure in name resolution'))

During handling of the above exception, another exception occurred:

Traceback (most recent call last):
  File "/home/lachaume/git/autolog/scripts/./periodlog.py", line 22, in <module>
    log = PeriodLog.fetch(telescope, period, **opts) 
  File "/home/lachaume/git/autolog/scripts/../autolog/eso/periodlog.py", line 56, in fetch
    logs = [NightLog.fetch(telescope, night, **opts)
  File "/home/lachaume/git/autolog/scripts/../autolog/eso/periodlog.py", line 56, in <listcomp>
    logs = [NightLog.fetch(telescope, night, **opts)
  File "/home/lachaume/git/autolog/scripts/../autolog/eso/nightlog.py", line 67, in fetch
    log = query.fetch(night=night, use_tap_cache=use_tap_cache)
  File "/home/lachaume/git/autolog/scripts/../autolog/eso/tapquery.py", line 115, in fetch
    tab = tap.execute().to_table()
  File "/usr/local/lib/python3.10/dist-packages/pyvo/dal/tap.py", line 942, in execute
    return TAPResults(self.execute_votable(), url=self.queryurl, session=self._session)
  File "/usr/local/lib/python3.10/dist-packages/pyvo/dal/query.py", line 245, in execute_votable
    raise DALFormatError(e, self.queryurl)
pyvo.dal.exceptions.DALFormatError: ConnectionError: HTTPConnectionPool(host='archive.eso.org', port=80): Max retries exceeded with url: /tap_obs/sync (Caused by NewConnectionError('<urllib3.connection.HTTPConnection object at 0x7f2e3d98bfa0>: Failed to establish a new connection: [Errno -3] Temporary failure in name resolution'))

git add * in /home/lachaume/git/autolog
git commit
git push
warning: fetch updated the current branch head.
fast-forwarding your working tree from
commit 79c77c58c64cf97d2f18580cde97df40c5967708.
error: Your local changes to the following files would be overwritten by merge:
	scripts/logs/2022-07-07.err
	scripts/logs/2022-07-07.log
Please commit your changes or stash them before you merge.
Aborting
fatal: Cannot fast-forward your working tree.
After making sure that you saved anything precious from
$ git diff 79c77c58c64cf97d2f18580cde97df40c5967708
output, run
$ git reset --hard
to recover.

github pull in /data/www/twoptwo.com
To github.com:loqueelvientoajuarez/obslog.git
   79c77c5..c714e31  master -> master


executing periodlog.py in /home/lachaume/git/autolog/scripts

git add * in /data/www/twoptwo.com
git commit
Everything up-to-date

Traceback (most recent call last):
  File "/usr/lib/python3/dist-packages/urllib3/connection.py", line 169, in _new_conn
    conn = connection.create_connection(
  File "/usr/lib/python3/dist-packages/urllib3/util/connection.py", line 73, in create_connection
    for res in socket.getaddrinfo(host, port, family, socket.SOCK_STREAM):
  File "/usr/lib/python3.10/socket.py", line 955, in getaddrinfo
    for res in _socket.getaddrinfo(host, port, family, type, proto, flags):
socket.gaierror: [Errno -3] Temporary failure in name resolution

During handling of the above exception, another exception occurred:

Traceback (most recent call last):
  File "/usr/lib/python3/dist-packages/urllib3/connectionpool.py", line 699, in urlopen
    httplib_response = self._make_request(
  File "/usr/lib/python3/dist-packages/urllib3/connectionpool.py", line 394, in _make_request
    conn.request(method, url, **httplib_request_kw)
  File "/usr/lib/python3/dist-packages/urllib3/connection.py", line 234, in request
    super(HTTPConnection, self).request(method, url, body=body, headers=headers)
  File "/usr/lib/python3.10/http/client.py", line 1282, in request
    self._send_request(method, url, body, headers, encode_chunked)
  File "/usr/lib/python3.10/http/client.py", line 1328, in _send_request
    self.endheaders(body, encode_chunked=encode_chunked)
  File "/usr/lib/python3.10/http/client.py", line 1277, in endheaders
    self._send_output(message_body, encode_chunked=encode_chunked)
  File "/usr/lib/python3.10/http/client.py", line 1037, in _send_output
    self.send(msg)
  File "/usr/lib/python3.10/http/client.py", line 975, in send
    self.connect()
  File "/usr/lib/python3/dist-packages/urllib3/connection.py", line 200, in connect
    conn = self._new_conn()
  File "/usr/lib/python3/dist-packages/urllib3/connection.py", line 181, in _new_conn
    raise NewConnectionError(
urllib3.exceptions.NewConnectionError: <urllib3.connection.HTTPConnection object at 0x7ff06fb58910>: Failed to establish a new connection: [Errno -3] Temporary failure in name resolution

During handling of the above exception, another exception occurred:

Traceback (most recent call last):
  File "/usr/lib/python3/dist-packages/requests/adapters.py", line 439, in send
    resp = conn.urlopen(
  File "/usr/lib/python3/dist-packages/urllib3/connectionpool.py", line 755, in urlopen
    retries = retries.increment(
  File "/usr/lib/python3/dist-packages/urllib3/util/retry.py", line 574, in increment
    raise MaxRetryError(_pool, url, error or ResponseError(cause))
urllib3.exceptions.MaxRetryError: HTTPConnectionPool(host='archive.eso.org', port=80): Max retries exceeded with url: /tap_obs/sync (Caused by NewConnectionError('<urllib3.connection.HTTPConnection object at 0x7ff06fb58910>: Failed to establish a new connection: [Errno -3] Temporary failure in name resolution'))

During handling of the above exception, another exception occurred:

Traceback (most recent call last):
  File "/usr/local/lib/python3.10/dist-packages/pyvo/dal/query.py", line 242, in execute_votable
    return votableparse(self.execute_stream(post=post).read)
  File "/usr/local/lib/python3.10/dist-packages/pyvo/dal/tap.py", line 926, in execute_stream
    return super().execute_stream(post=post)
  File "/usr/local/lib/python3.10/dist-packages/pyvo/utils/decorators.py", line 9, in wrapper
    raw = func(*args, **kwargs)
  File "/usr/local/lib/python3.10/dist-packages/pyvo/dal/query.py", line 191, in execute_stream
    response = self.submit(post=post)
  File "/usr/local/lib/python3.10/dist-packages/pyvo/dal/tap.py", line 959, in submit
    response = self._session.post(
  File "/usr/lib/python3/dist-packages/requests/sessions.py", line 590, in post
    return self.request('POST', url, data=data, json=json, **kwargs)
  File "/usr/lib/python3/dist-packages/requests/sessions.py", line 542, in request
    resp = self.send(prep, **send_kwargs)
  File "/usr/lib/python3/dist-packages/requests/sessions.py", line 655, in send
    r = adapter.send(request, **kwargs)
  File "/usr/lib/python3/dist-packages/requests/adapters.py", line 516, in send
    raise ConnectionError(e, request=request)
requests.exceptions.ConnectionError: HTTPConnectionPool(host='archive.eso.org', port=80): Max retries exceeded with url: /tap_obs/sync (Caused by NewConnectionError('<urllib3.connection.HTTPConnection object at 0x7ff06fb58910>: Failed to establish a new connection: [Errno -3] Temporary failure in name resolution'))

During handling of the above exception, another exception occurred:

Traceback (most recent call last):
  File "/home/lachaume/git/autolog/scripts/./periodlog.py", line 22, in <module>
    log = PeriodLog.fetch(telescope, period, **opts) 
  File "/home/lachaume/git/autolog/scripts/../autolog/eso/periodlog.py", line 56, in fetch
    logs = [NightLog.fetch(telescope, night, **opts)
  File "/home/lachaume/git/autolog/scripts/../autolog/eso/periodlog.py", line 56, in <listcomp>
    logs = [NightLog.fetch(telescope, night, **opts)
  File "/home/lachaume/git/autolog/scripts/../autolog/eso/nightlog.py", line 67, in fetch
    log = query.fetch(night=night, use_tap_cache=use_tap_cache)
  File "/home/lachaume/git/autolog/scripts/../autolog/eso/tapquery.py", line 115, in fetch
    tab = tap.execute().to_table()
  File "/usr/local/lib/python3.10/dist-packages/pyvo/dal/tap.py", line 942, in execute
    return TAPResults(self.execute_votable(), url=self.queryurl, session=self._session)
  File "/usr/local/lib/python3.10/dist-packages/pyvo/dal/query.py", line 245, in execute_votable
    raise DALFormatError(e, self.queryurl)
pyvo.dal.exceptions.DALFormatError: ConnectionError: HTTPConnectionPool(host='archive.eso.org', port=80): Max retries exceeded with url: /tap_obs/sync (Caused by NewConnectionError('<urllib3.connection.HTTPConnection object at 0x7ff06fb58910>: Failed to establish a new connection: [Errno -3] Temporary failure in name resolution'))

git add * in /home/lachaume/git/autolog
git commit
git push

daily.sh at 2022-07-07T16:17:01-04:00
-------------------------------------

github pull in /home/lachaume/git/autolog
ssh: Could not resolve hostname github.com: Temporary failure in name resolution
fatal: Could not read from remote repository.

Please make sure you have the correct access rights
and the repository exists.

ssh: Could not resolve hostname github.com: Temporary failure in name resolution
fatal: Could not read from remote repository.

Please make sure you have the correct access rights
and the repository exists.

github pull in /data/www/twoptwo.com

git add * in /data/www/twoptwo.com
git commit
ssh: Could not resolve hostname github.com: Temporary failure in name resolution
fatal: Could not read from remote repository.

Please make sure you have the correct access rights
and the repository exists.

executing periodlog.py in /home/lachaume/git/autolog/scripts
ssh: Could not resolve hostname github.com: Temporary failure in name resolution
fatal: Could not read from remote repository.

Please make sure you have the correct access rights
and the repository exists.


daily.sh at 2022-07-07T16:18:01-04:00
-------------------------------------

github pull in /home/lachaume/git/autolog
Traceback (most recent call last):
  File "/usr/lib/python3/dist-packages/urllib3/connection.py", line 169, in _new_conn
    conn = connection.create_connection(
  File "/usr/lib/python3/dist-packages/urllib3/util/connection.py", line 73, in create_connection
    for res in socket.getaddrinfo(host, port, family, socket.SOCK_STREAM):
  File "/usr/lib/python3.10/socket.py", line 955, in getaddrinfo
    for res in _socket.getaddrinfo(host, port, family, type, proto, flags):
socket.gaierror: [Errno -3] Temporary failure in name resolution

During handling of the above exception, another exception occurred:

Traceback (most recent call last):
  File "/usr/lib/python3/dist-packages/urllib3/connectionpool.py", line 699, in urlopen
    httplib_response = self._make_request(
  File "/usr/lib/python3/dist-packages/urllib3/connectionpool.py", line 394, in _make_request
    conn.request(method, url, **httplib_request_kw)
  File "/usr/lib/python3/dist-packages/urllib3/connection.py", line 234, in request
    super(HTTPConnection, self).request(method, url, body=body, headers=headers)
  File "/usr/lib/python3.10/http/client.py", line 1282, in request
    self._send_request(method, url, body, headers, encode_chunked)
  File "/usr/lib/python3.10/http/client.py", line 1328, in _send_request
    self.endheaders(body, encode_chunked=encode_chunked)
  File "/usr/lib/python3.10/http/client.py", line 1277, in endheaders
    self._send_output(message_body, encode_chunked=encode_chunked)
  File "/usr/lib/python3.10/http/client.py", line 1037, in _send_output
    self.send(msg)
  File "/usr/lib/python3.10/http/client.py", line 975, in send
    self.connect()
  File "/usr/lib/python3/dist-packages/urllib3/connection.py", line 200, in connect
    conn = self._new_conn()
  File "/usr/lib/python3/dist-packages/urllib3/connection.py", line 181, in _new_conn
    raise NewConnectionError(
urllib3.exceptions.NewConnectionError: <urllib3.connection.HTTPConnection object at 0x7fe2ae4fe9b0>: Failed to establish a new connection: [Errno -3] Temporary failure in name resolution

During handling of the above exception, another exception occurred:

Traceback (most recent call last):
  File "/usr/lib/python3/dist-packages/requests/adapters.py", line 439, in send
    resp = conn.urlopen(
  File "/usr/lib/python3/dist-packages/urllib3/connectionpool.py", line 755, in urlopen
    retries = retries.increment(
  File "/usr/lib/python3/dist-packages/urllib3/util/retry.py", line 574, in increment
    raise MaxRetryError(_pool, url, error or ResponseError(cause))
urllib3.exceptions.MaxRetryError: HTTPConnectionPool(host='archive.eso.org', port=80): Max retries exceeded with url: /tap_obs/sync (Caused by NewConnectionError('<urllib3.connection.HTTPConnection object at 0x7fe2ae4fe9b0>: Failed to establish a new connection: [Errno -3] Temporary failure in name resolution'))

During handling of the above exception, another exception occurred:

Traceback (most recent call last):
  File "/usr/local/lib/python3.10/dist-packages/pyvo/dal/query.py", line 242, in execute_votable
    return votableparse(self.execute_stream(post=post).read)
  File "/usr/local/lib/python3.10/dist-packages/pyvo/dal/tap.py", line 926, in execute_stream
    return super().execute_stream(post=post)
  File "/usr/local/lib/python3.10/dist-packages/pyvo/utils/decorators.py", line 9, in wrapper
    raw = func(*args, **kwargs)
  File "/usr/local/lib/python3.10/dist-packages/pyvo/dal/query.py", line 191, in execute_stream
    response = self.submit(post=post)
  File "/usr/local/lib/python3.10/dist-packages/pyvo/dal/tap.py", line 959, in submit
    response = self._session.post(
  File "/usr/lib/python3/dist-packages/requests/sessions.py", line 590, in post
    return self.request('POST', url, data=data, json=json, **kwargs)
  File "/usr/lib/python3/dist-packages/requests/sessions.py", line 542, in request
    resp = self.send(prep, **send_kwargs)
  File "/usr/lib/python3/dist-packages/requests/sessions.py", line 655, in send
    r = adapter.send(request, **kwargs)
  File "/usr/lib/python3/dist-packages/requests/adapters.py", line 516, in send
    raise ConnectionError(e, request=request)
requests.exceptions.ConnectionError: HTTPConnectionPool(host='archive.eso.org', port=80): Max retries exceeded with url: /tap_obs/sync (Caused by NewConnectionError('<urllib3.connection.HTTPConnection object at 0x7fe2ae4fe9b0>: Failed to establish a new connection: [Errno -3] Temporary failure in name resolution'))

During handling of the above exception, another exception occurred:

Traceback (most recent call last):
  File "/home/lachaume/git/autolog/scripts/./periodlog.py", line 22, in <module>
    log = PeriodLog.fetch(telescope, period, **opts) 
  File "/home/lachaume/git/autolog/scripts/../autolog/eso/periodlog.py", line 56, in fetch
    logs = [NightLog.fetch(telescope, night, **opts)
  File "/home/lachaume/git/autolog/scripts/../autolog/eso/periodlog.py", line 56, in <listcomp>
    logs = [NightLog.fetch(telescope, night, **opts)
  File "/home/lachaume/git/autolog/scripts/../autolog/eso/nightlog.py", line 67, in fetch
    log = query.fetch(night=night, use_tap_cache=use_tap_cache)
  File "/home/lachaume/git/autolog/scripts/../autolog/eso/tapquery.py", line 115, in fetch
    tab = tap.execute().to_table()
  File "/usr/local/lib/python3.10/dist-packages/pyvo/dal/tap.py", line 942, in execute
    return TAPResults(self.execute_votable(), url=self.queryurl, session=self._session)
  File "/usr/local/lib/python3.10/dist-packages/pyvo/dal/query.py", line 245, in execute_votable
    raise DALFormatError(e, self.queryurl)
pyvo.dal.exceptions.DALFormatError: ConnectionError: HTTPConnectionPool(host='archive.eso.org', port=80): Max retries exceeded with url: /tap_obs/sync (Caused by NewConnectionError('<urllib3.connection.HTTPConnection object at 0x7fe2ae4fe9b0>: Failed to establish a new connection: [Errno -3] Temporary failure in name resolution'))

git add * in /home/lachaume/git/autolog
git commit
git push
warning: fetch updated the current branch head.
fast-forwarding your working tree from
commit d3e3ea0756e4180dcd38076f8c5956a4439bc11a.
error: Your local changes to the following files would be overwritten by merge:
	scripts/logs/2022-07-07.err
	scripts/logs/2022-07-07.log
Please commit your changes or stash them before you merge.
Aborting
fatal: Cannot fast-forward your working tree.
After making sure that you saved anything precious from
$ git diff d3e3ea0756e4180dcd38076f8c5956a4439bc11a
output, run
$ git reset --hard
to recover.

github pull in /data/www/twoptwo.com
To github.com:loqueelvientoajuarez/obslog.git
   c714e31..e6e4fa1  master -> master


executing periodlog.py in /home/lachaume/git/autolog/scripts
Traceback (most recent call last):
  File "/usr/lib/python3/dist-packages/urllib3/connection.py", line 169, in _new_conn
    conn = connection.create_connection(
  File "/usr/lib/python3/dist-packages/urllib3/util/connection.py", line 73, in create_connection
    for res in socket.getaddrinfo(host, port, family, socket.SOCK_STREAM):
  File "/usr/lib/python3.10/socket.py", line 955, in getaddrinfo
    for res in _socket.getaddrinfo(host, port, family, type, proto, flags):
socket.gaierror: [Errno -3] Temporary failure in name resolution

During handling of the above exception, another exception occurred:

Traceback (most recent call last):
  File "/usr/lib/python3/dist-packages/urllib3/connectionpool.py", line 699, in urlopen
    httplib_response = self._make_request(
  File "/usr/lib/python3/dist-packages/urllib3/connectionpool.py", line 394, in _make_request
    conn.request(method, url, **httplib_request_kw)
  File "/usr/lib/python3/dist-packages/urllib3/connection.py", line 234, in request
    super(HTTPConnection, self).request(method, url, body=body, headers=headers)
  File "/usr/lib/python3.10/http/client.py", line 1282, in request
    self._send_request(method, url, body, headers, encode_chunked)
  File "/usr/lib/python3.10/http/client.py", line 1328, in _send_request
    self.endheaders(body, encode_chunked=encode_chunked)
  File "/usr/lib/python3.10/http/client.py", line 1277, in endheaders
    self._send_output(message_body, encode_chunked=encode_chunked)
  File "/usr/lib/python3.10/http/client.py", line 1037, in _send_output
    self.send(msg)
  File "/usr/lib/python3.10/http/client.py", line 975, in send
    self.connect()
  File "/usr/lib/python3/dist-packages/urllib3/connection.py", line 200, in connect
    conn = self._new_conn()
  File "/usr/lib/python3/dist-packages/urllib3/connection.py", line 181, in _new_conn
    raise NewConnectionError(
urllib3.exceptions.NewConnectionError: <urllib3.connection.HTTPConnection object at 0x7f1fb99e83d0>: Failed to establish a new connection: [Errno -3] Temporary failure in name resolution

During handling of the above exception, another exception occurred:

Traceback (most recent call last):
  File "/usr/lib/python3/dist-packages/requests/adapters.py", line 439, in send
    resp = conn.urlopen(
  File "/usr/lib/python3/dist-packages/urllib3/connectionpool.py", line 755, in urlopen
    retries = retries.increment(
  File "/usr/lib/python3/dist-packages/urllib3/util/retry.py", line 574, in increment
    raise MaxRetryError(_pool, url, error or ResponseError(cause))
urllib3.exceptions.MaxRetryError: HTTPConnectionPool(host='archive.eso.org', port=80): Max retries exceeded with url: /tap_obs/sync (Caused by NewConnectionError('<urllib3.connection.HTTPConnection object at 0x7f1fb99e83d0>: Failed to establish a new connection: [Errno -3] Temporary failure in name resolution'))

During handling of the above exception, another exception occurred:

Traceback (most recent call last):
  File "/usr/local/lib/python3.10/dist-packages/pyvo/dal/query.py", line 242, in execute_votable
    return votableparse(self.execute_stream(post=post).read)
  File "/usr/local/lib/python3.10/dist-packages/pyvo/dal/tap.py", line 926, in execute_stream
    return super().execute_stream(post=post)
  File "/usr/local/lib/python3.10/dist-packages/pyvo/utils/decorators.py", line 9, in wrapper
    raw = func(*args, **kwargs)
  File "/usr/local/lib/python3.10/dist-packages/pyvo/dal/query.py", line 191, in execute_stream
    response = self.submit(post=post)
  File "/usr/local/lib/python3.10/dist-packages/pyvo/dal/tap.py", line 959, in submit
    response = self._session.post(
  File "/usr/lib/python3/dist-packages/requests/sessions.py", line 590, in post
    return self.request('POST', url, data=data, json=json, **kwargs)
  File "/usr/lib/python3/dist-packages/requests/sessions.py", line 542, in request
    resp = self.send(prep, **send_kwargs)
  File "/usr/lib/python3/dist-packages/requests/sessions.py", line 655, in send
    r = adapter.send(request, **kwargs)
  File "/usr/lib/python3/dist-packages/requests/adapters.py", line 516, in send
    raise ConnectionError(e, request=request)
requests.exceptions.ConnectionError: HTTPConnectionPool(host='archive.eso.org', port=80): Max retries exceeded with url: /tap_obs/sync (Caused by NewConnectionError('<urllib3.connection.HTTPConnection object at 0x7f1fb99e83d0>: Failed to establish a new connection: [Errno -3] Temporary failure in name resolution'))

During handling of the above exception, another exception occurred:

Traceback (most recent call last):
  File "/home/lachaume/git/autolog/scripts/./periodlog.py", line 22, in <module>
    log = PeriodLog.fetch(telescope, period, **opts) 
  File "/home/lachaume/git/autolog/scripts/../autolog/eso/periodlog.py", line 56, in fetch
    logs = [NightLog.fetch(telescope, night, **opts)
  File "/home/lachaume/git/autolog/scripts/../autolog/eso/periodlog.py", line 56, in <listcomp>
    logs = [NightLog.fetch(telescope, night, **opts)
  File "/home/lachaume/git/autolog/scripts/../autolog/eso/nightlog.py", line 67, in fetch
    log = query.fetch(night=night, use_tap_cache=use_tap_cache)
  File "/home/lachaume/git/autolog/scripts/../autolog/eso/tapquery.py", line 115, in fetch
    tab = tap.execute().to_table()
  File "/usr/local/lib/python3.10/dist-packages/pyvo/dal/tap.py", line 942, in execute
    return TAPResults(self.execute_votable(), url=self.queryurl, session=self._session)
  File "/usr/local/lib/python3.10/dist-packages/pyvo/dal/query.py", line 245, in execute_votable
    raise DALFormatError(e, self.queryurl)
pyvo.dal.exceptions.DALFormatError: ConnectionError: HTTPConnectionPool(host='archive.eso.org', port=80): Max retries exceeded with url: /tap_obs/sync (Caused by NewConnectionError('<urllib3.connection.HTTPConnection object at 0x7f1fb99e83d0>: Failed to establish a new connection: [Errno -3] Temporary failure in name resolution'))

git add * in /home/lachaume/git/autolog
git commit
git push
ssh: Could not resolve hostname github.com: Temporary failure in name resolution
fatal: Could not read from remote repository.

Please make sure you have the correct access rights
and the repository exists.


daily.sh at 2022-07-07T16:19:01-04:00
-------------------------------------

github pull in /home/lachaume/git/autolog

git add * in /data/www/twoptwo.com
git commit
ssh: Could not resolve hostname github.com: Temporary failure in name resolution
fatal: Could not read from remote repository.

Please make sure you have the correct access rights
and the repository exists.

github pull in /data/www/twoptwo.com
ssh: Could not resolve hostname github.com: Temporary failure in name resolution
fatal: Could not read from remote repository.

Please make sure you have the correct access rights
and the repository exists.

ssh_dispatch_run_fatal: Connection to 20.201.28.151 port 22: Connection timed out
ssh_dispatch_run_fatal: Connection to 20.201.28.151 port 22: Connection timed out
fatal: Could not read from remote repository.

Please make sure you have the correct access rights
and the repository exists.
fatal: Could not read from remote repository.

Please make sure you have the correct access rights
and the repository exists.


github pull in /data/www/twoptwo.com
ssh: Could not resolve hostname github.com: Temporary failure in name resolution
fatal: Could not read from remote repository.

Please make sure you have the correct access rights
and the repository exists.

executing periodlog.py in /home/lachaume/git/autolog/scripts
ssh: Could not resolve hostname github.com: Temporary failure in name resolution
fatal: Could not read from remote repository.

Please make sure you have the correct access rights
and the repository exists.

git add * in /data/www/twoptwo.com

executing periodlog.py in /home/lachaume/git/autolog/scripts
git commit

git add * in /data/www/twoptwo.com
git commit
Everything up-to-date

Everything up-to-date


daily.sh at 2022-07-07T16:20:01-04:00
-------------------------------------

github pull in /home/lachaume/git/autolog
ssh: Could not resolve hostname github.com: Temporary failure in name resolution
fatal: Could not read from remote repository.

Please make sure you have the correct access rights
and the repository exists.

github pull in /data/www/twoptwo.com
Traceback (most recent call last):
  File "/usr/lib/python3/dist-packages/urllib3/connection.py", line 169, in _new_conn
    conn = connection.create_connection(
  File "/usr/lib/python3/dist-packages/urllib3/util/connection.py", line 73, in create_connection
    for res in socket.getaddrinfo(host, port, family, socket.SOCK_STREAM):
  File "/usr/lib/python3.10/socket.py", line 955, in getaddrinfo
    for res in _socket.getaddrinfo(host, port, family, type, proto, flags):
socket.gaierror: [Errno -3] Temporary failure in name resolution

During handling of the above exception, another exception occurred:

Traceback (most recent call last):
  File "/usr/lib/python3/dist-packages/urllib3/connectionpool.py", line 699, in urlopen
    httplib_response = self._make_request(
  File "/usr/lib/python3/dist-packages/urllib3/connectionpool.py", line 394, in _make_request
    conn.request(method, url, **httplib_request_kw)
  File "/usr/lib/python3/dist-packages/urllib3/connection.py", line 234, in request
    super(HTTPConnection, self).request(method, url, body=body, headers=headers)
  File "/usr/lib/python3.10/http/client.py", line 1282, in request
    self._send_request(method, url, body, headers, encode_chunked)
  File "/usr/lib/python3.10/http/client.py", line 1328, in _send_request
    self.endheaders(body, encode_chunked=encode_chunked)
  File "/usr/lib/python3.10/http/client.py", line 1277, in endheaders
    self._send_output(message_body, encode_chunked=encode_chunked)
  File "/usr/lib/python3.10/http/client.py", line 1037, in _send_output
    self.send(msg)
  File "/usr/lib/python3.10/http/client.py", line 975, in send
    self.connect()
  File "/usr/lib/python3/dist-packages/urllib3/connection.py", line 200, in connect
    conn = self._new_conn()
  File "/usr/lib/python3/dist-packages/urllib3/connection.py", line 181, in _new_conn
    raise NewConnectionError(
urllib3.exceptions.NewConnectionError: <urllib3.connection.HTTPConnection object at 0x7fd55a168970>: Failed to establish a new connection: [Errno -3] Temporary failure in name resolution

During handling of the above exception, another exception occurred:

Traceback (most recent call last):
  File "/usr/lib/python3/dist-packages/requests/adapters.py", line 439, in send
    resp = conn.urlopen(
  File "/usr/lib/python3/dist-packages/urllib3/connectionpool.py", line 755, in urlopen
    retries = retries.increment(
  File "/usr/lib/python3/dist-packages/urllib3/util/retry.py", line 574, in increment
    raise MaxRetryError(_pool, url, error or ResponseError(cause))
urllib3.exceptions.MaxRetryError: HTTPConnectionPool(host='archive.eso.org', port=80): Max retries exceeded with url: /tap_obs/sync (Caused by NewConnectionError('<urllib3.connection.HTTPConnection object at 0x7fd55a168970>: Failed to establish a new connection: [Errno -3] Temporary failure in name resolution'))

During handling of the above exception, another exception occurred:

Traceback (most recent call last):
  File "/usr/local/lib/python3.10/dist-packages/pyvo/dal/query.py", line 242, in execute_votable
    return votableparse(self.execute_stream(post=post).read)
  File "/usr/local/lib/python3.10/dist-packages/pyvo/dal/tap.py", line 926, in execute_stream
    return super().execute_stream(post=post)
  File "/usr/local/lib/python3.10/dist-packages/pyvo/utils/decorators.py", line 9, in wrapper
    raw = func(*args, **kwargs)
  File "/usr/local/lib/python3.10/dist-packages/pyvo/dal/query.py", line 191, in execute_stream
    response = self.submit(post=post)
  File "/usr/local/lib/python3.10/dist-packages/pyvo/dal/tap.py", line 959, in submit
    response = self._session.post(
  File "/usr/lib/python3/dist-packages/requests/sessions.py", line 590, in post
    return self.request('POST', url, data=data, json=json, **kwargs)
  File "/usr/lib/python3/dist-packages/requests/sessions.py", line 542, in request
    resp = self.send(prep, **send_kwargs)
  File "/usr/lib/python3/dist-packages/requests/sessions.py", line 655, in send
    r = adapter.send(request, **kwargs)
  File "/usr/lib/python3/dist-packages/requests/adapters.py", line 516, in send
    raise ConnectionError(e, request=request)
requests.exceptions.ConnectionError: HTTPConnectionPool(host='archive.eso.org', port=80): Max retries exceeded with url: /tap_obs/sync (Caused by NewConnectionError('<urllib3.connection.HTTPConnection object at 0x7fd55a168970>: Failed to establish a new connection: [Errno -3] Temporary failure in name resolution'))

During handling of the above exception, another exception occurred:

Traceback (most recent call last):
  File "/home/lachaume/git/autolog/scripts/./periodlog.py", line 22, in <module>
    log = PeriodLog.fetch(telescope, period, **opts) 
  File "/home/lachaume/git/autolog/scripts/../autolog/eso/periodlog.py", line 56, in fetch
    logs = [NightLog.fetch(telescope, night, **opts)
  File "/home/lachaume/git/autolog/scripts/../autolog/eso/periodlog.py", line 56, in <listcomp>
    logs = [NightLog.fetch(telescope, night, **opts)
  File "/home/lachaume/git/autolog/scripts/../autolog/eso/nightlog.py", line 67, in fetch
    log = query.fetch(night=night, use_tap_cache=use_tap_cache)
  File "/home/lachaume/git/autolog/scripts/../autolog/eso/tapquery.py", line 115, in fetch
    tab = tap.execute().to_table()
  File "/usr/local/lib/python3.10/dist-packages/pyvo/dal/tap.py", line 942, in execute
    return TAPResults(self.execute_votable(), url=self.queryurl, session=self._session)
  File "/usr/local/lib/python3.10/dist-packages/pyvo/dal/query.py", line 245, in execute_votable
    raise DALFormatError(e, self.queryurl)
pyvo.dal.exceptions.DALFormatError: ConnectionError: HTTPConnectionPool(host='archive.eso.org', port=80): Max retries exceeded with url: /tap_obs/sync (Caused by NewConnectionError('<urllib3.connection.HTTPConnection object at 0x7fd55a168970>: Failed to establish a new connection: [Errno -3] Temporary failure in name resolution'))

git add * in /home/lachaume/git/autolog
git commit
git push
Traceback (most recent call last):
  File "/usr/lib/python3/dist-packages/urllib3/connection.py", line 169, in _new_conn
    conn = connection.create_connection(
  File "/usr/lib/python3/dist-packages/urllib3/util/connection.py", line 73, in create_connection
    for res in socket.getaddrinfo(host, port, family, socket.SOCK_STREAM):
  File "/usr/lib/python3.10/socket.py", line 955, in getaddrinfo
    for res in _socket.getaddrinfo(host, port, family, type, proto, flags):
socket.gaierror: [Errno -3] Temporary failure in name resolution

During handling of the above exception, another exception occurred:

Traceback (most recent call last):
  File "/usr/lib/python3/dist-packages/urllib3/connectionpool.py", line 699, in urlopen
    httplib_response = self._make_request(
  File "/usr/lib/python3/dist-packages/urllib3/connectionpool.py", line 394, in _make_request
    conn.request(method, url, **httplib_request_kw)
  File "/usr/lib/python3/dist-packages/urllib3/connection.py", line 234, in request
    super(HTTPConnection, self).request(method, url, body=body, headers=headers)
  File "/usr/lib/python3.10/http/client.py", line 1282, in request
    self._send_request(method, url, body, headers, encode_chunked)
  File "/usr/lib/python3.10/http/client.py", line 1328, in _send_request
    self.endheaders(body, encode_chunked=encode_chunked)
  File "/usr/lib/python3.10/http/client.py", line 1277, in endheaders
    self._send_output(message_body, encode_chunked=encode_chunked)
  File "/usr/lib/python3.10/http/client.py", line 1037, in _send_output
    self.send(msg)
  File "/usr/lib/python3.10/http/client.py", line 975, in send
    self.connect()
  File "/usr/lib/python3/dist-packages/urllib3/connection.py", line 200, in connect
    conn = self._new_conn()
  File "/usr/lib/python3/dist-packages/urllib3/connection.py", line 181, in _new_conn
    raise NewConnectionError(
urllib3.exceptions.NewConnectionError: <urllib3.connection.HTTPConnection object at 0x7fef617685e0>: Failed to establish a new connection: [Errno -3] Temporary failure in name resolution

During handling of the above exception, another exception occurred:

Traceback (most recent call last):
  File "/usr/lib/python3/dist-packages/requests/adapters.py", line 439, in send
    resp = conn.urlopen(
  File "/usr/lib/python3/dist-packages/urllib3/connectionpool.py", line 755, in urlopen
    retries = retries.increment(
  File "/usr/lib/python3/dist-packages/urllib3/util/retry.py", line 574, in increment
    raise MaxRetryError(_pool, url, error or ResponseError(cause))
urllib3.exceptions.MaxRetryError: HTTPConnectionPool(host='archive.eso.org', port=80): Max retries exceeded with url: /tap_obs/sync (Caused by NewConnectionError('<urllib3.connection.HTTPConnection object at 0x7fef617685e0>: Failed to establish a new connection: [Errno -3] Temporary failure in name resolution'))

During handling of the above exception, another exception occurred:

Traceback (most recent call last):
  File "/usr/local/lib/python3.10/dist-packages/pyvo/dal/query.py", line 242, in execute_votable
    return votableparse(self.execute_stream(post=post).read)
  File "/usr/local/lib/python3.10/dist-packages/pyvo/dal/tap.py", line 926, in execute_stream
    return super().execute_stream(post=post)
  File "/usr/local/lib/python3.10/dist-packages/pyvo/utils/decorators.py", line 9, in wrapper
    raw = func(*args, **kwargs)
  File "/usr/local/lib/python3.10/dist-packages/pyvo/dal/query.py", line 191, in execute_stream
    response = self.submit(post=post)
  File "/usr/local/lib/python3.10/dist-packages/pyvo/dal/tap.py", line 959, in submit
    response = self._session.post(
  File "/usr/lib/python3/dist-packages/requests/sessions.py", line 590, in post
    return self.request('POST', url, data=data, json=json, **kwargs)
  File "/usr/lib/python3/dist-packages/requests/sessions.py", line 542, in request
    resp = self.send(prep, **send_kwargs)
  File "/usr/lib/python3/dist-packages/requests/sessions.py", line 655, in send
    r = adapter.send(request, **kwargs)
  File "/usr/lib/python3/dist-packages/requests/adapters.py", line 516, in send
    raise ConnectionError(e, request=request)
requests.exceptions.ConnectionError: HTTPConnectionPool(host='archive.eso.org', port=80): Max retries exceeded with url: /tap_obs/sync (Caused by NewConnectionError('<urllib3.connection.HTTPConnection object at 0x7fef617685e0>: Failed to establish a new connection: [Errno -3] Temporary failure in name resolution'))

During handling of the above exception, another exception occurred:

Traceback (most recent call last):
  File "/home/lachaume/git/autolog/scripts/./periodlog.py", line 22, in <module>
    log = PeriodLog.fetch(telescope, period, **opts) 
  File "/home/lachaume/git/autolog/scripts/../autolog/eso/periodlog.py", line 56, in fetch
    logs = [NightLog.fetch(telescope, night, **opts)
  File "/home/lachaume/git/autolog/scripts/../autolog/eso/periodlog.py", line 56, in <listcomp>
    logs = [NightLog.fetch(telescope, night, **opts)
  File "/home/lachaume/git/autolog/scripts/../autolog/eso/nightlog.py", line 67, in fetch
    log = query.fetch(night=night, use_tap_cache=use_tap_cache)
  File "/home/lachaume/git/autolog/scripts/../autolog/eso/tapquery.py", line 115, in fetch
    tab = tap.execute().to_table()
  File "/usr/local/lib/python3.10/dist-packages/pyvo/dal/tap.py", line 942, in execute
    return TAPResults(self.execute_votable(), url=self.queryurl, session=self._session)
  File "/usr/local/lib/python3.10/dist-packages/pyvo/dal/query.py", line 245, in execute_votable
    raise DALFormatError(e, self.queryurl)
pyvo.dal.exceptions.DALFormatError: ConnectionError: HTTPConnectionPool(host='archive.eso.org', port=80): Max retries exceeded with url: /tap_obs/sync (Caused by NewConnectionError('<urllib3.connection.HTTPConnection object at 0x7fef617685e0>: Failed to establish a new connection: [Errno -3] Temporary failure in name resolution'))

git add * in /home/lachaume/git/autolog
git commit
git push
ssh: Could not resolve hostname github.com: Temporary failure in name resolution
fatal: Could not read from remote repository.

Please make sure you have the correct access rights
and the repository exists.

executing periodlog.py in /home/lachaume/git/autolog/scripts
ssh: Could not resolve hostname github.com: Temporary failure in name resolution
fatal: Could not read from remote repository.

Please make sure you have the correct access rights
and the repository exists.

ssh: Could not resolve hostname github.com: Temporary failure in name resolution
fatal: Could not read from remote repository.

Please make sure you have the correct access rights
and the repository exists.


daily.sh at 2022-07-07T16:21:01-04:00
-------------------------------------

github pull in /home/lachaume/git/autolog
Traceback (most recent call last):
  File "/usr/lib/python3/dist-packages/urllib3/connection.py", line 169, in _new_conn
    conn = connection.create_connection(
  File "/usr/lib/python3/dist-packages/urllib3/util/connection.py", line 73, in create_connection
    for res in socket.getaddrinfo(host, port, family, socket.SOCK_STREAM):
  File "/usr/lib/python3.10/socket.py", line 955, in getaddrinfo
    for res in _socket.getaddrinfo(host, port, family, type, proto, flags):
socket.gaierror: [Errno -3] Temporary failure in name resolution

During handling of the above exception, another exception occurred:

Traceback (most recent call last):
  File "/usr/lib/python3/dist-packages/urllib3/connectionpool.py", line 699, in urlopen
    httplib_response = self._make_request(
  File "/usr/lib/python3/dist-packages/urllib3/connectionpool.py", line 394, in _make_request
    conn.request(method, url, **httplib_request_kw)
  File "/usr/lib/python3/dist-packages/urllib3/connection.py", line 234, in request
    super(HTTPConnection, self).request(method, url, body=body, headers=headers)
  File "/usr/lib/python3.10/http/client.py", line 1282, in request
    self._send_request(method, url, body, headers, encode_chunked)
  File "/usr/lib/python3.10/http/client.py", line 1328, in _send_request
    self.endheaders(body, encode_chunked=encode_chunked)
  File "/usr/lib/python3.10/http/client.py", line 1277, in endheaders
    self._send_output(message_body, encode_chunked=encode_chunked)
  File "/usr/lib/python3.10/http/client.py", line 1037, in _send_output
    self.send(msg)
  File "/usr/lib/python3.10/http/client.py", line 975, in send
    self.connect()
  File "/usr/lib/python3/dist-packages/urllib3/connection.py", line 200, in connect
    conn = self._new_conn()
  File "/usr/lib/python3/dist-packages/urllib3/connection.py", line 181, in _new_conn
    raise NewConnectionError(
urllib3.exceptions.NewConnectionError: <urllib3.connection.HTTPConnection object at 0x7fe56e868550>: Failed to establish a new connection: [Errno -3] Temporary failure in name resolution

During handling of the above exception, another exception occurred:

Traceback (most recent call last):
  File "/usr/lib/python3/dist-packages/requests/adapters.py", line 439, in send
    resp = conn.urlopen(
  File "/usr/lib/python3/dist-packages/urllib3/connectionpool.py", line 755, in urlopen
    retries = retries.increment(
  File "/usr/lib/python3/dist-packages/urllib3/util/retry.py", line 574, in increment
    raise MaxRetryError(_pool, url, error or ResponseError(cause))
urllib3.exceptions.MaxRetryError: HTTPConnectionPool(host='archive.eso.org', port=80): Max retries exceeded with url: /tap_obs/sync (Caused by NewConnectionError('<urllib3.connection.HTTPConnection object at 0x7fe56e868550>: Failed to establish a new connection: [Errno -3] Temporary failure in name resolution'))

During handling of the above exception, another exception occurred:

Traceback (most recent call last):
  File "/usr/local/lib/python3.10/dist-packages/pyvo/dal/query.py", line 242, in execute_votable
    return votableparse(self.execute_stream(post=post).read)
  File "/usr/local/lib/python3.10/dist-packages/pyvo/dal/tap.py", line 926, in execute_stream
    return super().execute_stream(post=post)
  File "/usr/local/lib/python3.10/dist-packages/pyvo/utils/decorators.py", line 9, in wrapper
    raw = func(*args, **kwargs)
  File "/usr/local/lib/python3.10/dist-packages/pyvo/dal/query.py", line 191, in execute_stream
    response = self.submit(post=post)
  File "/usr/local/lib/python3.10/dist-packages/pyvo/dal/tap.py", line 959, in submit
    response = self._session.post(
  File "/usr/lib/python3/dist-packages/requests/sessions.py", line 590, in post
    return self.request('POST', url, data=data, json=json, **kwargs)
  File "/usr/lib/python3/dist-packages/requests/sessions.py", line 542, in request
    resp = self.send(prep, **send_kwargs)
  File "/usr/lib/python3/dist-packages/requests/sessions.py", line 655, in send
    r = adapter.send(request, **kwargs)
  File "/usr/lib/python3/dist-packages/requests/adapters.py", line 516, in send
    raise ConnectionError(e, request=request)
requests.exceptions.ConnectionError: HTTPConnectionPool(host='archive.eso.org', port=80): Max retries exceeded with url: /tap_obs/sync (Caused by NewConnectionError('<urllib3.connection.HTTPConnection object at 0x7fe56e868550>: Failed to establish a new connection: [Errno -3] Temporary failure in name resolution'))

During handling of the above exception, another exception occurred:

Traceback (most recent call last):
  File "/home/lachaume/git/autolog/scripts/./periodlog.py", line 22, in <module>
    log = PeriodLog.fetch(telescope, period, **opts) 
  File "/home/lachaume/git/autolog/scripts/../autolog/eso/periodlog.py", line 56, in fetch
    logs = [NightLog.fetch(telescope, night, **opts)
  File "/home/lachaume/git/autolog/scripts/../autolog/eso/periodlog.py", line 56, in <listcomp>
    logs = [NightLog.fetch(telescope, night, **opts)
  File "/home/lachaume/git/autolog/scripts/../autolog/eso/nightlog.py", line 67, in fetch
    log = query.fetch(night=night, use_tap_cache=use_tap_cache)
  File "/home/lachaume/git/autolog/scripts/../autolog/eso/tapquery.py", line 115, in fetch
    tab = tap.execute().to_table()
  File "/usr/local/lib/python3.10/dist-packages/pyvo/dal/tap.py", line 942, in execute
    return TAPResults(self.execute_votable(), url=self.queryurl, session=self._session)
  File "/usr/local/lib/python3.10/dist-packages/pyvo/dal/query.py", line 245, in execute_votable
    raise DALFormatError(e, self.queryurl)
pyvo.dal.exceptions.DALFormatError: ConnectionError: HTTPConnectionPool(host='archive.eso.org', port=80): Max retries exceeded with url: /tap_obs/sync (Caused by NewConnectionError('<urllib3.connection.HTTPConnection object at 0x7fe56e868550>: Failed to establish a new connection: [Errno -3] Temporary failure in name resolution'))

git add * in /home/lachaume/git/autolog
